[2023-03-10 21:26:38,388] {scheduler_job.py:182} INFO - Started process (PID=581) to work on /opt/airflow/dags/spent_by_user.py
[2023-03-10 21:26:38,392] {scheduler_job.py:629} INFO - Processing file /opt/airflow/dags/spent_by_user.py for tasks to queue
[2023-03-10 21:26:38,395] {logging_mixin.py:104} INFO - [2023-03-10 21:26:38,395] {dagbag.py:448} INFO - Filling up the DagBag from /opt/airflow/dags/spent_by_user.py
[2023-03-10 21:26:38,458] {logging_mixin.py:104} INFO - [2023-03-10 21:26:38,453] {dagbag.py:305} ERROR - Failed to import: /opt/airflow/dags/spent_by_user.py
Traceback (most recent call last):
  File "/home/airflow/.local/lib/python3.6/site-packages/airflow/models/dagbag.py", line 302, in _load_modules_from_file
    loader.exec_module(new_module)
  File "<frozen importlib._bootstrap_external>", line 678, in exec_module
  File "<frozen importlib._bootstrap>", line 219, in _call_with_frames_removed
  File "/opt/airflow/dags/spent_by_user.py", line 7, in <module>
    from models.models import Purchase, Customer
ModuleNotFoundError: No module named 'models'
[2023-03-10 21:26:38,463] {scheduler_job.py:641} WARNING - No viable dags retrieved from /opt/airflow/dags/spent_by_user.py
[2023-03-10 21:26:38,497] {scheduler_job.py:190} INFO - Processing /opt/airflow/dags/spent_by_user.py took 0.116 seconds
[2023-03-10 21:27:08,770] {scheduler_job.py:182} INFO - Started process (PID=629) to work on /opt/airflow/dags/spent_by_user.py
[2023-03-10 21:27:08,774] {scheduler_job.py:629} INFO - Processing file /opt/airflow/dags/spent_by_user.py for tasks to queue
[2023-03-10 21:27:08,778] {logging_mixin.py:104} INFO - [2023-03-10 21:27:08,777] {dagbag.py:448} INFO - Filling up the DagBag from /opt/airflow/dags/spent_by_user.py
[2023-03-10 21:27:08,837] {logging_mixin.py:104} INFO - [2023-03-10 21:27:08,828] {dagbag.py:305} ERROR - Failed to import: /opt/airflow/dags/spent_by_user.py
Traceback (most recent call last):
  File "/home/airflow/.local/lib/python3.6/site-packages/airflow/models/dagbag.py", line 302, in _load_modules_from_file
    loader.exec_module(new_module)
  File "<frozen importlib._bootstrap_external>", line 678, in exec_module
  File "<frozen importlib._bootstrap>", line 219, in _call_with_frames_removed
  File "/opt/airflow/dags/spent_by_user.py", line 10, in <module>
    engine = create_engine('postgresql://username:password@host:port/dbname')
  File "/home/airflow/.local/lib/python3.6/site-packages/sqlalchemy/engine/__init__.py", line 520, in create_engine
    return strategy.create(*args, **kwargs)
  File "/home/airflow/.local/lib/python3.6/site-packages/sqlalchemy/engine/strategies.py", line 54, in create
    u = url.make_url(name_or_url)
  File "/home/airflow/.local/lib/python3.6/site-packages/sqlalchemy/engine/url.py", line 229, in make_url
    return _parse_rfc1738_args(name_or_url)
  File "/home/airflow/.local/lib/python3.6/site-packages/sqlalchemy/engine/url.py", line 288, in _parse_rfc1738_args
    return URL(name, **components)
  File "/home/airflow/.local/lib/python3.6/site-packages/sqlalchemy/engine/url.py", line 71, in __init__
    self.port = int(port)
ValueError: invalid literal for int() with base 10: 'port'
[2023-03-10 21:27:08,841] {scheduler_job.py:641} WARNING - No viable dags retrieved from /opt/airflow/dags/spent_by_user.py
[2023-03-10 21:27:08,872] {scheduler_job.py:190} INFO - Processing /opt/airflow/dags/spent_by_user.py took 0.109 seconds
[2023-03-10 21:27:39,240] {scheduler_job.py:182} INFO - Started process (PID=679) to work on /opt/airflow/dags/spent_by_user.py
[2023-03-10 21:27:39,245] {scheduler_job.py:629} INFO - Processing file /opt/airflow/dags/spent_by_user.py for tasks to queue
[2023-03-10 21:27:39,249] {logging_mixin.py:104} INFO - [2023-03-10 21:27:39,248] {dagbag.py:448} INFO - Filling up the DagBag from /opt/airflow/dags/spent_by_user.py
[2023-03-10 21:27:39,319] {logging_mixin.py:104} INFO - [2023-03-10 21:27:39,307] {dagbag.py:305} ERROR - Failed to import: /opt/airflow/dags/spent_by_user.py
Traceback (most recent call last):
  File "/home/airflow/.local/lib/python3.6/site-packages/airflow/models/dagbag.py", line 302, in _load_modules_from_file
    loader.exec_module(new_module)
  File "<frozen importlib._bootstrap_external>", line 678, in exec_module
  File "<frozen importlib._bootstrap>", line 219, in _call_with_frames_removed
  File "/opt/airflow/dags/spent_by_user.py", line 43, in <module>
    dag=dag,
  File "/home/airflow/.local/lib/python3.6/site-packages/airflow/models/baseoperator.py", line 89, in __call__
    obj: BaseOperator = type.__call__(cls, *args, **kwargs)
  File "/home/airflow/.local/lib/python3.6/site-packages/airflow/utils/decorators.py", line 94, in wrapper
    result = func(*args, **kwargs)
  File "/home/airflow/.local/lib/python3.6/site-packages/airflow/operators/python.py", line 101, in __init__
    super().__init__(**kwargs)
  File "/home/airflow/.local/lib/python3.6/site-packages/airflow/utils/decorators.py", line 94, in wrapper
    result = func(*args, **kwargs)
  File "/home/airflow/.local/lib/python3.6/site-packages/airflow/models/baseoperator.py", line 487, in __init__
    self.dag = dag or DagContext.get_current_dag()
  File "/home/airflow/.local/lib/python3.6/site-packages/airflow/models/baseoperator.py", line 593, in __setattr__
    super().__setattr__(key, value)
  File "/home/airflow/.local/lib/python3.6/site-packages/airflow/models/baseoperator.py", line 644, in dag
    dag.add_task(self)
  File "/home/airflow/.local/lib/python3.6/site-packages/airflow/models/dag.py", line 1589, in add_task
    raise AirflowException("Task is missing the start_date parameter")
airflow.exceptions.AirflowException: Task is missing the start_date parameter
[2023-03-10 21:27:39,325] {scheduler_job.py:641} WARNING - No viable dags retrieved from /opt/airflow/dags/spent_by_user.py
[2023-03-10 21:27:39,354] {scheduler_job.py:190} INFO - Processing /opt/airflow/dags/spent_by_user.py took 0.122 seconds
[2023-03-10 21:28:41,537] {scheduler_job.py:182} INFO - Started process (PID=81) to work on /opt/airflow/dags/spent_by_user.py
[2023-03-10 21:28:41,543] {scheduler_job.py:629} INFO - Processing file /opt/airflow/dags/spent_by_user.py for tasks to queue
[2023-03-10 21:28:41,546] {logging_mixin.py:104} INFO - [2023-03-10 21:28:41,545] {dagbag.py:448} INFO - Filling up the DagBag from /opt/airflow/dags/spent_by_user.py
[2023-03-10 21:28:41,626] {logging_mixin.py:104} INFO - [2023-03-10 21:28:41,600] {dagbag.py:305} ERROR - Failed to import: /opt/airflow/dags/spent_by_user.py
Traceback (most recent call last):
  File "/home/airflow/.local/lib/python3.6/site-packages/airflow/models/dagbag.py", line 302, in _load_modules_from_file
    loader.exec_module(new_module)
  File "<frozen importlib._bootstrap_external>", line 678, in exec_module
  File "<frozen importlib._bootstrap>", line 219, in _call_with_frames_removed
  File "/opt/airflow/dags/spent_by_user.py", line 43, in <module>
    dag=dag,
  File "/home/airflow/.local/lib/python3.6/site-packages/airflow/models/baseoperator.py", line 89, in __call__
    obj: BaseOperator = type.__call__(cls, *args, **kwargs)
  File "/home/airflow/.local/lib/python3.6/site-packages/airflow/utils/decorators.py", line 94, in wrapper
    result = func(*args, **kwargs)
  File "/home/airflow/.local/lib/python3.6/site-packages/airflow/operators/python.py", line 101, in __init__
    super().__init__(**kwargs)
  File "/home/airflow/.local/lib/python3.6/site-packages/airflow/utils/decorators.py", line 94, in wrapper
    result = func(*args, **kwargs)
  File "/home/airflow/.local/lib/python3.6/site-packages/airflow/models/baseoperator.py", line 487, in __init__
    self.dag = dag or DagContext.get_current_dag()
  File "/home/airflow/.local/lib/python3.6/site-packages/airflow/models/baseoperator.py", line 593, in __setattr__
    super().__setattr__(key, value)
  File "/home/airflow/.local/lib/python3.6/site-packages/airflow/models/baseoperator.py", line 644, in dag
    dag.add_task(self)
  File "/home/airflow/.local/lib/python3.6/site-packages/airflow/models/dag.py", line 1589, in add_task
    raise AirflowException("Task is missing the start_date parameter")
airflow.exceptions.AirflowException: Task is missing the start_date parameter
[2023-03-10 21:28:41,645] {scheduler_job.py:641} WARNING - No viable dags retrieved from /opt/airflow/dags/spent_by_user.py
[2023-03-10 21:28:41,702] {scheduler_job.py:190} INFO - Processing /opt/airflow/dags/spent_by_user.py took 0.173 seconds
[2023-03-10 21:29:11,938] {scheduler_job.py:182} INFO - Started process (PID=133) to work on /opt/airflow/dags/spent_by_user.py
[2023-03-10 21:29:11,944] {scheduler_job.py:629} INFO - Processing file /opt/airflow/dags/spent_by_user.py for tasks to queue
[2023-03-10 21:29:11,949] {logging_mixin.py:104} INFO - [2023-03-10 21:29:11,948] {dagbag.py:448} INFO - Filling up the DagBag from /opt/airflow/dags/spent_by_user.py
[2023-03-10 21:29:12,014] {logging_mixin.py:104} INFO - [2023-03-10 21:29:12,006] {dagbag.py:305} ERROR - Failed to import: /opt/airflow/dags/spent_by_user.py
Traceback (most recent call last):
  File "/home/airflow/.local/lib/python3.6/site-packages/airflow/models/dagbag.py", line 302, in _load_modules_from_file
    loader.exec_module(new_module)
  File "<frozen importlib._bootstrap_external>", line 678, in exec_module
  File "<frozen importlib._bootstrap>", line 219, in _call_with_frames_removed
  File "/opt/airflow/dags/spent_by_user.py", line 13, in <module>
    class UserTotalSpent(Base):
  File "/opt/airflow/dags/spent_by_user.py", line 15, in UserTotalSpent
    customer_id = Column(Integer, primary_key=True)
NameError: name 'Column' is not defined
[2023-03-10 21:29:12,019] {scheduler_job.py:641} WARNING - No viable dags retrieved from /opt/airflow/dags/spent_by_user.py
[2023-03-10 21:29:12,072] {scheduler_job.py:190} INFO - Processing /opt/airflow/dags/spent_by_user.py took 0.144 seconds
[2023-03-10 21:29:43,309] {scheduler_job.py:182} INFO - Started process (PID=181) to work on /opt/airflow/dags/spent_by_user.py
[2023-03-10 21:29:43,314] {scheduler_job.py:629} INFO - Processing file /opt/airflow/dags/spent_by_user.py for tasks to queue
[2023-03-10 21:29:43,322] {logging_mixin.py:104} INFO - [2023-03-10 21:29:43,321] {dagbag.py:448} INFO - Filling up the DagBag from /opt/airflow/dags/spent_by_user.py
[2023-03-10 21:29:43,618] {logging_mixin.py:104} INFO - [2023-03-10 21:29:43,587] {dagbag.py:305} ERROR - Failed to import: /opt/airflow/dags/spent_by_user.py
Traceback (most recent call last):
  File "/home/airflow/.local/lib/python3.6/site-packages/sqlalchemy/engine/base.py", line 2336, in _wrap_pool_connect
    return fn()
  File "/home/airflow/.local/lib/python3.6/site-packages/sqlalchemy/pool/base.py", line 364, in connect
    return _ConnectionFairy._checkout(self)
  File "/home/airflow/.local/lib/python3.6/site-packages/sqlalchemy/pool/base.py", line 778, in _checkout
    fairy = _ConnectionRecord.checkout(pool)
  File "/home/airflow/.local/lib/python3.6/site-packages/sqlalchemy/pool/base.py", line 495, in checkout
    rec = pool._do_get()
  File "/home/airflow/.local/lib/python3.6/site-packages/sqlalchemy/pool/impl.py", line 140, in _do_get
    self._dec_overflow()
  File "/home/airflow/.local/lib/python3.6/site-packages/sqlalchemy/util/langhelpers.py", line 70, in __exit__
    with_traceback=exc_tb,
  File "/home/airflow/.local/lib/python3.6/site-packages/sqlalchemy/util/compat.py", line 182, in raise_
    raise exception
  File "/home/airflow/.local/lib/python3.6/site-packages/sqlalchemy/pool/impl.py", line 137, in _do_get
    return self._create_connection()
  File "/home/airflow/.local/lib/python3.6/site-packages/sqlalchemy/pool/base.py", line 309, in _create_connection
    return _ConnectionRecord(self)
  File "/home/airflow/.local/lib/python3.6/site-packages/sqlalchemy/pool/base.py", line 440, in __init__
    self.__connect(first_connect_check=True)
  File "/home/airflow/.local/lib/python3.6/site-packages/sqlalchemy/pool/base.py", line 661, in __connect
    pool.logger.debug("Error on connect(): %s", e)
  File "/home/airflow/.local/lib/python3.6/site-packages/sqlalchemy/util/langhelpers.py", line 70, in __exit__
    with_traceback=exc_tb,
  File "/home/airflow/.local/lib/python3.6/site-packages/sqlalchemy/util/compat.py", line 182, in raise_
    raise exception
  File "/home/airflow/.local/lib/python3.6/site-packages/sqlalchemy/pool/base.py", line 656, in __connect
    connection = pool._invoke_creator(self)
  File "/home/airflow/.local/lib/python3.6/site-packages/sqlalchemy/engine/strategies.py", line 114, in connect
    return dialect.connect(*cargs, **cparams)
  File "/home/airflow/.local/lib/python3.6/site-packages/sqlalchemy/engine/default.py", line 508, in connect
    return self.dbapi.connect(*cargs, **cparams)
  File "/home/airflow/.local/lib/python3.6/site-packages/psycopg2/__init__.py", line 127, in connect
    conn = _connect(dsn, connection_factory=connection_factory, **kwasync)
psycopg2.OperationalError: could not translate host name "db" to address: Name or service not known


The above exception was the direct cause of the following exception:

Traceback (most recent call last):
  File "/home/airflow/.local/lib/python3.6/site-packages/airflow/models/dagbag.py", line 302, in _load_modules_from_file
    loader.exec_module(new_module)
  File "<frozen importlib._bootstrap_external>", line 678, in exec_module
  File "<frozen importlib._bootstrap>", line 219, in _call_with_frames_removed
  File "/opt/airflow/dags/spent_by_user.py", line 20, in <module>
    Base.metadata.create_all(bind=engine, tables=[UserTotalSpent.__table__])
  File "/home/airflow/.local/lib/python3.6/site-packages/sqlalchemy/sql/schema.py", line 4664, in create_all
    ddl.SchemaGenerator, self, checkfirst=checkfirst, tables=tables
  File "/home/airflow/.local/lib/python3.6/site-packages/sqlalchemy/engine/base.py", line 2094, in _run_visitor
    with self._optional_conn_ctx_manager(connection) as conn:
  File "/usr/local/lib/python3.6/contextlib.py", line 81, in __enter__
    return next(self.gen)
  File "/home/airflow/.local/lib/python3.6/site-packages/sqlalchemy/engine/base.py", line 2086, in _optional_conn_ctx_manager
    with self._contextual_connect() as conn:
  File "/home/airflow/.local/lib/python3.6/site-packages/sqlalchemy/engine/base.py", line 2302, in _contextual_connect
    self._wrap_pool_connect(self.pool.connect, None),
  File "/home/airflow/.local/lib/python3.6/site-packages/sqlalchemy/engine/base.py", line 2340, in _wrap_pool_connect
    e, dialect, self
  File "/home/airflow/.local/lib/python3.6/site-packages/sqlalchemy/engine/base.py", line 1584, in _handle_dbapi_exception_noconnection
    sqlalchemy_exception, with_traceback=exc_info[2], from_=e
  File "/home/airflow/.local/lib/python3.6/site-packages/sqlalchemy/util/compat.py", line 182, in raise_
    raise exception
  File "/home/airflow/.local/lib/python3.6/site-packages/sqlalchemy/engine/base.py", line 2336, in _wrap_pool_connect
    return fn()
  File "/home/airflow/.local/lib/python3.6/site-packages/sqlalchemy/pool/base.py", line 364, in connect
    return _ConnectionFairy._checkout(self)
  File "/home/airflow/.local/lib/python3.6/site-packages/sqlalchemy/pool/base.py", line 778, in _checkout
    fairy = _ConnectionRecord.checkout(pool)
  File "/home/airflow/.local/lib/python3.6/site-packages/sqlalchemy/pool/base.py", line 495, in checkout
    rec = pool._do_get()
  File "/home/airflow/.local/lib/python3.6/site-packages/sqlalchemy/pool/impl.py", line 140, in _do_get
    self._dec_overflow()
  File "/home/airflow/.local/lib/python3.6/site-packages/sqlalchemy/util/langhelpers.py", line 70, in __exit__
    with_traceback=exc_tb,
  File "/home/airflow/.local/lib/python3.6/site-packages/sqlalchemy/util/compat.py", line 182, in raise_
    raise exception
  File "/home/airflow/.local/lib/python3.6/site-packages/sqlalchemy/pool/impl.py", line 137, in _do_get
    return self._create_connection()
  File "/home/airflow/.local/lib/python3.6/site-packages/sqlalchemy/pool/base.py", line 309, in _create_connection
    return _ConnectionRecord(self)
  File "/home/airflow/.local/lib/python3.6/site-packages/sqlalchemy/pool/base.py", line 440, in __init__
    self.__connect(first_connect_check=True)
  File "/home/airflow/.local/lib/python3.6/site-packages/sqlalchemy/pool/base.py", line 661, in __connect
    pool.logger.debug("Error on connect(): %s", e)
  File "/home/airflow/.local/lib/python3.6/site-packages/sqlalchemy/util/langhelpers.py", line 70, in __exit__
    with_traceback=exc_tb,
  File "/home/airflow/.local/lib/python3.6/site-packages/sqlalchemy/util/compat.py", line 182, in raise_
    raise exception
  File "/home/airflow/.local/lib/python3.6/site-packages/sqlalchemy/pool/base.py", line 656, in __connect
    connection = pool._invoke_creator(self)
  File "/home/airflow/.local/lib/python3.6/site-packages/sqlalchemy/engine/strategies.py", line 114, in connect
    return dialect.connect(*cargs, **cparams)
  File "/home/airflow/.local/lib/python3.6/site-packages/sqlalchemy/engine/default.py", line 508, in connect
    return self.dbapi.connect(*cargs, **cparams)
  File "/home/airflow/.local/lib/python3.6/site-packages/psycopg2/__init__.py", line 127, in connect
    conn = _connect(dsn, connection_factory=connection_factory, **kwasync)
sqlalchemy.exc.OperationalError: (psycopg2.OperationalError) could not translate host name "db" to address: Name or service not known

(Background on this error at: http://sqlalche.me/e/13/e3q8)
[2023-03-10 21:29:43,642] {scheduler_job.py:641} WARNING - No viable dags retrieved from /opt/airflow/dags/spent_by_user.py
[2023-03-10 21:29:43,724] {scheduler_job.py:190} INFO - Processing /opt/airflow/dags/spent_by_user.py took 0.430 seconds
[2023-03-10 21:30:14,413] {scheduler_job.py:182} INFO - Started process (PID=237) to work on /opt/airflow/dags/spent_by_user.py
[2023-03-10 21:30:14,417] {scheduler_job.py:629} INFO - Processing file /opt/airflow/dags/spent_by_user.py for tasks to queue
[2023-03-10 21:30:14,421] {logging_mixin.py:104} INFO - [2023-03-10 21:30:14,420] {dagbag.py:448} INFO - Filling up the DagBag from /opt/airflow/dags/spent_by_user.py
[2023-03-10 21:30:14,497] {logging_mixin.py:104} INFO - [2023-03-10 21:30:14,475] {dagbag.py:305} ERROR - Failed to import: /opt/airflow/dags/spent_by_user.py
Traceback (most recent call last):
  File "/home/airflow/.local/lib/python3.6/site-packages/sqlalchemy/engine/base.py", line 2336, in _wrap_pool_connect
    return fn()
  File "/home/airflow/.local/lib/python3.6/site-packages/sqlalchemy/pool/base.py", line 364, in connect
    return _ConnectionFairy._checkout(self)
  File "/home/airflow/.local/lib/python3.6/site-packages/sqlalchemy/pool/base.py", line 778, in _checkout
    fairy = _ConnectionRecord.checkout(pool)
  File "/home/airflow/.local/lib/python3.6/site-packages/sqlalchemy/pool/base.py", line 495, in checkout
    rec = pool._do_get()
  File "/home/airflow/.local/lib/python3.6/site-packages/sqlalchemy/pool/impl.py", line 140, in _do_get
    self._dec_overflow()
  File "/home/airflow/.local/lib/python3.6/site-packages/sqlalchemy/util/langhelpers.py", line 70, in __exit__
    with_traceback=exc_tb,
  File "/home/airflow/.local/lib/python3.6/site-packages/sqlalchemy/util/compat.py", line 182, in raise_
    raise exception
  File "/home/airflow/.local/lib/python3.6/site-packages/sqlalchemy/pool/impl.py", line 137, in _do_get
    return self._create_connection()
  File "/home/airflow/.local/lib/python3.6/site-packages/sqlalchemy/pool/base.py", line 309, in _create_connection
    return _ConnectionRecord(self)
  File "/home/airflow/.local/lib/python3.6/site-packages/sqlalchemy/pool/base.py", line 440, in __init__
    self.__connect(first_connect_check=True)
  File "/home/airflow/.local/lib/python3.6/site-packages/sqlalchemy/pool/base.py", line 661, in __connect
    pool.logger.debug("Error on connect(): %s", e)
  File "/home/airflow/.local/lib/python3.6/site-packages/sqlalchemy/util/langhelpers.py", line 70, in __exit__
    with_traceback=exc_tb,
  File "/home/airflow/.local/lib/python3.6/site-packages/sqlalchemy/util/compat.py", line 182, in raise_
    raise exception
  File "/home/airflow/.local/lib/python3.6/site-packages/sqlalchemy/pool/base.py", line 656, in __connect
    connection = pool._invoke_creator(self)
  File "/home/airflow/.local/lib/python3.6/site-packages/sqlalchemy/engine/strategies.py", line 114, in connect
    return dialect.connect(*cargs, **cparams)
  File "/home/airflow/.local/lib/python3.6/site-packages/sqlalchemy/engine/default.py", line 508, in connect
    return self.dbapi.connect(*cargs, **cparams)
  File "/home/airflow/.local/lib/python3.6/site-packages/psycopg2/__init__.py", line 127, in connect
    conn = _connect(dsn, connection_factory=connection_factory, **kwasync)
psycopg2.OperationalError: could not translate host name "db" to address: Name or service not known


The above exception was the direct cause of the following exception:

Traceback (most recent call last):
  File "/home/airflow/.local/lib/python3.6/site-packages/airflow/models/dagbag.py", line 302, in _load_modules_from_file
    loader.exec_module(new_module)
  File "<frozen importlib._bootstrap_external>", line 678, in exec_module
  File "<frozen importlib._bootstrap>", line 219, in _call_with_frames_removed
  File "/opt/airflow/dags/spent_by_user.py", line 20, in <module>
    Base.metadata.create_all(bind=engine, tables=[UserTotalSpent.__table__])
  File "/home/airflow/.local/lib/python3.6/site-packages/sqlalchemy/sql/schema.py", line 4664, in create_all
    ddl.SchemaGenerator, self, checkfirst=checkfirst, tables=tables
  File "/home/airflow/.local/lib/python3.6/site-packages/sqlalchemy/engine/base.py", line 2094, in _run_visitor
    with self._optional_conn_ctx_manager(connection) as conn:
  File "/usr/local/lib/python3.6/contextlib.py", line 81, in __enter__
    return next(self.gen)
  File "/home/airflow/.local/lib/python3.6/site-packages/sqlalchemy/engine/base.py", line 2086, in _optional_conn_ctx_manager
    with self._contextual_connect() as conn:
  File "/home/airflow/.local/lib/python3.6/site-packages/sqlalchemy/engine/base.py", line 2302, in _contextual_connect
    self._wrap_pool_connect(self.pool.connect, None),
  File "/home/airflow/.local/lib/python3.6/site-packages/sqlalchemy/engine/base.py", line 2340, in _wrap_pool_connect
    e, dialect, self
  File "/home/airflow/.local/lib/python3.6/site-packages/sqlalchemy/engine/base.py", line 1584, in _handle_dbapi_exception_noconnection
    sqlalchemy_exception, with_traceback=exc_info[2], from_=e
  File "/home/airflow/.local/lib/python3.6/site-packages/sqlalchemy/util/compat.py", line 182, in raise_
    raise exception
  File "/home/airflow/.local/lib/python3.6/site-packages/sqlalchemy/engine/base.py", line 2336, in _wrap_pool_connect
    return fn()
  File "/home/airflow/.local/lib/python3.6/site-packages/sqlalchemy/pool/base.py", line 364, in connect
    return _ConnectionFairy._checkout(self)
  File "/home/airflow/.local/lib/python3.6/site-packages/sqlalchemy/pool/base.py", line 778, in _checkout
    fairy = _ConnectionRecord.checkout(pool)
  File "/home/airflow/.local/lib/python3.6/site-packages/sqlalchemy/pool/base.py", line 495, in checkout
    rec = pool._do_get()
  File "/home/airflow/.local/lib/python3.6/site-packages/sqlalchemy/pool/impl.py", line 140, in _do_get
    self._dec_overflow()
  File "/home/airflow/.local/lib/python3.6/site-packages/sqlalchemy/util/langhelpers.py", line 70, in __exit__
    with_traceback=exc_tb,
  File "/home/airflow/.local/lib/python3.6/site-packages/sqlalchemy/util/compat.py", line 182, in raise_
    raise exception
  File "/home/airflow/.local/lib/python3.6/site-packages/sqlalchemy/pool/impl.py", line 137, in _do_get
    return self._create_connection()
  File "/home/airflow/.local/lib/python3.6/site-packages/sqlalchemy/pool/base.py", line 309, in _create_connection
    return _ConnectionRecord(self)
  File "/home/airflow/.local/lib/python3.6/site-packages/sqlalchemy/pool/base.py", line 440, in __init__
    self.__connect(first_connect_check=True)
  File "/home/airflow/.local/lib/python3.6/site-packages/sqlalchemy/pool/base.py", line 661, in __connect
    pool.logger.debug("Error on connect(): %s", e)
  File "/home/airflow/.local/lib/python3.6/site-packages/sqlalchemy/util/langhelpers.py", line 70, in __exit__
    with_traceback=exc_tb,
  File "/home/airflow/.local/lib/python3.6/site-packages/sqlalchemy/util/compat.py", line 182, in raise_
    raise exception
  File "/home/airflow/.local/lib/python3.6/site-packages/sqlalchemy/pool/base.py", line 656, in __connect
    connection = pool._invoke_creator(self)
  File "/home/airflow/.local/lib/python3.6/site-packages/sqlalchemy/engine/strategies.py", line 114, in connect
    return dialect.connect(*cargs, **cparams)
  File "/home/airflow/.local/lib/python3.6/site-packages/sqlalchemy/engine/default.py", line 508, in connect
    return self.dbapi.connect(*cargs, **cparams)
  File "/home/airflow/.local/lib/python3.6/site-packages/psycopg2/__init__.py", line 127, in connect
    conn = _connect(dsn, connection_factory=connection_factory, **kwasync)
sqlalchemy.exc.OperationalError: (psycopg2.OperationalError) could not translate host name "db" to address: Name or service not known

(Background on this error at: http://sqlalche.me/e/13/e3q8)
[2023-03-10 21:30:14,505] {scheduler_job.py:641} WARNING - No viable dags retrieved from /opt/airflow/dags/spent_by_user.py
[2023-03-10 21:30:14,538] {scheduler_job.py:190} INFO - Processing /opt/airflow/dags/spent_by_user.py took 0.132 seconds
[2023-03-10 21:30:45,370] {scheduler_job.py:182} INFO - Started process (PID=291) to work on /opt/airflow/dags/spent_by_user.py
[2023-03-10 21:30:45,375] {scheduler_job.py:629} INFO - Processing file /opt/airflow/dags/spent_by_user.py for tasks to queue
[2023-03-10 21:30:45,380] {logging_mixin.py:104} INFO - [2023-03-10 21:30:45,379] {dagbag.py:448} INFO - Filling up the DagBag from /opt/airflow/dags/spent_by_user.py
[2023-03-10 21:30:45,464] {logging_mixin.py:104} INFO - [2023-03-10 21:30:45,438] {dagbag.py:305} ERROR - Failed to import: /opt/airflow/dags/spent_by_user.py
Traceback (most recent call last):
  File "/home/airflow/.local/lib/python3.6/site-packages/sqlalchemy/engine/base.py", line 2336, in _wrap_pool_connect
    return fn()
  File "/home/airflow/.local/lib/python3.6/site-packages/sqlalchemy/pool/base.py", line 364, in connect
    return _ConnectionFairy._checkout(self)
  File "/home/airflow/.local/lib/python3.6/site-packages/sqlalchemy/pool/base.py", line 778, in _checkout
    fairy = _ConnectionRecord.checkout(pool)
  File "/home/airflow/.local/lib/python3.6/site-packages/sqlalchemy/pool/base.py", line 495, in checkout
    rec = pool._do_get()
  File "/home/airflow/.local/lib/python3.6/site-packages/sqlalchemy/pool/impl.py", line 140, in _do_get
    self._dec_overflow()
  File "/home/airflow/.local/lib/python3.6/site-packages/sqlalchemy/util/langhelpers.py", line 70, in __exit__
    with_traceback=exc_tb,
  File "/home/airflow/.local/lib/python3.6/site-packages/sqlalchemy/util/compat.py", line 182, in raise_
    raise exception
  File "/home/airflow/.local/lib/python3.6/site-packages/sqlalchemy/pool/impl.py", line 137, in _do_get
    return self._create_connection()
  File "/home/airflow/.local/lib/python3.6/site-packages/sqlalchemy/pool/base.py", line 309, in _create_connection
    return _ConnectionRecord(self)
  File "/home/airflow/.local/lib/python3.6/site-packages/sqlalchemy/pool/base.py", line 440, in __init__
    self.__connect(first_connect_check=True)
  File "/home/airflow/.local/lib/python3.6/site-packages/sqlalchemy/pool/base.py", line 661, in __connect
    pool.logger.debug("Error on connect(): %s", e)
  File "/home/airflow/.local/lib/python3.6/site-packages/sqlalchemy/util/langhelpers.py", line 70, in __exit__
    with_traceback=exc_tb,
  File "/home/airflow/.local/lib/python3.6/site-packages/sqlalchemy/util/compat.py", line 182, in raise_
    raise exception
  File "/home/airflow/.local/lib/python3.6/site-packages/sqlalchemy/pool/base.py", line 656, in __connect
    connection = pool._invoke_creator(self)
  File "/home/airflow/.local/lib/python3.6/site-packages/sqlalchemy/engine/strategies.py", line 114, in connect
    return dialect.connect(*cargs, **cparams)
  File "/home/airflow/.local/lib/python3.6/site-packages/sqlalchemy/engine/default.py", line 508, in connect
    return self.dbapi.connect(*cargs, **cparams)
  File "/home/airflow/.local/lib/python3.6/site-packages/psycopg2/__init__.py", line 127, in connect
    conn = _connect(dsn, connection_factory=connection_factory, **kwasync)
psycopg2.OperationalError: could not translate host name "db" to address: Name or service not known


The above exception was the direct cause of the following exception:

Traceback (most recent call last):
  File "/home/airflow/.local/lib/python3.6/site-packages/airflow/models/dagbag.py", line 302, in _load_modules_from_file
    loader.exec_module(new_module)
  File "<frozen importlib._bootstrap_external>", line 678, in exec_module
  File "<frozen importlib._bootstrap>", line 219, in _call_with_frames_removed
  File "/opt/airflow/dags/spent_by_user.py", line 20, in <module>
    Base.metadata.create_all(bind=engine, tables=[UserTotalSpent.__table__])
  File "/home/airflow/.local/lib/python3.6/site-packages/sqlalchemy/sql/schema.py", line 4664, in create_all
    ddl.SchemaGenerator, self, checkfirst=checkfirst, tables=tables
  File "/home/airflow/.local/lib/python3.6/site-packages/sqlalchemy/engine/base.py", line 2094, in _run_visitor
    with self._optional_conn_ctx_manager(connection) as conn:
  File "/usr/local/lib/python3.6/contextlib.py", line 81, in __enter__
    return next(self.gen)
  File "/home/airflow/.local/lib/python3.6/site-packages/sqlalchemy/engine/base.py", line 2086, in _optional_conn_ctx_manager
    with self._contextual_connect() as conn:
  File "/home/airflow/.local/lib/python3.6/site-packages/sqlalchemy/engine/base.py", line 2302, in _contextual_connect
    self._wrap_pool_connect(self.pool.connect, None),
  File "/home/airflow/.local/lib/python3.6/site-packages/sqlalchemy/engine/base.py", line 2340, in _wrap_pool_connect
    e, dialect, self
  File "/home/airflow/.local/lib/python3.6/site-packages/sqlalchemy/engine/base.py", line 1584, in _handle_dbapi_exception_noconnection
    sqlalchemy_exception, with_traceback=exc_info[2], from_=e
  File "/home/airflow/.local/lib/python3.6/site-packages/sqlalchemy/util/compat.py", line 182, in raise_
    raise exception
  File "/home/airflow/.local/lib/python3.6/site-packages/sqlalchemy/engine/base.py", line 2336, in _wrap_pool_connect
    return fn()
  File "/home/airflow/.local/lib/python3.6/site-packages/sqlalchemy/pool/base.py", line 364, in connect
    return _ConnectionFairy._checkout(self)
  File "/home/airflow/.local/lib/python3.6/site-packages/sqlalchemy/pool/base.py", line 778, in _checkout
    fairy = _ConnectionRecord.checkout(pool)
  File "/home/airflow/.local/lib/python3.6/site-packages/sqlalchemy/pool/base.py", line 495, in checkout
    rec = pool._do_get()
  File "/home/airflow/.local/lib/python3.6/site-packages/sqlalchemy/pool/impl.py", line 140, in _do_get
    self._dec_overflow()
  File "/home/airflow/.local/lib/python3.6/site-packages/sqlalchemy/util/langhelpers.py", line 70, in __exit__
    with_traceback=exc_tb,
  File "/home/airflow/.local/lib/python3.6/site-packages/sqlalchemy/util/compat.py", line 182, in raise_
    raise exception
  File "/home/airflow/.local/lib/python3.6/site-packages/sqlalchemy/pool/impl.py", line 137, in _do_get
    return self._create_connection()
  File "/home/airflow/.local/lib/python3.6/site-packages/sqlalchemy/pool/base.py", line 309, in _create_connection
    return _ConnectionRecord(self)
  File "/home/airflow/.local/lib/python3.6/site-packages/sqlalchemy/pool/base.py", line 440, in __init__
    self.__connect(first_connect_check=True)
  File "/home/airflow/.local/lib/python3.6/site-packages/sqlalchemy/pool/base.py", line 661, in __connect
    pool.logger.debug("Error on connect(): %s", e)
  File "/home/airflow/.local/lib/python3.6/site-packages/sqlalchemy/util/langhelpers.py", line 70, in __exit__
    with_traceback=exc_tb,
  File "/home/airflow/.local/lib/python3.6/site-packages/sqlalchemy/util/compat.py", line 182, in raise_
    raise exception
  File "/home/airflow/.local/lib/python3.6/site-packages/sqlalchemy/pool/base.py", line 656, in __connect
    connection = pool._invoke_creator(self)
  File "/home/airflow/.local/lib/python3.6/site-packages/sqlalchemy/engine/strategies.py", line 114, in connect
    return dialect.connect(*cargs, **cparams)
  File "/home/airflow/.local/lib/python3.6/site-packages/sqlalchemy/engine/default.py", line 508, in connect
    return self.dbapi.connect(*cargs, **cparams)
  File "/home/airflow/.local/lib/python3.6/site-packages/psycopg2/__init__.py", line 127, in connect
    conn = _connect(dsn, connection_factory=connection_factory, **kwasync)
sqlalchemy.exc.OperationalError: (psycopg2.OperationalError) could not translate host name "db" to address: Name or service not known

(Background on this error at: http://sqlalche.me/e/13/e3q8)
[2023-03-10 21:30:45,473] {scheduler_job.py:641} WARNING - No viable dags retrieved from /opt/airflow/dags/spent_by_user.py
[2023-03-10 21:30:45,519] {scheduler_job.py:190} INFO - Processing /opt/airflow/dags/spent_by_user.py took 0.161 seconds
[2023-03-10 21:31:16,195] {scheduler_job.py:182} INFO - Started process (PID=345) to work on /opt/airflow/dags/spent_by_user.py
[2023-03-10 21:31:16,202] {scheduler_job.py:629} INFO - Processing file /opt/airflow/dags/spent_by_user.py for tasks to queue
[2023-03-10 21:31:16,206] {logging_mixin.py:104} INFO - [2023-03-10 21:31:16,205] {dagbag.py:448} INFO - Filling up the DagBag from /opt/airflow/dags/spent_by_user.py
[2023-03-10 21:31:16,445] {logging_mixin.py:104} INFO - [2023-03-10 21:31:16,422] {dagbag.py:305} ERROR - Failed to import: /opt/airflow/dags/spent_by_user.py
Traceback (most recent call last):
  File "/home/airflow/.local/lib/python3.6/site-packages/sqlalchemy/engine/base.py", line 2336, in _wrap_pool_connect
    return fn()
  File "/home/airflow/.local/lib/python3.6/site-packages/sqlalchemy/pool/base.py", line 364, in connect
    return _ConnectionFairy._checkout(self)
  File "/home/airflow/.local/lib/python3.6/site-packages/sqlalchemy/pool/base.py", line 778, in _checkout
    fairy = _ConnectionRecord.checkout(pool)
  File "/home/airflow/.local/lib/python3.6/site-packages/sqlalchemy/pool/base.py", line 495, in checkout
    rec = pool._do_get()
  File "/home/airflow/.local/lib/python3.6/site-packages/sqlalchemy/pool/impl.py", line 140, in _do_get
    self._dec_overflow()
  File "/home/airflow/.local/lib/python3.6/site-packages/sqlalchemy/util/langhelpers.py", line 70, in __exit__
    with_traceback=exc_tb,
  File "/home/airflow/.local/lib/python3.6/site-packages/sqlalchemy/util/compat.py", line 182, in raise_
    raise exception
  File "/home/airflow/.local/lib/python3.6/site-packages/sqlalchemy/pool/impl.py", line 137, in _do_get
    return self._create_connection()
  File "/home/airflow/.local/lib/python3.6/site-packages/sqlalchemy/pool/base.py", line 309, in _create_connection
    return _ConnectionRecord(self)
  File "/home/airflow/.local/lib/python3.6/site-packages/sqlalchemy/pool/base.py", line 440, in __init__
    self.__connect(first_connect_check=True)
  File "/home/airflow/.local/lib/python3.6/site-packages/sqlalchemy/pool/base.py", line 661, in __connect
    pool.logger.debug("Error on connect(): %s", e)
  File "/home/airflow/.local/lib/python3.6/site-packages/sqlalchemy/util/langhelpers.py", line 70, in __exit__
    with_traceback=exc_tb,
  File "/home/airflow/.local/lib/python3.6/site-packages/sqlalchemy/util/compat.py", line 182, in raise_
    raise exception
  File "/home/airflow/.local/lib/python3.6/site-packages/sqlalchemy/pool/base.py", line 656, in __connect
    connection = pool._invoke_creator(self)
  File "/home/airflow/.local/lib/python3.6/site-packages/sqlalchemy/engine/strategies.py", line 114, in connect
    return dialect.connect(*cargs, **cparams)
  File "/home/airflow/.local/lib/python3.6/site-packages/sqlalchemy/engine/default.py", line 508, in connect
    return self.dbapi.connect(*cargs, **cparams)
  File "/home/airflow/.local/lib/python3.6/site-packages/psycopg2/__init__.py", line 127, in connect
    conn = _connect(dsn, connection_factory=connection_factory, **kwasync)
psycopg2.OperationalError: could not translate host name "db" to address: Name or service not known


The above exception was the direct cause of the following exception:

Traceback (most recent call last):
  File "/home/airflow/.local/lib/python3.6/site-packages/airflow/models/dagbag.py", line 302, in _load_modules_from_file
    loader.exec_module(new_module)
  File "<frozen importlib._bootstrap_external>", line 678, in exec_module
  File "<frozen importlib._bootstrap>", line 219, in _call_with_frames_removed
  File "/opt/airflow/dags/spent_by_user.py", line 20, in <module>
    Base.metadata.create_all(bind=engine, tables=[UserTotalSpent.__table__])
  File "/home/airflow/.local/lib/python3.6/site-packages/sqlalchemy/sql/schema.py", line 4664, in create_all
    ddl.SchemaGenerator, self, checkfirst=checkfirst, tables=tables
  File "/home/airflow/.local/lib/python3.6/site-packages/sqlalchemy/engine/base.py", line 2094, in _run_visitor
    with self._optional_conn_ctx_manager(connection) as conn:
  File "/usr/local/lib/python3.6/contextlib.py", line 81, in __enter__
    return next(self.gen)
  File "/home/airflow/.local/lib/python3.6/site-packages/sqlalchemy/engine/base.py", line 2086, in _optional_conn_ctx_manager
    with self._contextual_connect() as conn:
  File "/home/airflow/.local/lib/python3.6/site-packages/sqlalchemy/engine/base.py", line 2302, in _contextual_connect
    self._wrap_pool_connect(self.pool.connect, None),
  File "/home/airflow/.local/lib/python3.6/site-packages/sqlalchemy/engine/base.py", line 2340, in _wrap_pool_connect
    e, dialect, self
  File "/home/airflow/.local/lib/python3.6/site-packages/sqlalchemy/engine/base.py", line 1584, in _handle_dbapi_exception_noconnection
    sqlalchemy_exception, with_traceback=exc_info[2], from_=e
  File "/home/airflow/.local/lib/python3.6/site-packages/sqlalchemy/util/compat.py", line 182, in raise_
    raise exception
  File "/home/airflow/.local/lib/python3.6/site-packages/sqlalchemy/engine/base.py", line 2336, in _wrap_pool_connect
    return fn()
  File "/home/airflow/.local/lib/python3.6/site-packages/sqlalchemy/pool/base.py", line 364, in connect
    return _ConnectionFairy._checkout(self)
  File "/home/airflow/.local/lib/python3.6/site-packages/sqlalchemy/pool/base.py", line 778, in _checkout
    fairy = _ConnectionRecord.checkout(pool)
  File "/home/airflow/.local/lib/python3.6/site-packages/sqlalchemy/pool/base.py", line 495, in checkout
    rec = pool._do_get()
  File "/home/airflow/.local/lib/python3.6/site-packages/sqlalchemy/pool/impl.py", line 140, in _do_get
    self._dec_overflow()
  File "/home/airflow/.local/lib/python3.6/site-packages/sqlalchemy/util/langhelpers.py", line 70, in __exit__
    with_traceback=exc_tb,
  File "/home/airflow/.local/lib/python3.6/site-packages/sqlalchemy/util/compat.py", line 182, in raise_
    raise exception
  File "/home/airflow/.local/lib/python3.6/site-packages/sqlalchemy/pool/impl.py", line 137, in _do_get
    return self._create_connection()
  File "/home/airflow/.local/lib/python3.6/site-packages/sqlalchemy/pool/base.py", line 309, in _create_connection
    return _ConnectionRecord(self)
  File "/home/airflow/.local/lib/python3.6/site-packages/sqlalchemy/pool/base.py", line 440, in __init__
    self.__connect(first_connect_check=True)
  File "/home/airflow/.local/lib/python3.6/site-packages/sqlalchemy/pool/base.py", line 661, in __connect
    pool.logger.debug("Error on connect(): %s", e)
  File "/home/airflow/.local/lib/python3.6/site-packages/sqlalchemy/util/langhelpers.py", line 70, in __exit__
    with_traceback=exc_tb,
  File "/home/airflow/.local/lib/python3.6/site-packages/sqlalchemy/util/compat.py", line 182, in raise_
    raise exception
  File "/home/airflow/.local/lib/python3.6/site-packages/sqlalchemy/pool/base.py", line 656, in __connect
    connection = pool._invoke_creator(self)
  File "/home/airflow/.local/lib/python3.6/site-packages/sqlalchemy/engine/strategies.py", line 114, in connect
    return dialect.connect(*cargs, **cparams)
  File "/home/airflow/.local/lib/python3.6/site-packages/sqlalchemy/engine/default.py", line 508, in connect
    return self.dbapi.connect(*cargs, **cparams)
  File "/home/airflow/.local/lib/python3.6/site-packages/psycopg2/__init__.py", line 127, in connect
    conn = _connect(dsn, connection_factory=connection_factory, **kwasync)
sqlalchemy.exc.OperationalError: (psycopg2.OperationalError) could not translate host name "db" to address: Name or service not known

(Background on this error at: http://sqlalche.me/e/13/e3q8)
[2023-03-10 21:31:16,453] {scheduler_job.py:641} WARNING - No viable dags retrieved from /opt/airflow/dags/spent_by_user.py
[2023-03-10 21:31:16,487] {scheduler_job.py:190} INFO - Processing /opt/airflow/dags/spent_by_user.py took 0.301 seconds
[2023-03-10 21:31:46,748] {scheduler_job.py:182} INFO - Started process (PID=401) to work on /opt/airflow/dags/spent_by_user.py
[2023-03-10 21:31:46,753] {scheduler_job.py:629} INFO - Processing file /opt/airflow/dags/spent_by_user.py for tasks to queue
[2023-03-10 21:31:46,756] {logging_mixin.py:104} INFO - [2023-03-10 21:31:46,756] {dagbag.py:448} INFO - Filling up the DagBag from /opt/airflow/dags/spent_by_user.py
[2023-03-10 21:31:46,829] {logging_mixin.py:104} INFO - [2023-03-10 21:31:46,807] {dagbag.py:305} ERROR - Failed to import: /opt/airflow/dags/spent_by_user.py
Traceback (most recent call last):
  File "/home/airflow/.local/lib/python3.6/site-packages/sqlalchemy/engine/base.py", line 2336, in _wrap_pool_connect
    return fn()
  File "/home/airflow/.local/lib/python3.6/site-packages/sqlalchemy/pool/base.py", line 364, in connect
    return _ConnectionFairy._checkout(self)
  File "/home/airflow/.local/lib/python3.6/site-packages/sqlalchemy/pool/base.py", line 778, in _checkout
    fairy = _ConnectionRecord.checkout(pool)
  File "/home/airflow/.local/lib/python3.6/site-packages/sqlalchemy/pool/base.py", line 495, in checkout
    rec = pool._do_get()
  File "/home/airflow/.local/lib/python3.6/site-packages/sqlalchemy/pool/impl.py", line 140, in _do_get
    self._dec_overflow()
  File "/home/airflow/.local/lib/python3.6/site-packages/sqlalchemy/util/langhelpers.py", line 70, in __exit__
    with_traceback=exc_tb,
  File "/home/airflow/.local/lib/python3.6/site-packages/sqlalchemy/util/compat.py", line 182, in raise_
    raise exception
  File "/home/airflow/.local/lib/python3.6/site-packages/sqlalchemy/pool/impl.py", line 137, in _do_get
    return self._create_connection()
  File "/home/airflow/.local/lib/python3.6/site-packages/sqlalchemy/pool/base.py", line 309, in _create_connection
    return _ConnectionRecord(self)
  File "/home/airflow/.local/lib/python3.6/site-packages/sqlalchemy/pool/base.py", line 440, in __init__
    self.__connect(first_connect_check=True)
  File "/home/airflow/.local/lib/python3.6/site-packages/sqlalchemy/pool/base.py", line 661, in __connect
    pool.logger.debug("Error on connect(): %s", e)
  File "/home/airflow/.local/lib/python3.6/site-packages/sqlalchemy/util/langhelpers.py", line 70, in __exit__
    with_traceback=exc_tb,
  File "/home/airflow/.local/lib/python3.6/site-packages/sqlalchemy/util/compat.py", line 182, in raise_
    raise exception
  File "/home/airflow/.local/lib/python3.6/site-packages/sqlalchemy/pool/base.py", line 656, in __connect
    connection = pool._invoke_creator(self)
  File "/home/airflow/.local/lib/python3.6/site-packages/sqlalchemy/engine/strategies.py", line 114, in connect
    return dialect.connect(*cargs, **cparams)
  File "/home/airflow/.local/lib/python3.6/site-packages/sqlalchemy/engine/default.py", line 508, in connect
    return self.dbapi.connect(*cargs, **cparams)
  File "/home/airflow/.local/lib/python3.6/site-packages/psycopg2/__init__.py", line 127, in connect
    conn = _connect(dsn, connection_factory=connection_factory, **kwasync)
psycopg2.OperationalError: could not translate host name "db" to address: Name or service not known


The above exception was the direct cause of the following exception:

Traceback (most recent call last):
  File "/home/airflow/.local/lib/python3.6/site-packages/airflow/models/dagbag.py", line 302, in _load_modules_from_file
    loader.exec_module(new_module)
  File "<frozen importlib._bootstrap_external>", line 678, in exec_module
  File "<frozen importlib._bootstrap>", line 219, in _call_with_frames_removed
  File "/opt/airflow/dags/spent_by_user.py", line 20, in <module>
    Base.metadata.create_all(bind=engine, tables=[UserTotalSpent.__table__])
  File "/home/airflow/.local/lib/python3.6/site-packages/sqlalchemy/sql/schema.py", line 4664, in create_all
    ddl.SchemaGenerator, self, checkfirst=checkfirst, tables=tables
  File "/home/airflow/.local/lib/python3.6/site-packages/sqlalchemy/engine/base.py", line 2094, in _run_visitor
    with self._optional_conn_ctx_manager(connection) as conn:
  File "/usr/local/lib/python3.6/contextlib.py", line 81, in __enter__
    return next(self.gen)
  File "/home/airflow/.local/lib/python3.6/site-packages/sqlalchemy/engine/base.py", line 2086, in _optional_conn_ctx_manager
    with self._contextual_connect() as conn:
  File "/home/airflow/.local/lib/python3.6/site-packages/sqlalchemy/engine/base.py", line 2302, in _contextual_connect
    self._wrap_pool_connect(self.pool.connect, None),
  File "/home/airflow/.local/lib/python3.6/site-packages/sqlalchemy/engine/base.py", line 2340, in _wrap_pool_connect
    e, dialect, self
  File "/home/airflow/.local/lib/python3.6/site-packages/sqlalchemy/engine/base.py", line 1584, in _handle_dbapi_exception_noconnection
    sqlalchemy_exception, with_traceback=exc_info[2], from_=e
  File "/home/airflow/.local/lib/python3.6/site-packages/sqlalchemy/util/compat.py", line 182, in raise_
    raise exception
  File "/home/airflow/.local/lib/python3.6/site-packages/sqlalchemy/engine/base.py", line 2336, in _wrap_pool_connect
    return fn()
  File "/home/airflow/.local/lib/python3.6/site-packages/sqlalchemy/pool/base.py", line 364, in connect
    return _ConnectionFairy._checkout(self)
  File "/home/airflow/.local/lib/python3.6/site-packages/sqlalchemy/pool/base.py", line 778, in _checkout
    fairy = _ConnectionRecord.checkout(pool)
  File "/home/airflow/.local/lib/python3.6/site-packages/sqlalchemy/pool/base.py", line 495, in checkout
    rec = pool._do_get()
  File "/home/airflow/.local/lib/python3.6/site-packages/sqlalchemy/pool/impl.py", line 140, in _do_get
    self._dec_overflow()
  File "/home/airflow/.local/lib/python3.6/site-packages/sqlalchemy/util/langhelpers.py", line 70, in __exit__
    with_traceback=exc_tb,
  File "/home/airflow/.local/lib/python3.6/site-packages/sqlalchemy/util/compat.py", line 182, in raise_
    raise exception
  File "/home/airflow/.local/lib/python3.6/site-packages/sqlalchemy/pool/impl.py", line 137, in _do_get
    return self._create_connection()
  File "/home/airflow/.local/lib/python3.6/site-packages/sqlalchemy/pool/base.py", line 309, in _create_connection
    return _ConnectionRecord(self)
  File "/home/airflow/.local/lib/python3.6/site-packages/sqlalchemy/pool/base.py", line 440, in __init__
    self.__connect(first_connect_check=True)
  File "/home/airflow/.local/lib/python3.6/site-packages/sqlalchemy/pool/base.py", line 661, in __connect
    pool.logger.debug("Error on connect(): %s", e)
  File "/home/airflow/.local/lib/python3.6/site-packages/sqlalchemy/util/langhelpers.py", line 70, in __exit__
    with_traceback=exc_tb,
  File "/home/airflow/.local/lib/python3.6/site-packages/sqlalchemy/util/compat.py", line 182, in raise_
    raise exception
  File "/home/airflow/.local/lib/python3.6/site-packages/sqlalchemy/pool/base.py", line 656, in __connect
    connection = pool._invoke_creator(self)
  File "/home/airflow/.local/lib/python3.6/site-packages/sqlalchemy/engine/strategies.py", line 114, in connect
    return dialect.connect(*cargs, **cparams)
  File "/home/airflow/.local/lib/python3.6/site-packages/sqlalchemy/engine/default.py", line 508, in connect
    return self.dbapi.connect(*cargs, **cparams)
  File "/home/airflow/.local/lib/python3.6/site-packages/psycopg2/__init__.py", line 127, in connect
    conn = _connect(dsn, connection_factory=connection_factory, **kwasync)
sqlalchemy.exc.OperationalError: (psycopg2.OperationalError) could not translate host name "db" to address: Name or service not known

(Background on this error at: http://sqlalche.me/e/13/e3q8)
[2023-03-10 21:31:46,837] {scheduler_job.py:641} WARNING - No viable dags retrieved from /opt/airflow/dags/spent_by_user.py
[2023-03-10 21:31:46,873] {scheduler_job.py:190} INFO - Processing /opt/airflow/dags/spent_by_user.py took 0.131 seconds
[2023-03-10 21:32:17,443] {scheduler_job.py:182} INFO - Started process (PID=453) to work on /opt/airflow/dags/spent_by_user.py
[2023-03-10 21:32:17,447] {scheduler_job.py:629} INFO - Processing file /opt/airflow/dags/spent_by_user.py for tasks to queue
[2023-03-10 21:32:17,450] {logging_mixin.py:104} INFO - [2023-03-10 21:32:17,450] {dagbag.py:448} INFO - Filling up the DagBag from /opt/airflow/dags/spent_by_user.py
[2023-03-10 21:32:17,515] {logging_mixin.py:104} INFO - [2023-03-10 21:32:17,494] {dagbag.py:305} ERROR - Failed to import: /opt/airflow/dags/spent_by_user.py
Traceback (most recent call last):
  File "/home/airflow/.local/lib/python3.6/site-packages/sqlalchemy/engine/base.py", line 2336, in _wrap_pool_connect
    return fn()
  File "/home/airflow/.local/lib/python3.6/site-packages/sqlalchemy/pool/base.py", line 364, in connect
    return _ConnectionFairy._checkout(self)
  File "/home/airflow/.local/lib/python3.6/site-packages/sqlalchemy/pool/base.py", line 778, in _checkout
    fairy = _ConnectionRecord.checkout(pool)
  File "/home/airflow/.local/lib/python3.6/site-packages/sqlalchemy/pool/base.py", line 495, in checkout
    rec = pool._do_get()
  File "/home/airflow/.local/lib/python3.6/site-packages/sqlalchemy/pool/impl.py", line 140, in _do_get
    self._dec_overflow()
  File "/home/airflow/.local/lib/python3.6/site-packages/sqlalchemy/util/langhelpers.py", line 70, in __exit__
    with_traceback=exc_tb,
  File "/home/airflow/.local/lib/python3.6/site-packages/sqlalchemy/util/compat.py", line 182, in raise_
    raise exception
  File "/home/airflow/.local/lib/python3.6/site-packages/sqlalchemy/pool/impl.py", line 137, in _do_get
    return self._create_connection()
  File "/home/airflow/.local/lib/python3.6/site-packages/sqlalchemy/pool/base.py", line 309, in _create_connection
    return _ConnectionRecord(self)
  File "/home/airflow/.local/lib/python3.6/site-packages/sqlalchemy/pool/base.py", line 440, in __init__
    self.__connect(first_connect_check=True)
  File "/home/airflow/.local/lib/python3.6/site-packages/sqlalchemy/pool/base.py", line 661, in __connect
    pool.logger.debug("Error on connect(): %s", e)
  File "/home/airflow/.local/lib/python3.6/site-packages/sqlalchemy/util/langhelpers.py", line 70, in __exit__
    with_traceback=exc_tb,
  File "/home/airflow/.local/lib/python3.6/site-packages/sqlalchemy/util/compat.py", line 182, in raise_
    raise exception
  File "/home/airflow/.local/lib/python3.6/site-packages/sqlalchemy/pool/base.py", line 656, in __connect
    connection = pool._invoke_creator(self)
  File "/home/airflow/.local/lib/python3.6/site-packages/sqlalchemy/engine/strategies.py", line 114, in connect
    return dialect.connect(*cargs, **cparams)
  File "/home/airflow/.local/lib/python3.6/site-packages/sqlalchemy/engine/default.py", line 508, in connect
    return self.dbapi.connect(*cargs, **cparams)
  File "/home/airflow/.local/lib/python3.6/site-packages/psycopg2/__init__.py", line 127, in connect
    conn = _connect(dsn, connection_factory=connection_factory, **kwasync)
psycopg2.OperationalError: could not translate host name "db" to address: Name or service not known


The above exception was the direct cause of the following exception:

Traceback (most recent call last):
  File "/home/airflow/.local/lib/python3.6/site-packages/airflow/models/dagbag.py", line 302, in _load_modules_from_file
    loader.exec_module(new_module)
  File "<frozen importlib._bootstrap_external>", line 678, in exec_module
  File "<frozen importlib._bootstrap>", line 219, in _call_with_frames_removed
  File "/opt/airflow/dags/spent_by_user.py", line 20, in <module>
    Base.metadata.create_all(bind=engine, tables=[UserTotalSpent.__table__])
  File "/home/airflow/.local/lib/python3.6/site-packages/sqlalchemy/sql/schema.py", line 4664, in create_all
    ddl.SchemaGenerator, self, checkfirst=checkfirst, tables=tables
  File "/home/airflow/.local/lib/python3.6/site-packages/sqlalchemy/engine/base.py", line 2094, in _run_visitor
    with self._optional_conn_ctx_manager(connection) as conn:
  File "/usr/local/lib/python3.6/contextlib.py", line 81, in __enter__
    return next(self.gen)
  File "/home/airflow/.local/lib/python3.6/site-packages/sqlalchemy/engine/base.py", line 2086, in _optional_conn_ctx_manager
    with self._contextual_connect() as conn:
  File "/home/airflow/.local/lib/python3.6/site-packages/sqlalchemy/engine/base.py", line 2302, in _contextual_connect
    self._wrap_pool_connect(self.pool.connect, None),
  File "/home/airflow/.local/lib/python3.6/site-packages/sqlalchemy/engine/base.py", line 2340, in _wrap_pool_connect
    e, dialect, self
  File "/home/airflow/.local/lib/python3.6/site-packages/sqlalchemy/engine/base.py", line 1584, in _handle_dbapi_exception_noconnection
    sqlalchemy_exception, with_traceback=exc_info[2], from_=e
  File "/home/airflow/.local/lib/python3.6/site-packages/sqlalchemy/util/compat.py", line 182, in raise_
    raise exception
  File "/home/airflow/.local/lib/python3.6/site-packages/sqlalchemy/engine/base.py", line 2336, in _wrap_pool_connect
    return fn()
  File "/home/airflow/.local/lib/python3.6/site-packages/sqlalchemy/pool/base.py", line 364, in connect
    return _ConnectionFairy._checkout(self)
  File "/home/airflow/.local/lib/python3.6/site-packages/sqlalchemy/pool/base.py", line 778, in _checkout
    fairy = _ConnectionRecord.checkout(pool)
  File "/home/airflow/.local/lib/python3.6/site-packages/sqlalchemy/pool/base.py", line 495, in checkout
    rec = pool._do_get()
  File "/home/airflow/.local/lib/python3.6/site-packages/sqlalchemy/pool/impl.py", line 140, in _do_get
    self._dec_overflow()
  File "/home/airflow/.local/lib/python3.6/site-packages/sqlalchemy/util/langhelpers.py", line 70, in __exit__
    with_traceback=exc_tb,
  File "/home/airflow/.local/lib/python3.6/site-packages/sqlalchemy/util/compat.py", line 182, in raise_
    raise exception
  File "/home/airflow/.local/lib/python3.6/site-packages/sqlalchemy/pool/impl.py", line 137, in _do_get
    return self._create_connection()
  File "/home/airflow/.local/lib/python3.6/site-packages/sqlalchemy/pool/base.py", line 309, in _create_connection
    return _ConnectionRecord(self)
  File "/home/airflow/.local/lib/python3.6/site-packages/sqlalchemy/pool/base.py", line 440, in __init__
    self.__connect(first_connect_check=True)
  File "/home/airflow/.local/lib/python3.6/site-packages/sqlalchemy/pool/base.py", line 661, in __connect
    pool.logger.debug("Error on connect(): %s", e)
  File "/home/airflow/.local/lib/python3.6/site-packages/sqlalchemy/util/langhelpers.py", line 70, in __exit__
    with_traceback=exc_tb,
  File "/home/airflow/.local/lib/python3.6/site-packages/sqlalchemy/util/compat.py", line 182, in raise_
    raise exception
  File "/home/airflow/.local/lib/python3.6/site-packages/sqlalchemy/pool/base.py", line 656, in __connect
    connection = pool._invoke_creator(self)
  File "/home/airflow/.local/lib/python3.6/site-packages/sqlalchemy/engine/strategies.py", line 114, in connect
    return dialect.connect(*cargs, **cparams)
  File "/home/airflow/.local/lib/python3.6/site-packages/sqlalchemy/engine/default.py", line 508, in connect
    return self.dbapi.connect(*cargs, **cparams)
  File "/home/airflow/.local/lib/python3.6/site-packages/psycopg2/__init__.py", line 127, in connect
    conn = _connect(dsn, connection_factory=connection_factory, **kwasync)
sqlalchemy.exc.OperationalError: (psycopg2.OperationalError) could not translate host name "db" to address: Name or service not known

(Background on this error at: http://sqlalche.me/e/13/e3q8)
[2023-03-10 21:32:17,522] {scheduler_job.py:641} WARNING - No viable dags retrieved from /opt/airflow/dags/spent_by_user.py
[2023-03-10 21:32:17,554] {scheduler_job.py:190} INFO - Processing /opt/airflow/dags/spent_by_user.py took 0.118 seconds
[2023-03-10 21:32:47,785] {scheduler_job.py:182} INFO - Started process (PID=507) to work on /opt/airflow/dags/spent_by_user.py
[2023-03-10 21:32:47,790] {scheduler_job.py:629} INFO - Processing file /opt/airflow/dags/spent_by_user.py for tasks to queue
[2023-03-10 21:32:47,793] {logging_mixin.py:104} INFO - [2023-03-10 21:32:47,793] {dagbag.py:448} INFO - Filling up the DagBag from /opt/airflow/dags/spent_by_user.py
[2023-03-10 21:32:48,009] {logging_mixin.py:104} INFO - [2023-03-10 21:32:47,988] {dagbag.py:305} ERROR - Failed to import: /opt/airflow/dags/spent_by_user.py
Traceback (most recent call last):
  File "/home/airflow/.local/lib/python3.6/site-packages/sqlalchemy/engine/base.py", line 2336, in _wrap_pool_connect
    return fn()
  File "/home/airflow/.local/lib/python3.6/site-packages/sqlalchemy/pool/base.py", line 364, in connect
    return _ConnectionFairy._checkout(self)
  File "/home/airflow/.local/lib/python3.6/site-packages/sqlalchemy/pool/base.py", line 778, in _checkout
    fairy = _ConnectionRecord.checkout(pool)
  File "/home/airflow/.local/lib/python3.6/site-packages/sqlalchemy/pool/base.py", line 495, in checkout
    rec = pool._do_get()
  File "/home/airflow/.local/lib/python3.6/site-packages/sqlalchemy/pool/impl.py", line 140, in _do_get
    self._dec_overflow()
  File "/home/airflow/.local/lib/python3.6/site-packages/sqlalchemy/util/langhelpers.py", line 70, in __exit__
    with_traceback=exc_tb,
  File "/home/airflow/.local/lib/python3.6/site-packages/sqlalchemy/util/compat.py", line 182, in raise_
    raise exception
  File "/home/airflow/.local/lib/python3.6/site-packages/sqlalchemy/pool/impl.py", line 137, in _do_get
    return self._create_connection()
  File "/home/airflow/.local/lib/python3.6/site-packages/sqlalchemy/pool/base.py", line 309, in _create_connection
    return _ConnectionRecord(self)
  File "/home/airflow/.local/lib/python3.6/site-packages/sqlalchemy/pool/base.py", line 440, in __init__
    self.__connect(first_connect_check=True)
  File "/home/airflow/.local/lib/python3.6/site-packages/sqlalchemy/pool/base.py", line 661, in __connect
    pool.logger.debug("Error on connect(): %s", e)
  File "/home/airflow/.local/lib/python3.6/site-packages/sqlalchemy/util/langhelpers.py", line 70, in __exit__
    with_traceback=exc_tb,
  File "/home/airflow/.local/lib/python3.6/site-packages/sqlalchemy/util/compat.py", line 182, in raise_
    raise exception
  File "/home/airflow/.local/lib/python3.6/site-packages/sqlalchemy/pool/base.py", line 656, in __connect
    connection = pool._invoke_creator(self)
  File "/home/airflow/.local/lib/python3.6/site-packages/sqlalchemy/engine/strategies.py", line 114, in connect
    return dialect.connect(*cargs, **cparams)
  File "/home/airflow/.local/lib/python3.6/site-packages/sqlalchemy/engine/default.py", line 508, in connect
    return self.dbapi.connect(*cargs, **cparams)
  File "/home/airflow/.local/lib/python3.6/site-packages/psycopg2/__init__.py", line 127, in connect
    conn = _connect(dsn, connection_factory=connection_factory, **kwasync)
psycopg2.OperationalError: could not translate host name "db" to address: Name or service not known


The above exception was the direct cause of the following exception:

Traceback (most recent call last):
  File "/home/airflow/.local/lib/python3.6/site-packages/airflow/models/dagbag.py", line 302, in _load_modules_from_file
    loader.exec_module(new_module)
  File "<frozen importlib._bootstrap_external>", line 678, in exec_module
  File "<frozen importlib._bootstrap>", line 219, in _call_with_frames_removed
  File "/opt/airflow/dags/spent_by_user.py", line 20, in <module>
    Base.metadata.create_all(bind=engine, tables=[UserTotalSpent.__table__])
  File "/home/airflow/.local/lib/python3.6/site-packages/sqlalchemy/sql/schema.py", line 4664, in create_all
    ddl.SchemaGenerator, self, checkfirst=checkfirst, tables=tables
  File "/home/airflow/.local/lib/python3.6/site-packages/sqlalchemy/engine/base.py", line 2094, in _run_visitor
    with self._optional_conn_ctx_manager(connection) as conn:
  File "/usr/local/lib/python3.6/contextlib.py", line 81, in __enter__
    return next(self.gen)
  File "/home/airflow/.local/lib/python3.6/site-packages/sqlalchemy/engine/base.py", line 2086, in _optional_conn_ctx_manager
    with self._contextual_connect() as conn:
  File "/home/airflow/.local/lib/python3.6/site-packages/sqlalchemy/engine/base.py", line 2302, in _contextual_connect
    self._wrap_pool_connect(self.pool.connect, None),
  File "/home/airflow/.local/lib/python3.6/site-packages/sqlalchemy/engine/base.py", line 2340, in _wrap_pool_connect
    e, dialect, self
  File "/home/airflow/.local/lib/python3.6/site-packages/sqlalchemy/engine/base.py", line 1584, in _handle_dbapi_exception_noconnection
    sqlalchemy_exception, with_traceback=exc_info[2], from_=e
  File "/home/airflow/.local/lib/python3.6/site-packages/sqlalchemy/util/compat.py", line 182, in raise_
    raise exception
  File "/home/airflow/.local/lib/python3.6/site-packages/sqlalchemy/engine/base.py", line 2336, in _wrap_pool_connect
    return fn()
  File "/home/airflow/.local/lib/python3.6/site-packages/sqlalchemy/pool/base.py", line 364, in connect
    return _ConnectionFairy._checkout(self)
  File "/home/airflow/.local/lib/python3.6/site-packages/sqlalchemy/pool/base.py", line 778, in _checkout
    fairy = _ConnectionRecord.checkout(pool)
  File "/home/airflow/.local/lib/python3.6/site-packages/sqlalchemy/pool/base.py", line 495, in checkout
    rec = pool._do_get()
  File "/home/airflow/.local/lib/python3.6/site-packages/sqlalchemy/pool/impl.py", line 140, in _do_get
    self._dec_overflow()
  File "/home/airflow/.local/lib/python3.6/site-packages/sqlalchemy/util/langhelpers.py", line 70, in __exit__
    with_traceback=exc_tb,
  File "/home/airflow/.local/lib/python3.6/site-packages/sqlalchemy/util/compat.py", line 182, in raise_
    raise exception
  File "/home/airflow/.local/lib/python3.6/site-packages/sqlalchemy/pool/impl.py", line 137, in _do_get
    return self._create_connection()
  File "/home/airflow/.local/lib/python3.6/site-packages/sqlalchemy/pool/base.py", line 309, in _create_connection
    return _ConnectionRecord(self)
  File "/home/airflow/.local/lib/python3.6/site-packages/sqlalchemy/pool/base.py", line 440, in __init__
    self.__connect(first_connect_check=True)
  File "/home/airflow/.local/lib/python3.6/site-packages/sqlalchemy/pool/base.py", line 661, in __connect
    pool.logger.debug("Error on connect(): %s", e)
  File "/home/airflow/.local/lib/python3.6/site-packages/sqlalchemy/util/langhelpers.py", line 70, in __exit__
    with_traceback=exc_tb,
  File "/home/airflow/.local/lib/python3.6/site-packages/sqlalchemy/util/compat.py", line 182, in raise_
    raise exception
  File "/home/airflow/.local/lib/python3.6/site-packages/sqlalchemy/pool/base.py", line 656, in __connect
    connection = pool._invoke_creator(self)
  File "/home/airflow/.local/lib/python3.6/site-packages/sqlalchemy/engine/strategies.py", line 114, in connect
    return dialect.connect(*cargs, **cparams)
  File "/home/airflow/.local/lib/python3.6/site-packages/sqlalchemy/engine/default.py", line 508, in connect
    return self.dbapi.connect(*cargs, **cparams)
  File "/home/airflow/.local/lib/python3.6/site-packages/psycopg2/__init__.py", line 127, in connect
    conn = _connect(dsn, connection_factory=connection_factory, **kwasync)
sqlalchemy.exc.OperationalError: (psycopg2.OperationalError) could not translate host name "db" to address: Name or service not known

(Background on this error at: http://sqlalche.me/e/13/e3q8)
[2023-03-10 21:32:48,017] {scheduler_job.py:641} WARNING - No viable dags retrieved from /opt/airflow/dags/spent_by_user.py
[2023-03-10 21:32:48,056] {scheduler_job.py:190} INFO - Processing /opt/airflow/dags/spent_by_user.py took 0.278 seconds
[2023-03-10 21:33:18,454] {scheduler_job.py:182} INFO - Started process (PID=561) to work on /opt/airflow/dags/spent_by_user.py
[2023-03-10 21:33:18,458] {scheduler_job.py:629} INFO - Processing file /opt/airflow/dags/spent_by_user.py for tasks to queue
[2023-03-10 21:33:18,461] {logging_mixin.py:104} INFO - [2023-03-10 21:33:18,460] {dagbag.py:448} INFO - Filling up the DagBag from /opt/airflow/dags/spent_by_user.py
[2023-03-10 21:33:18,536] {logging_mixin.py:104} INFO - [2023-03-10 21:33:18,513] {dagbag.py:305} ERROR - Failed to import: /opt/airflow/dags/spent_by_user.py
Traceback (most recent call last):
  File "/home/airflow/.local/lib/python3.6/site-packages/sqlalchemy/engine/base.py", line 2336, in _wrap_pool_connect
    return fn()
  File "/home/airflow/.local/lib/python3.6/site-packages/sqlalchemy/pool/base.py", line 364, in connect
    return _ConnectionFairy._checkout(self)
  File "/home/airflow/.local/lib/python3.6/site-packages/sqlalchemy/pool/base.py", line 778, in _checkout
    fairy = _ConnectionRecord.checkout(pool)
  File "/home/airflow/.local/lib/python3.6/site-packages/sqlalchemy/pool/base.py", line 495, in checkout
    rec = pool._do_get()
  File "/home/airflow/.local/lib/python3.6/site-packages/sqlalchemy/pool/impl.py", line 140, in _do_get
    self._dec_overflow()
  File "/home/airflow/.local/lib/python3.6/site-packages/sqlalchemy/util/langhelpers.py", line 70, in __exit__
    with_traceback=exc_tb,
  File "/home/airflow/.local/lib/python3.6/site-packages/sqlalchemy/util/compat.py", line 182, in raise_
    raise exception
  File "/home/airflow/.local/lib/python3.6/site-packages/sqlalchemy/pool/impl.py", line 137, in _do_get
    return self._create_connection()
  File "/home/airflow/.local/lib/python3.6/site-packages/sqlalchemy/pool/base.py", line 309, in _create_connection
    return _ConnectionRecord(self)
  File "/home/airflow/.local/lib/python3.6/site-packages/sqlalchemy/pool/base.py", line 440, in __init__
    self.__connect(first_connect_check=True)
  File "/home/airflow/.local/lib/python3.6/site-packages/sqlalchemy/pool/base.py", line 661, in __connect
    pool.logger.debug("Error on connect(): %s", e)
  File "/home/airflow/.local/lib/python3.6/site-packages/sqlalchemy/util/langhelpers.py", line 70, in __exit__
    with_traceback=exc_tb,
  File "/home/airflow/.local/lib/python3.6/site-packages/sqlalchemy/util/compat.py", line 182, in raise_
    raise exception
  File "/home/airflow/.local/lib/python3.6/site-packages/sqlalchemy/pool/base.py", line 656, in __connect
    connection = pool._invoke_creator(self)
  File "/home/airflow/.local/lib/python3.6/site-packages/sqlalchemy/engine/strategies.py", line 114, in connect
    return dialect.connect(*cargs, **cparams)
  File "/home/airflow/.local/lib/python3.6/site-packages/sqlalchemy/engine/default.py", line 508, in connect
    return self.dbapi.connect(*cargs, **cparams)
  File "/home/airflow/.local/lib/python3.6/site-packages/psycopg2/__init__.py", line 127, in connect
    conn = _connect(dsn, connection_factory=connection_factory, **kwasync)
psycopg2.OperationalError: could not translate host name "db" to address: Name or service not known


The above exception was the direct cause of the following exception:

Traceback (most recent call last):
  File "/home/airflow/.local/lib/python3.6/site-packages/airflow/models/dagbag.py", line 302, in _load_modules_from_file
    loader.exec_module(new_module)
  File "<frozen importlib._bootstrap_external>", line 678, in exec_module
  File "<frozen importlib._bootstrap>", line 219, in _call_with_frames_removed
  File "/opt/airflow/dags/spent_by_user.py", line 20, in <module>
    Base.metadata.create_all(bind=engine, tables=[UserTotalSpent.__table__])
  File "/home/airflow/.local/lib/python3.6/site-packages/sqlalchemy/sql/schema.py", line 4664, in create_all
    ddl.SchemaGenerator, self, checkfirst=checkfirst, tables=tables
  File "/home/airflow/.local/lib/python3.6/site-packages/sqlalchemy/engine/base.py", line 2094, in _run_visitor
    with self._optional_conn_ctx_manager(connection) as conn:
  File "/usr/local/lib/python3.6/contextlib.py", line 81, in __enter__
    return next(self.gen)
  File "/home/airflow/.local/lib/python3.6/site-packages/sqlalchemy/engine/base.py", line 2086, in _optional_conn_ctx_manager
    with self._contextual_connect() as conn:
  File "/home/airflow/.local/lib/python3.6/site-packages/sqlalchemy/engine/base.py", line 2302, in _contextual_connect
    self._wrap_pool_connect(self.pool.connect, None),
  File "/home/airflow/.local/lib/python3.6/site-packages/sqlalchemy/engine/base.py", line 2340, in _wrap_pool_connect
    e, dialect, self
  File "/home/airflow/.local/lib/python3.6/site-packages/sqlalchemy/engine/base.py", line 1584, in _handle_dbapi_exception_noconnection
    sqlalchemy_exception, with_traceback=exc_info[2], from_=e
  File "/home/airflow/.local/lib/python3.6/site-packages/sqlalchemy/util/compat.py", line 182, in raise_
    raise exception
  File "/home/airflow/.local/lib/python3.6/site-packages/sqlalchemy/engine/base.py", line 2336, in _wrap_pool_connect
    return fn()
  File "/home/airflow/.local/lib/python3.6/site-packages/sqlalchemy/pool/base.py", line 364, in connect
    return _ConnectionFairy._checkout(self)
  File "/home/airflow/.local/lib/python3.6/site-packages/sqlalchemy/pool/base.py", line 778, in _checkout
    fairy = _ConnectionRecord.checkout(pool)
  File "/home/airflow/.local/lib/python3.6/site-packages/sqlalchemy/pool/base.py", line 495, in checkout
    rec = pool._do_get()
  File "/home/airflow/.local/lib/python3.6/site-packages/sqlalchemy/pool/impl.py", line 140, in _do_get
    self._dec_overflow()
  File "/home/airflow/.local/lib/python3.6/site-packages/sqlalchemy/util/langhelpers.py", line 70, in __exit__
    with_traceback=exc_tb,
  File "/home/airflow/.local/lib/python3.6/site-packages/sqlalchemy/util/compat.py", line 182, in raise_
    raise exception
  File "/home/airflow/.local/lib/python3.6/site-packages/sqlalchemy/pool/impl.py", line 137, in _do_get
    return self._create_connection()
  File "/home/airflow/.local/lib/python3.6/site-packages/sqlalchemy/pool/base.py", line 309, in _create_connection
    return _ConnectionRecord(self)
  File "/home/airflow/.local/lib/python3.6/site-packages/sqlalchemy/pool/base.py", line 440, in __init__
    self.__connect(first_connect_check=True)
  File "/home/airflow/.local/lib/python3.6/site-packages/sqlalchemy/pool/base.py", line 661, in __connect
    pool.logger.debug("Error on connect(): %s", e)
  File "/home/airflow/.local/lib/python3.6/site-packages/sqlalchemy/util/langhelpers.py", line 70, in __exit__
    with_traceback=exc_tb,
  File "/home/airflow/.local/lib/python3.6/site-packages/sqlalchemy/util/compat.py", line 182, in raise_
    raise exception
  File "/home/airflow/.local/lib/python3.6/site-packages/sqlalchemy/pool/base.py", line 656, in __connect
    connection = pool._invoke_creator(self)
  File "/home/airflow/.local/lib/python3.6/site-packages/sqlalchemy/engine/strategies.py", line 114, in connect
    return dialect.connect(*cargs, **cparams)
  File "/home/airflow/.local/lib/python3.6/site-packages/sqlalchemy/engine/default.py", line 508, in connect
    return self.dbapi.connect(*cargs, **cparams)
  File "/home/airflow/.local/lib/python3.6/site-packages/psycopg2/__init__.py", line 127, in connect
    conn = _connect(dsn, connection_factory=connection_factory, **kwasync)
sqlalchemy.exc.OperationalError: (psycopg2.OperationalError) could not translate host name "db" to address: Name or service not known

(Background on this error at: http://sqlalche.me/e/13/e3q8)
[2023-03-10 21:33:18,544] {scheduler_job.py:641} WARNING - No viable dags retrieved from /opt/airflow/dags/spent_by_user.py
[2023-03-10 21:33:18,577] {scheduler_job.py:190} INFO - Processing /opt/airflow/dags/spent_by_user.py took 0.129 seconds
[2023-03-10 21:33:49,407] {scheduler_job.py:182} INFO - Started process (PID=613) to work on /opt/airflow/dags/spent_by_user.py
[2023-03-10 21:33:49,413] {scheduler_job.py:629} INFO - Processing file /opt/airflow/dags/spent_by_user.py for tasks to queue
[2023-03-10 21:33:49,418] {logging_mixin.py:104} INFO - [2023-03-10 21:33:49,418] {dagbag.py:448} INFO - Filling up the DagBag from /opt/airflow/dags/spent_by_user.py
[2023-03-10 21:33:49,501] {logging_mixin.py:104} INFO - [2023-03-10 21:33:49,479] {dagbag.py:305} ERROR - Failed to import: /opt/airflow/dags/spent_by_user.py
Traceback (most recent call last):
  File "/home/airflow/.local/lib/python3.6/site-packages/sqlalchemy/engine/base.py", line 2336, in _wrap_pool_connect
    return fn()
  File "/home/airflow/.local/lib/python3.6/site-packages/sqlalchemy/pool/base.py", line 364, in connect
    return _ConnectionFairy._checkout(self)
  File "/home/airflow/.local/lib/python3.6/site-packages/sqlalchemy/pool/base.py", line 778, in _checkout
    fairy = _ConnectionRecord.checkout(pool)
  File "/home/airflow/.local/lib/python3.6/site-packages/sqlalchemy/pool/base.py", line 495, in checkout
    rec = pool._do_get()
  File "/home/airflow/.local/lib/python3.6/site-packages/sqlalchemy/pool/impl.py", line 140, in _do_get
    self._dec_overflow()
  File "/home/airflow/.local/lib/python3.6/site-packages/sqlalchemy/util/langhelpers.py", line 70, in __exit__
    with_traceback=exc_tb,
  File "/home/airflow/.local/lib/python3.6/site-packages/sqlalchemy/util/compat.py", line 182, in raise_
    raise exception
  File "/home/airflow/.local/lib/python3.6/site-packages/sqlalchemy/pool/impl.py", line 137, in _do_get
    return self._create_connection()
  File "/home/airflow/.local/lib/python3.6/site-packages/sqlalchemy/pool/base.py", line 309, in _create_connection
    return _ConnectionRecord(self)
  File "/home/airflow/.local/lib/python3.6/site-packages/sqlalchemy/pool/base.py", line 440, in __init__
    self.__connect(first_connect_check=True)
  File "/home/airflow/.local/lib/python3.6/site-packages/sqlalchemy/pool/base.py", line 661, in __connect
    pool.logger.debug("Error on connect(): %s", e)
  File "/home/airflow/.local/lib/python3.6/site-packages/sqlalchemy/util/langhelpers.py", line 70, in __exit__
    with_traceback=exc_tb,
  File "/home/airflow/.local/lib/python3.6/site-packages/sqlalchemy/util/compat.py", line 182, in raise_
    raise exception
  File "/home/airflow/.local/lib/python3.6/site-packages/sqlalchemy/pool/base.py", line 656, in __connect
    connection = pool._invoke_creator(self)
  File "/home/airflow/.local/lib/python3.6/site-packages/sqlalchemy/engine/strategies.py", line 114, in connect
    return dialect.connect(*cargs, **cparams)
  File "/home/airflow/.local/lib/python3.6/site-packages/sqlalchemy/engine/default.py", line 508, in connect
    return self.dbapi.connect(*cargs, **cparams)
  File "/home/airflow/.local/lib/python3.6/site-packages/psycopg2/__init__.py", line 127, in connect
    conn = _connect(dsn, connection_factory=connection_factory, **kwasync)
psycopg2.OperationalError: could not translate host name "db" to address: Name or service not known


The above exception was the direct cause of the following exception:

Traceback (most recent call last):
  File "/home/airflow/.local/lib/python3.6/site-packages/airflow/models/dagbag.py", line 302, in _load_modules_from_file
    loader.exec_module(new_module)
  File "<frozen importlib._bootstrap_external>", line 678, in exec_module
  File "<frozen importlib._bootstrap>", line 219, in _call_with_frames_removed
  File "/opt/airflow/dags/spent_by_user.py", line 20, in <module>
    Base.metadata.create_all(bind=engine, tables=[UserTotalSpent.__table__])
  File "/home/airflow/.local/lib/python3.6/site-packages/sqlalchemy/sql/schema.py", line 4664, in create_all
    ddl.SchemaGenerator, self, checkfirst=checkfirst, tables=tables
  File "/home/airflow/.local/lib/python3.6/site-packages/sqlalchemy/engine/base.py", line 2094, in _run_visitor
    with self._optional_conn_ctx_manager(connection) as conn:
  File "/usr/local/lib/python3.6/contextlib.py", line 81, in __enter__
    return next(self.gen)
  File "/home/airflow/.local/lib/python3.6/site-packages/sqlalchemy/engine/base.py", line 2086, in _optional_conn_ctx_manager
    with self._contextual_connect() as conn:
  File "/home/airflow/.local/lib/python3.6/site-packages/sqlalchemy/engine/base.py", line 2302, in _contextual_connect
    self._wrap_pool_connect(self.pool.connect, None),
  File "/home/airflow/.local/lib/python3.6/site-packages/sqlalchemy/engine/base.py", line 2340, in _wrap_pool_connect
    e, dialect, self
  File "/home/airflow/.local/lib/python3.6/site-packages/sqlalchemy/engine/base.py", line 1584, in _handle_dbapi_exception_noconnection
    sqlalchemy_exception, with_traceback=exc_info[2], from_=e
  File "/home/airflow/.local/lib/python3.6/site-packages/sqlalchemy/util/compat.py", line 182, in raise_
    raise exception
  File "/home/airflow/.local/lib/python3.6/site-packages/sqlalchemy/engine/base.py", line 2336, in _wrap_pool_connect
    return fn()
  File "/home/airflow/.local/lib/python3.6/site-packages/sqlalchemy/pool/base.py", line 364, in connect
    return _ConnectionFairy._checkout(self)
  File "/home/airflow/.local/lib/python3.6/site-packages/sqlalchemy/pool/base.py", line 778, in _checkout
    fairy = _ConnectionRecord.checkout(pool)
  File "/home/airflow/.local/lib/python3.6/site-packages/sqlalchemy/pool/base.py", line 495, in checkout
    rec = pool._do_get()
  File "/home/airflow/.local/lib/python3.6/site-packages/sqlalchemy/pool/impl.py", line 140, in _do_get
    self._dec_overflow()
  File "/home/airflow/.local/lib/python3.6/site-packages/sqlalchemy/util/langhelpers.py", line 70, in __exit__
    with_traceback=exc_tb,
  File "/home/airflow/.local/lib/python3.6/site-packages/sqlalchemy/util/compat.py", line 182, in raise_
    raise exception
  File "/home/airflow/.local/lib/python3.6/site-packages/sqlalchemy/pool/impl.py", line 137, in _do_get
    return self._create_connection()
  File "/home/airflow/.local/lib/python3.6/site-packages/sqlalchemy/pool/base.py", line 309, in _create_connection
    return _ConnectionRecord(self)
  File "/home/airflow/.local/lib/python3.6/site-packages/sqlalchemy/pool/base.py", line 440, in __init__
    self.__connect(first_connect_check=True)
  File "/home/airflow/.local/lib/python3.6/site-packages/sqlalchemy/pool/base.py", line 661, in __connect
    pool.logger.debug("Error on connect(): %s", e)
  File "/home/airflow/.local/lib/python3.6/site-packages/sqlalchemy/util/langhelpers.py", line 70, in __exit__
    with_traceback=exc_tb,
  File "/home/airflow/.local/lib/python3.6/site-packages/sqlalchemy/util/compat.py", line 182, in raise_
    raise exception
  File "/home/airflow/.local/lib/python3.6/site-packages/sqlalchemy/pool/base.py", line 656, in __connect
    connection = pool._invoke_creator(self)
  File "/home/airflow/.local/lib/python3.6/site-packages/sqlalchemy/engine/strategies.py", line 114, in connect
    return dialect.connect(*cargs, **cparams)
  File "/home/airflow/.local/lib/python3.6/site-packages/sqlalchemy/engine/default.py", line 508, in connect
    return self.dbapi.connect(*cargs, **cparams)
  File "/home/airflow/.local/lib/python3.6/site-packages/psycopg2/__init__.py", line 127, in connect
    conn = _connect(dsn, connection_factory=connection_factory, **kwasync)
sqlalchemy.exc.OperationalError: (psycopg2.OperationalError) could not translate host name "db" to address: Name or service not known

(Background on this error at: http://sqlalche.me/e/13/e3q8)
[2023-03-10 21:33:49,509] {scheduler_job.py:641} WARNING - No viable dags retrieved from /opt/airflow/dags/spent_by_user.py
[2023-03-10 21:33:49,541] {scheduler_job.py:190} INFO - Processing /opt/airflow/dags/spent_by_user.py took 0.143 seconds
[2023-03-10 21:50:19,337] {scheduler_job.py:182} INFO - Started process (PID=73) to work on /opt/airflow/dags/spent_by_user.py
[2023-03-10 21:50:19,342] {scheduler_job.py:629} INFO - Processing file /opt/airflow/dags/spent_by_user.py for tasks to queue
[2023-03-10 21:50:19,347] {logging_mixin.py:104} INFO - [2023-03-10 21:50:19,346] {dagbag.py:448} INFO - Filling up the DagBag from /opt/airflow/dags/spent_by_user.py
[2023-03-10 21:50:19,557] {logging_mixin.py:104} INFO - [2023-03-10 21:50:19,481] {dagbag.py:305} ERROR - Failed to import: /opt/airflow/dags/spent_by_user.py
Traceback (most recent call last):
  File "/home/airflow/.local/lib/python3.6/site-packages/sqlalchemy/engine/base.py", line 2336, in _wrap_pool_connect
    return fn()
  File "/home/airflow/.local/lib/python3.6/site-packages/sqlalchemy/pool/base.py", line 364, in connect
    return _ConnectionFairy._checkout(self)
  File "/home/airflow/.local/lib/python3.6/site-packages/sqlalchemy/pool/base.py", line 778, in _checkout
    fairy = _ConnectionRecord.checkout(pool)
  File "/home/airflow/.local/lib/python3.6/site-packages/sqlalchemy/pool/base.py", line 495, in checkout
    rec = pool._do_get()
  File "/home/airflow/.local/lib/python3.6/site-packages/sqlalchemy/pool/impl.py", line 140, in _do_get
    self._dec_overflow()
  File "/home/airflow/.local/lib/python3.6/site-packages/sqlalchemy/util/langhelpers.py", line 70, in __exit__
    with_traceback=exc_tb,
  File "/home/airflow/.local/lib/python3.6/site-packages/sqlalchemy/util/compat.py", line 182, in raise_
    raise exception
  File "/home/airflow/.local/lib/python3.6/site-packages/sqlalchemy/pool/impl.py", line 137, in _do_get
    return self._create_connection()
  File "/home/airflow/.local/lib/python3.6/site-packages/sqlalchemy/pool/base.py", line 309, in _create_connection
    return _ConnectionRecord(self)
  File "/home/airflow/.local/lib/python3.6/site-packages/sqlalchemy/pool/base.py", line 440, in __init__
    self.__connect(first_connect_check=True)
  File "/home/airflow/.local/lib/python3.6/site-packages/sqlalchemy/pool/base.py", line 661, in __connect
    pool.logger.debug("Error on connect(): %s", e)
  File "/home/airflow/.local/lib/python3.6/site-packages/sqlalchemy/util/langhelpers.py", line 70, in __exit__
    with_traceback=exc_tb,
  File "/home/airflow/.local/lib/python3.6/site-packages/sqlalchemy/util/compat.py", line 182, in raise_
    raise exception
  File "/home/airflow/.local/lib/python3.6/site-packages/sqlalchemy/pool/base.py", line 656, in __connect
    connection = pool._invoke_creator(self)
  File "/home/airflow/.local/lib/python3.6/site-packages/sqlalchemy/engine/strategies.py", line 114, in connect
    return dialect.connect(*cargs, **cparams)
  File "/home/airflow/.local/lib/python3.6/site-packages/sqlalchemy/engine/default.py", line 508, in connect
    return self.dbapi.connect(*cargs, **cparams)
  File "/home/airflow/.local/lib/python3.6/site-packages/psycopg2/__init__.py", line 127, in connect
    conn = _connect(dsn, connection_factory=connection_factory, **kwasync)
psycopg2.OperationalError: could not connect to server: Connection refused
	Is the server running on host "db" (172.28.0.7) and accepting
	TCP/IP connections on port 5431?


The above exception was the direct cause of the following exception:

Traceback (most recent call last):
  File "/home/airflow/.local/lib/python3.6/site-packages/airflow/models/dagbag.py", line 302, in _load_modules_from_file
    loader.exec_module(new_module)
  File "<frozen importlib._bootstrap_external>", line 678, in exec_module
  File "<frozen importlib._bootstrap>", line 219, in _call_with_frames_removed
  File "/opt/airflow/dags/spent_by_user.py", line 20, in <module>
    Base.metadata.create_all(bind=engine, tables=[UserTotalSpent.__table__])
  File "/home/airflow/.local/lib/python3.6/site-packages/sqlalchemy/sql/schema.py", line 4664, in create_all
    ddl.SchemaGenerator, self, checkfirst=checkfirst, tables=tables
  File "/home/airflow/.local/lib/python3.6/site-packages/sqlalchemy/engine/base.py", line 2094, in _run_visitor
    with self._optional_conn_ctx_manager(connection) as conn:
  File "/usr/local/lib/python3.6/contextlib.py", line 81, in __enter__
    return next(self.gen)
  File "/home/airflow/.local/lib/python3.6/site-packages/sqlalchemy/engine/base.py", line 2086, in _optional_conn_ctx_manager
    with self._contextual_connect() as conn:
  File "/home/airflow/.local/lib/python3.6/site-packages/sqlalchemy/engine/base.py", line 2302, in _contextual_connect
    self._wrap_pool_connect(self.pool.connect, None),
  File "/home/airflow/.local/lib/python3.6/site-packages/sqlalchemy/engine/base.py", line 2340, in _wrap_pool_connect
    e, dialect, self
  File "/home/airflow/.local/lib/python3.6/site-packages/sqlalchemy/engine/base.py", line 1584, in _handle_dbapi_exception_noconnection
    sqlalchemy_exception, with_traceback=exc_info[2], from_=e
  File "/home/airflow/.local/lib/python3.6/site-packages/sqlalchemy/util/compat.py", line 182, in raise_
    raise exception
  File "/home/airflow/.local/lib/python3.6/site-packages/sqlalchemy/engine/base.py", line 2336, in _wrap_pool_connect
    return fn()
  File "/home/airflow/.local/lib/python3.6/site-packages/sqlalchemy/pool/base.py", line 364, in connect
    return _ConnectionFairy._checkout(self)
  File "/home/airflow/.local/lib/python3.6/site-packages/sqlalchemy/pool/base.py", line 778, in _checkout
    fairy = _ConnectionRecord.checkout(pool)
  File "/home/airflow/.local/lib/python3.6/site-packages/sqlalchemy/pool/base.py", line 495, in checkout
    rec = pool._do_get()
  File "/home/airflow/.local/lib/python3.6/site-packages/sqlalchemy/pool/impl.py", line 140, in _do_get
    self._dec_overflow()
  File "/home/airflow/.local/lib/python3.6/site-packages/sqlalchemy/util/langhelpers.py", line 70, in __exit__
    with_traceback=exc_tb,
  File "/home/airflow/.local/lib/python3.6/site-packages/sqlalchemy/util/compat.py", line 182, in raise_
    raise exception
  File "/home/airflow/.local/lib/python3.6/site-packages/sqlalchemy/pool/impl.py", line 137, in _do_get
    return self._create_connection()
  File "/home/airflow/.local/lib/python3.6/site-packages/sqlalchemy/pool/base.py", line 309, in _create_connection
    return _ConnectionRecord(self)
  File "/home/airflow/.local/lib/python3.6/site-packages/sqlalchemy/pool/base.py", line 440, in __init__
    self.__connect(first_connect_check=True)
  File "/home/airflow/.local/lib/python3.6/site-packages/sqlalchemy/pool/base.py", line 661, in __connect
    pool.logger.debug("Error on connect(): %s", e)
  File "/home/airflow/.local/lib/python3.6/site-packages/sqlalchemy/util/langhelpers.py", line 70, in __exit__
    with_traceback=exc_tb,
  File "/home/airflow/.local/lib/python3.6/site-packages/sqlalchemy/util/compat.py", line 182, in raise_
    raise exception
  File "/home/airflow/.local/lib/python3.6/site-packages/sqlalchemy/pool/base.py", line 656, in __connect
    connection = pool._invoke_creator(self)
  File "/home/airflow/.local/lib/python3.6/site-packages/sqlalchemy/engine/strategies.py", line 114, in connect
    return dialect.connect(*cargs, **cparams)
  File "/home/airflow/.local/lib/python3.6/site-packages/sqlalchemy/engine/default.py", line 508, in connect
    return self.dbapi.connect(*cargs, **cparams)
  File "/home/airflow/.local/lib/python3.6/site-packages/psycopg2/__init__.py", line 127, in connect
    conn = _connect(dsn, connection_factory=connection_factory, **kwasync)
sqlalchemy.exc.OperationalError: (psycopg2.OperationalError) could not connect to server: Connection refused
	Is the server running on host "db" (172.28.0.7) and accepting
	TCP/IP connections on port 5431?

(Background on this error at: http://sqlalche.me/e/13/e3q8)
[2023-03-10 21:50:19,572] {scheduler_job.py:641} WARNING - No viable dags retrieved from /opt/airflow/dags/spent_by_user.py
[2023-03-10 21:50:19,672] {scheduler_job.py:190} INFO - Processing /opt/airflow/dags/spent_by_user.py took 0.344 seconds
[2023-03-10 21:50:50,444] {scheduler_job.py:182} INFO - Started process (PID=127) to work on /opt/airflow/dags/spent_by_user.py
[2023-03-10 21:50:50,450] {scheduler_job.py:629} INFO - Processing file /opt/airflow/dags/spent_by_user.py for tasks to queue
[2023-03-10 21:50:50,454] {logging_mixin.py:104} INFO - [2023-03-10 21:50:50,453] {dagbag.py:448} INFO - Filling up the DagBag from /opt/airflow/dags/spent_by_user.py
[2023-03-10 21:50:50,526] {logging_mixin.py:104} INFO - [2023-03-10 21:50:50,503] {dagbag.py:305} ERROR - Failed to import: /opt/airflow/dags/spent_by_user.py
Traceback (most recent call last):
  File "/home/airflow/.local/lib/python3.6/site-packages/sqlalchemy/engine/base.py", line 2336, in _wrap_pool_connect
    return fn()
  File "/home/airflow/.local/lib/python3.6/site-packages/sqlalchemy/pool/base.py", line 364, in connect
    return _ConnectionFairy._checkout(self)
  File "/home/airflow/.local/lib/python3.6/site-packages/sqlalchemy/pool/base.py", line 778, in _checkout
    fairy = _ConnectionRecord.checkout(pool)
  File "/home/airflow/.local/lib/python3.6/site-packages/sqlalchemy/pool/base.py", line 495, in checkout
    rec = pool._do_get()
  File "/home/airflow/.local/lib/python3.6/site-packages/sqlalchemy/pool/impl.py", line 140, in _do_get
    self._dec_overflow()
  File "/home/airflow/.local/lib/python3.6/site-packages/sqlalchemy/util/langhelpers.py", line 70, in __exit__
    with_traceback=exc_tb,
  File "/home/airflow/.local/lib/python3.6/site-packages/sqlalchemy/util/compat.py", line 182, in raise_
    raise exception
  File "/home/airflow/.local/lib/python3.6/site-packages/sqlalchemy/pool/impl.py", line 137, in _do_get
    return self._create_connection()
  File "/home/airflow/.local/lib/python3.6/site-packages/sqlalchemy/pool/base.py", line 309, in _create_connection
    return _ConnectionRecord(self)
  File "/home/airflow/.local/lib/python3.6/site-packages/sqlalchemy/pool/base.py", line 440, in __init__
    self.__connect(first_connect_check=True)
  File "/home/airflow/.local/lib/python3.6/site-packages/sqlalchemy/pool/base.py", line 661, in __connect
    pool.logger.debug("Error on connect(): %s", e)
  File "/home/airflow/.local/lib/python3.6/site-packages/sqlalchemy/util/langhelpers.py", line 70, in __exit__
    with_traceback=exc_tb,
  File "/home/airflow/.local/lib/python3.6/site-packages/sqlalchemy/util/compat.py", line 182, in raise_
    raise exception
  File "/home/airflow/.local/lib/python3.6/site-packages/sqlalchemy/pool/base.py", line 656, in __connect
    connection = pool._invoke_creator(self)
  File "/home/airflow/.local/lib/python3.6/site-packages/sqlalchemy/engine/strategies.py", line 114, in connect
    return dialect.connect(*cargs, **cparams)
  File "/home/airflow/.local/lib/python3.6/site-packages/sqlalchemy/engine/default.py", line 508, in connect
    return self.dbapi.connect(*cargs, **cparams)
  File "/home/airflow/.local/lib/python3.6/site-packages/psycopg2/__init__.py", line 127, in connect
    conn = _connect(dsn, connection_factory=connection_factory, **kwasync)
psycopg2.OperationalError: could not connect to server: Connection refused
	Is the server running on host "db" (172.28.0.7) and accepting
	TCP/IP connections on port 5431?


The above exception was the direct cause of the following exception:

Traceback (most recent call last):
  File "/home/airflow/.local/lib/python3.6/site-packages/airflow/models/dagbag.py", line 302, in _load_modules_from_file
    loader.exec_module(new_module)
  File "<frozen importlib._bootstrap_external>", line 678, in exec_module
  File "<frozen importlib._bootstrap>", line 219, in _call_with_frames_removed
  File "/opt/airflow/dags/spent_by_user.py", line 20, in <module>
    Base.metadata.create_all(bind=engine, tables=[UserTotalSpent.__table__])
  File "/home/airflow/.local/lib/python3.6/site-packages/sqlalchemy/sql/schema.py", line 4664, in create_all
    ddl.SchemaGenerator, self, checkfirst=checkfirst, tables=tables
  File "/home/airflow/.local/lib/python3.6/site-packages/sqlalchemy/engine/base.py", line 2094, in _run_visitor
    with self._optional_conn_ctx_manager(connection) as conn:
  File "/usr/local/lib/python3.6/contextlib.py", line 81, in __enter__
    return next(self.gen)
  File "/home/airflow/.local/lib/python3.6/site-packages/sqlalchemy/engine/base.py", line 2086, in _optional_conn_ctx_manager
    with self._contextual_connect() as conn:
  File "/home/airflow/.local/lib/python3.6/site-packages/sqlalchemy/engine/base.py", line 2302, in _contextual_connect
    self._wrap_pool_connect(self.pool.connect, None),
  File "/home/airflow/.local/lib/python3.6/site-packages/sqlalchemy/engine/base.py", line 2340, in _wrap_pool_connect
    e, dialect, self
  File "/home/airflow/.local/lib/python3.6/site-packages/sqlalchemy/engine/base.py", line 1584, in _handle_dbapi_exception_noconnection
    sqlalchemy_exception, with_traceback=exc_info[2], from_=e
  File "/home/airflow/.local/lib/python3.6/site-packages/sqlalchemy/util/compat.py", line 182, in raise_
    raise exception
  File "/home/airflow/.local/lib/python3.6/site-packages/sqlalchemy/engine/base.py", line 2336, in _wrap_pool_connect
    return fn()
  File "/home/airflow/.local/lib/python3.6/site-packages/sqlalchemy/pool/base.py", line 364, in connect
    return _ConnectionFairy._checkout(self)
  File "/home/airflow/.local/lib/python3.6/site-packages/sqlalchemy/pool/base.py", line 778, in _checkout
    fairy = _ConnectionRecord.checkout(pool)
  File "/home/airflow/.local/lib/python3.6/site-packages/sqlalchemy/pool/base.py", line 495, in checkout
    rec = pool._do_get()
  File "/home/airflow/.local/lib/python3.6/site-packages/sqlalchemy/pool/impl.py", line 140, in _do_get
    self._dec_overflow()
  File "/home/airflow/.local/lib/python3.6/site-packages/sqlalchemy/util/langhelpers.py", line 70, in __exit__
    with_traceback=exc_tb,
  File "/home/airflow/.local/lib/python3.6/site-packages/sqlalchemy/util/compat.py", line 182, in raise_
    raise exception
  File "/home/airflow/.local/lib/python3.6/site-packages/sqlalchemy/pool/impl.py", line 137, in _do_get
    return self._create_connection()
  File "/home/airflow/.local/lib/python3.6/site-packages/sqlalchemy/pool/base.py", line 309, in _create_connection
    return _ConnectionRecord(self)
  File "/home/airflow/.local/lib/python3.6/site-packages/sqlalchemy/pool/base.py", line 440, in __init__
    self.__connect(first_connect_check=True)
  File "/home/airflow/.local/lib/python3.6/site-packages/sqlalchemy/pool/base.py", line 661, in __connect
    pool.logger.debug("Error on connect(): %s", e)
  File "/home/airflow/.local/lib/python3.6/site-packages/sqlalchemy/util/langhelpers.py", line 70, in __exit__
    with_traceback=exc_tb,
  File "/home/airflow/.local/lib/python3.6/site-packages/sqlalchemy/util/compat.py", line 182, in raise_
    raise exception
  File "/home/airflow/.local/lib/python3.6/site-packages/sqlalchemy/pool/base.py", line 656, in __connect
    connection = pool._invoke_creator(self)
  File "/home/airflow/.local/lib/python3.6/site-packages/sqlalchemy/engine/strategies.py", line 114, in connect
    return dialect.connect(*cargs, **cparams)
  File "/home/airflow/.local/lib/python3.6/site-packages/sqlalchemy/engine/default.py", line 508, in connect
    return self.dbapi.connect(*cargs, **cparams)
  File "/home/airflow/.local/lib/python3.6/site-packages/psycopg2/__init__.py", line 127, in connect
    conn = _connect(dsn, connection_factory=connection_factory, **kwasync)
sqlalchemy.exc.OperationalError: (psycopg2.OperationalError) could not connect to server: Connection refused
	Is the server running on host "db" (172.28.0.7) and accepting
	TCP/IP connections on port 5431?

(Background on this error at: http://sqlalche.me/e/13/e3q8)
[2023-03-10 21:50:50,534] {scheduler_job.py:641} WARNING - No viable dags retrieved from /opt/airflow/dags/spent_by_user.py
[2023-03-10 21:50:50,570] {scheduler_job.py:190} INFO - Processing /opt/airflow/dags/spent_by_user.py took 0.134 seconds
[2023-03-10 21:51:21,314] {scheduler_job.py:182} INFO - Started process (PID=181) to work on /opt/airflow/dags/spent_by_user.py
[2023-03-10 21:51:21,320] {scheduler_job.py:629} INFO - Processing file /opt/airflow/dags/spent_by_user.py for tasks to queue
[2023-03-10 21:51:21,330] {logging_mixin.py:104} INFO - [2023-03-10 21:51:21,329] {dagbag.py:448} INFO - Filling up the DagBag from /opt/airflow/dags/spent_by_user.py
[2023-03-10 21:51:21,434] {logging_mixin.py:104} INFO - [2023-03-10 21:51:21,390] {dagbag.py:305} ERROR - Failed to import: /opt/airflow/dags/spent_by_user.py
Traceback (most recent call last):
  File "/home/airflow/.local/lib/python3.6/site-packages/sqlalchemy/engine/base.py", line 2336, in _wrap_pool_connect
    return fn()
  File "/home/airflow/.local/lib/python3.6/site-packages/sqlalchemy/pool/base.py", line 364, in connect
    return _ConnectionFairy._checkout(self)
  File "/home/airflow/.local/lib/python3.6/site-packages/sqlalchemy/pool/base.py", line 778, in _checkout
    fairy = _ConnectionRecord.checkout(pool)
  File "/home/airflow/.local/lib/python3.6/site-packages/sqlalchemy/pool/base.py", line 495, in checkout
    rec = pool._do_get()
  File "/home/airflow/.local/lib/python3.6/site-packages/sqlalchemy/pool/impl.py", line 140, in _do_get
    self._dec_overflow()
  File "/home/airflow/.local/lib/python3.6/site-packages/sqlalchemy/util/langhelpers.py", line 70, in __exit__
    with_traceback=exc_tb,
  File "/home/airflow/.local/lib/python3.6/site-packages/sqlalchemy/util/compat.py", line 182, in raise_
    raise exception
  File "/home/airflow/.local/lib/python3.6/site-packages/sqlalchemy/pool/impl.py", line 137, in _do_get
    return self._create_connection()
  File "/home/airflow/.local/lib/python3.6/site-packages/sqlalchemy/pool/base.py", line 309, in _create_connection
    return _ConnectionRecord(self)
  File "/home/airflow/.local/lib/python3.6/site-packages/sqlalchemy/pool/base.py", line 440, in __init__
    self.__connect(first_connect_check=True)
  File "/home/airflow/.local/lib/python3.6/site-packages/sqlalchemy/pool/base.py", line 661, in __connect
    pool.logger.debug("Error on connect(): %s", e)
  File "/home/airflow/.local/lib/python3.6/site-packages/sqlalchemy/util/langhelpers.py", line 70, in __exit__
    with_traceback=exc_tb,
  File "/home/airflow/.local/lib/python3.6/site-packages/sqlalchemy/util/compat.py", line 182, in raise_
    raise exception
  File "/home/airflow/.local/lib/python3.6/site-packages/sqlalchemy/pool/base.py", line 656, in __connect
    connection = pool._invoke_creator(self)
  File "/home/airflow/.local/lib/python3.6/site-packages/sqlalchemy/engine/strategies.py", line 114, in connect
    return dialect.connect(*cargs, **cparams)
  File "/home/airflow/.local/lib/python3.6/site-packages/sqlalchemy/engine/default.py", line 508, in connect
    return self.dbapi.connect(*cargs, **cparams)
  File "/home/airflow/.local/lib/python3.6/site-packages/psycopg2/__init__.py", line 127, in connect
    conn = _connect(dsn, connection_factory=connection_factory, **kwasync)
psycopg2.OperationalError: could not connect to server: Connection refused
	Is the server running on host "db" (172.28.0.7) and accepting
	TCP/IP connections on port 5431?


The above exception was the direct cause of the following exception:

Traceback (most recent call last):
  File "/home/airflow/.local/lib/python3.6/site-packages/airflow/models/dagbag.py", line 302, in _load_modules_from_file
    loader.exec_module(new_module)
  File "<frozen importlib._bootstrap_external>", line 678, in exec_module
  File "<frozen importlib._bootstrap>", line 219, in _call_with_frames_removed
  File "/opt/airflow/dags/spent_by_user.py", line 20, in <module>
    Base.metadata.create_all(bind=engine, tables=[UserTotalSpent.__table__])
  File "/home/airflow/.local/lib/python3.6/site-packages/sqlalchemy/sql/schema.py", line 4664, in create_all
    ddl.SchemaGenerator, self, checkfirst=checkfirst, tables=tables
  File "/home/airflow/.local/lib/python3.6/site-packages/sqlalchemy/engine/base.py", line 2094, in _run_visitor
    with self._optional_conn_ctx_manager(connection) as conn:
  File "/usr/local/lib/python3.6/contextlib.py", line 81, in __enter__
    return next(self.gen)
  File "/home/airflow/.local/lib/python3.6/site-packages/sqlalchemy/engine/base.py", line 2086, in _optional_conn_ctx_manager
    with self._contextual_connect() as conn:
  File "/home/airflow/.local/lib/python3.6/site-packages/sqlalchemy/engine/base.py", line 2302, in _contextual_connect
    self._wrap_pool_connect(self.pool.connect, None),
  File "/home/airflow/.local/lib/python3.6/site-packages/sqlalchemy/engine/base.py", line 2340, in _wrap_pool_connect
    e, dialect, self
  File "/home/airflow/.local/lib/python3.6/site-packages/sqlalchemy/engine/base.py", line 1584, in _handle_dbapi_exception_noconnection
    sqlalchemy_exception, with_traceback=exc_info[2], from_=e
  File "/home/airflow/.local/lib/python3.6/site-packages/sqlalchemy/util/compat.py", line 182, in raise_
    raise exception
  File "/home/airflow/.local/lib/python3.6/site-packages/sqlalchemy/engine/base.py", line 2336, in _wrap_pool_connect
    return fn()
  File "/home/airflow/.local/lib/python3.6/site-packages/sqlalchemy/pool/base.py", line 364, in connect
    return _ConnectionFairy._checkout(self)
  File "/home/airflow/.local/lib/python3.6/site-packages/sqlalchemy/pool/base.py", line 778, in _checkout
    fairy = _ConnectionRecord.checkout(pool)
  File "/home/airflow/.local/lib/python3.6/site-packages/sqlalchemy/pool/base.py", line 495, in checkout
    rec = pool._do_get()
  File "/home/airflow/.local/lib/python3.6/site-packages/sqlalchemy/pool/impl.py", line 140, in _do_get
    self._dec_overflow()
  File "/home/airflow/.local/lib/python3.6/site-packages/sqlalchemy/util/langhelpers.py", line 70, in __exit__
    with_traceback=exc_tb,
  File "/home/airflow/.local/lib/python3.6/site-packages/sqlalchemy/util/compat.py", line 182, in raise_
    raise exception
  File "/home/airflow/.local/lib/python3.6/site-packages/sqlalchemy/pool/impl.py", line 137, in _do_get
    return self._create_connection()
  File "/home/airflow/.local/lib/python3.6/site-packages/sqlalchemy/pool/base.py", line 309, in _create_connection
    return _ConnectionRecord(self)
  File "/home/airflow/.local/lib/python3.6/site-packages/sqlalchemy/pool/base.py", line 440, in __init__
    self.__connect(first_connect_check=True)
  File "/home/airflow/.local/lib/python3.6/site-packages/sqlalchemy/pool/base.py", line 661, in __connect
    pool.logger.debug("Error on connect(): %s", e)
  File "/home/airflow/.local/lib/python3.6/site-packages/sqlalchemy/util/langhelpers.py", line 70, in __exit__
    with_traceback=exc_tb,
  File "/home/airflow/.local/lib/python3.6/site-packages/sqlalchemy/util/compat.py", line 182, in raise_
    raise exception
  File "/home/airflow/.local/lib/python3.6/site-packages/sqlalchemy/pool/base.py", line 656, in __connect
    connection = pool._invoke_creator(self)
  File "/home/airflow/.local/lib/python3.6/site-packages/sqlalchemy/engine/strategies.py", line 114, in connect
    return dialect.connect(*cargs, **cparams)
  File "/home/airflow/.local/lib/python3.6/site-packages/sqlalchemy/engine/default.py", line 508, in connect
    return self.dbapi.connect(*cargs, **cparams)
  File "/home/airflow/.local/lib/python3.6/site-packages/psycopg2/__init__.py", line 127, in connect
    conn = _connect(dsn, connection_factory=connection_factory, **kwasync)
sqlalchemy.exc.OperationalError: (psycopg2.OperationalError) could not connect to server: Connection refused
	Is the server running on host "db" (172.28.0.7) and accepting
	TCP/IP connections on port 5431?

(Background on this error at: http://sqlalche.me/e/13/e3q8)
[2023-03-10 21:51:21,442] {scheduler_job.py:641} WARNING - No viable dags retrieved from /opt/airflow/dags/spent_by_user.py
[2023-03-10 21:51:21,519] {scheduler_job.py:190} INFO - Processing /opt/airflow/dags/spent_by_user.py took 0.216 seconds
[2023-03-10 21:51:52,660] {scheduler_job.py:182} INFO - Started process (PID=239) to work on /opt/airflow/dags/spent_by_user.py
[2023-03-10 21:51:52,665] {scheduler_job.py:629} INFO - Processing file /opt/airflow/dags/spent_by_user.py for tasks to queue
[2023-03-10 21:51:52,668] {logging_mixin.py:104} INFO - [2023-03-10 21:51:52,668] {dagbag.py:448} INFO - Filling up the DagBag from /opt/airflow/dags/spent_by_user.py
[2023-03-10 21:51:52,730] {logging_mixin.py:104} INFO - [2023-03-10 21:51:52,709] {dagbag.py:305} ERROR - Failed to import: /opt/airflow/dags/spent_by_user.py
Traceback (most recent call last):
  File "/home/airflow/.local/lib/python3.6/site-packages/sqlalchemy/engine/base.py", line 2336, in _wrap_pool_connect
    return fn()
  File "/home/airflow/.local/lib/python3.6/site-packages/sqlalchemy/pool/base.py", line 364, in connect
    return _ConnectionFairy._checkout(self)
  File "/home/airflow/.local/lib/python3.6/site-packages/sqlalchemy/pool/base.py", line 778, in _checkout
    fairy = _ConnectionRecord.checkout(pool)
  File "/home/airflow/.local/lib/python3.6/site-packages/sqlalchemy/pool/base.py", line 495, in checkout
    rec = pool._do_get()
  File "/home/airflow/.local/lib/python3.6/site-packages/sqlalchemy/pool/impl.py", line 140, in _do_get
    self._dec_overflow()
  File "/home/airflow/.local/lib/python3.6/site-packages/sqlalchemy/util/langhelpers.py", line 70, in __exit__
    with_traceback=exc_tb,
  File "/home/airflow/.local/lib/python3.6/site-packages/sqlalchemy/util/compat.py", line 182, in raise_
    raise exception
  File "/home/airflow/.local/lib/python3.6/site-packages/sqlalchemy/pool/impl.py", line 137, in _do_get
    return self._create_connection()
  File "/home/airflow/.local/lib/python3.6/site-packages/sqlalchemy/pool/base.py", line 309, in _create_connection
    return _ConnectionRecord(self)
  File "/home/airflow/.local/lib/python3.6/site-packages/sqlalchemy/pool/base.py", line 440, in __init__
    self.__connect(first_connect_check=True)
  File "/home/airflow/.local/lib/python3.6/site-packages/sqlalchemy/pool/base.py", line 661, in __connect
    pool.logger.debug("Error on connect(): %s", e)
  File "/home/airflow/.local/lib/python3.6/site-packages/sqlalchemy/util/langhelpers.py", line 70, in __exit__
    with_traceback=exc_tb,
  File "/home/airflow/.local/lib/python3.6/site-packages/sqlalchemy/util/compat.py", line 182, in raise_
    raise exception
  File "/home/airflow/.local/lib/python3.6/site-packages/sqlalchemy/pool/base.py", line 656, in __connect
    connection = pool._invoke_creator(self)
  File "/home/airflow/.local/lib/python3.6/site-packages/sqlalchemy/engine/strategies.py", line 114, in connect
    return dialect.connect(*cargs, **cparams)
  File "/home/airflow/.local/lib/python3.6/site-packages/sqlalchemy/engine/default.py", line 508, in connect
    return self.dbapi.connect(*cargs, **cparams)
  File "/home/airflow/.local/lib/python3.6/site-packages/psycopg2/__init__.py", line 127, in connect
    conn = _connect(dsn, connection_factory=connection_factory, **kwasync)
psycopg2.OperationalError: could not connect to server: Connection refused
	Is the server running on host "db" (172.28.0.7) and accepting
	TCP/IP connections on port 5431?


The above exception was the direct cause of the following exception:

Traceback (most recent call last):
  File "/home/airflow/.local/lib/python3.6/site-packages/airflow/models/dagbag.py", line 302, in _load_modules_from_file
    loader.exec_module(new_module)
  File "<frozen importlib._bootstrap_external>", line 678, in exec_module
  File "<frozen importlib._bootstrap>", line 219, in _call_with_frames_removed
  File "/opt/airflow/dags/spent_by_user.py", line 20, in <module>
    Base.metadata.create_all(bind=engine, tables=[UserTotalSpent.__table__])
  File "/home/airflow/.local/lib/python3.6/site-packages/sqlalchemy/sql/schema.py", line 4664, in create_all
    ddl.SchemaGenerator, self, checkfirst=checkfirst, tables=tables
  File "/home/airflow/.local/lib/python3.6/site-packages/sqlalchemy/engine/base.py", line 2094, in _run_visitor
    with self._optional_conn_ctx_manager(connection) as conn:
  File "/usr/local/lib/python3.6/contextlib.py", line 81, in __enter__
    return next(self.gen)
  File "/home/airflow/.local/lib/python3.6/site-packages/sqlalchemy/engine/base.py", line 2086, in _optional_conn_ctx_manager
    with self._contextual_connect() as conn:
  File "/home/airflow/.local/lib/python3.6/site-packages/sqlalchemy/engine/base.py", line 2302, in _contextual_connect
    self._wrap_pool_connect(self.pool.connect, None),
  File "/home/airflow/.local/lib/python3.6/site-packages/sqlalchemy/engine/base.py", line 2340, in _wrap_pool_connect
    e, dialect, self
  File "/home/airflow/.local/lib/python3.6/site-packages/sqlalchemy/engine/base.py", line 1584, in _handle_dbapi_exception_noconnection
    sqlalchemy_exception, with_traceback=exc_info[2], from_=e
  File "/home/airflow/.local/lib/python3.6/site-packages/sqlalchemy/util/compat.py", line 182, in raise_
    raise exception
  File "/home/airflow/.local/lib/python3.6/site-packages/sqlalchemy/engine/base.py", line 2336, in _wrap_pool_connect
    return fn()
  File "/home/airflow/.local/lib/python3.6/site-packages/sqlalchemy/pool/base.py", line 364, in connect
    return _ConnectionFairy._checkout(self)
  File "/home/airflow/.local/lib/python3.6/site-packages/sqlalchemy/pool/base.py", line 778, in _checkout
    fairy = _ConnectionRecord.checkout(pool)
  File "/home/airflow/.local/lib/python3.6/site-packages/sqlalchemy/pool/base.py", line 495, in checkout
    rec = pool._do_get()
  File "/home/airflow/.local/lib/python3.6/site-packages/sqlalchemy/pool/impl.py", line 140, in _do_get
    self._dec_overflow()
  File "/home/airflow/.local/lib/python3.6/site-packages/sqlalchemy/util/langhelpers.py", line 70, in __exit__
    with_traceback=exc_tb,
  File "/home/airflow/.local/lib/python3.6/site-packages/sqlalchemy/util/compat.py", line 182, in raise_
    raise exception
  File "/home/airflow/.local/lib/python3.6/site-packages/sqlalchemy/pool/impl.py", line 137, in _do_get
    return self._create_connection()
  File "/home/airflow/.local/lib/python3.6/site-packages/sqlalchemy/pool/base.py", line 309, in _create_connection
    return _ConnectionRecord(self)
  File "/home/airflow/.local/lib/python3.6/site-packages/sqlalchemy/pool/base.py", line 440, in __init__
    self.__connect(first_connect_check=True)
  File "/home/airflow/.local/lib/python3.6/site-packages/sqlalchemy/pool/base.py", line 661, in __connect
    pool.logger.debug("Error on connect(): %s", e)
  File "/home/airflow/.local/lib/python3.6/site-packages/sqlalchemy/util/langhelpers.py", line 70, in __exit__
    with_traceback=exc_tb,
  File "/home/airflow/.local/lib/python3.6/site-packages/sqlalchemy/util/compat.py", line 182, in raise_
    raise exception
  File "/home/airflow/.local/lib/python3.6/site-packages/sqlalchemy/pool/base.py", line 656, in __connect
    connection = pool._invoke_creator(self)
  File "/home/airflow/.local/lib/python3.6/site-packages/sqlalchemy/engine/strategies.py", line 114, in connect
    return dialect.connect(*cargs, **cparams)
  File "/home/airflow/.local/lib/python3.6/site-packages/sqlalchemy/engine/default.py", line 508, in connect
    return self.dbapi.connect(*cargs, **cparams)
  File "/home/airflow/.local/lib/python3.6/site-packages/psycopg2/__init__.py", line 127, in connect
    conn = _connect(dsn, connection_factory=connection_factory, **kwasync)
sqlalchemy.exc.OperationalError: (psycopg2.OperationalError) could not connect to server: Connection refused
	Is the server running on host "db" (172.28.0.7) and accepting
	TCP/IP connections on port 5431?

(Background on this error at: http://sqlalche.me/e/13/e3q8)
[2023-03-10 21:51:52,737] {scheduler_job.py:641} WARNING - No viable dags retrieved from /opt/airflow/dags/spent_by_user.py
[2023-03-10 21:51:52,771] {scheduler_job.py:190} INFO - Processing /opt/airflow/dags/spent_by_user.py took 0.119 seconds
[2023-03-10 21:52:23,057] {scheduler_job.py:182} INFO - Started process (PID=293) to work on /opt/airflow/dags/spent_by_user.py
[2023-03-10 21:52:23,062] {scheduler_job.py:629} INFO - Processing file /opt/airflow/dags/spent_by_user.py for tasks to queue
[2023-03-10 21:52:23,065] {logging_mixin.py:104} INFO - [2023-03-10 21:52:23,064] {dagbag.py:448} INFO - Filling up the DagBag from /opt/airflow/dags/spent_by_user.py
[2023-03-10 21:52:23,125] {logging_mixin.py:104} INFO - [2023-03-10 21:52:23,104] {dagbag.py:305} ERROR - Failed to import: /opt/airflow/dags/spent_by_user.py
Traceback (most recent call last):
  File "/home/airflow/.local/lib/python3.6/site-packages/sqlalchemy/engine/base.py", line 2336, in _wrap_pool_connect
    return fn()
  File "/home/airflow/.local/lib/python3.6/site-packages/sqlalchemy/pool/base.py", line 364, in connect
    return _ConnectionFairy._checkout(self)
  File "/home/airflow/.local/lib/python3.6/site-packages/sqlalchemy/pool/base.py", line 778, in _checkout
    fairy = _ConnectionRecord.checkout(pool)
  File "/home/airflow/.local/lib/python3.6/site-packages/sqlalchemy/pool/base.py", line 495, in checkout
    rec = pool._do_get()
  File "/home/airflow/.local/lib/python3.6/site-packages/sqlalchemy/pool/impl.py", line 140, in _do_get
    self._dec_overflow()
  File "/home/airflow/.local/lib/python3.6/site-packages/sqlalchemy/util/langhelpers.py", line 70, in __exit__
    with_traceback=exc_tb,
  File "/home/airflow/.local/lib/python3.6/site-packages/sqlalchemy/util/compat.py", line 182, in raise_
    raise exception
  File "/home/airflow/.local/lib/python3.6/site-packages/sqlalchemy/pool/impl.py", line 137, in _do_get
    return self._create_connection()
  File "/home/airflow/.local/lib/python3.6/site-packages/sqlalchemy/pool/base.py", line 309, in _create_connection
    return _ConnectionRecord(self)
  File "/home/airflow/.local/lib/python3.6/site-packages/sqlalchemy/pool/base.py", line 440, in __init__
    self.__connect(first_connect_check=True)
  File "/home/airflow/.local/lib/python3.6/site-packages/sqlalchemy/pool/base.py", line 661, in __connect
    pool.logger.debug("Error on connect(): %s", e)
  File "/home/airflow/.local/lib/python3.6/site-packages/sqlalchemy/util/langhelpers.py", line 70, in __exit__
    with_traceback=exc_tb,
  File "/home/airflow/.local/lib/python3.6/site-packages/sqlalchemy/util/compat.py", line 182, in raise_
    raise exception
  File "/home/airflow/.local/lib/python3.6/site-packages/sqlalchemy/pool/base.py", line 656, in __connect
    connection = pool._invoke_creator(self)
  File "/home/airflow/.local/lib/python3.6/site-packages/sqlalchemy/engine/strategies.py", line 114, in connect
    return dialect.connect(*cargs, **cparams)
  File "/home/airflow/.local/lib/python3.6/site-packages/sqlalchemy/engine/default.py", line 508, in connect
    return self.dbapi.connect(*cargs, **cparams)
  File "/home/airflow/.local/lib/python3.6/site-packages/psycopg2/__init__.py", line 127, in connect
    conn = _connect(dsn, connection_factory=connection_factory, **kwasync)
psycopg2.OperationalError: could not connect to server: Connection refused
	Is the server running on host "db" (172.28.0.7) and accepting
	TCP/IP connections on port 5431?


The above exception was the direct cause of the following exception:

Traceback (most recent call last):
  File "/home/airflow/.local/lib/python3.6/site-packages/airflow/models/dagbag.py", line 302, in _load_modules_from_file
    loader.exec_module(new_module)
  File "<frozen importlib._bootstrap_external>", line 678, in exec_module
  File "<frozen importlib._bootstrap>", line 219, in _call_with_frames_removed
  File "/opt/airflow/dags/spent_by_user.py", line 20, in <module>
    Base.metadata.create_all(bind=engine, tables=[UserTotalSpent.__table__])
  File "/home/airflow/.local/lib/python3.6/site-packages/sqlalchemy/sql/schema.py", line 4664, in create_all
    ddl.SchemaGenerator, self, checkfirst=checkfirst, tables=tables
  File "/home/airflow/.local/lib/python3.6/site-packages/sqlalchemy/engine/base.py", line 2094, in _run_visitor
    with self._optional_conn_ctx_manager(connection) as conn:
  File "/usr/local/lib/python3.6/contextlib.py", line 81, in __enter__
    return next(self.gen)
  File "/home/airflow/.local/lib/python3.6/site-packages/sqlalchemy/engine/base.py", line 2086, in _optional_conn_ctx_manager
    with self._contextual_connect() as conn:
  File "/home/airflow/.local/lib/python3.6/site-packages/sqlalchemy/engine/base.py", line 2302, in _contextual_connect
    self._wrap_pool_connect(self.pool.connect, None),
  File "/home/airflow/.local/lib/python3.6/site-packages/sqlalchemy/engine/base.py", line 2340, in _wrap_pool_connect
    e, dialect, self
  File "/home/airflow/.local/lib/python3.6/site-packages/sqlalchemy/engine/base.py", line 1584, in _handle_dbapi_exception_noconnection
    sqlalchemy_exception, with_traceback=exc_info[2], from_=e
  File "/home/airflow/.local/lib/python3.6/site-packages/sqlalchemy/util/compat.py", line 182, in raise_
    raise exception
  File "/home/airflow/.local/lib/python3.6/site-packages/sqlalchemy/engine/base.py", line 2336, in _wrap_pool_connect
    return fn()
  File "/home/airflow/.local/lib/python3.6/site-packages/sqlalchemy/pool/base.py", line 364, in connect
    return _ConnectionFairy._checkout(self)
  File "/home/airflow/.local/lib/python3.6/site-packages/sqlalchemy/pool/base.py", line 778, in _checkout
    fairy = _ConnectionRecord.checkout(pool)
  File "/home/airflow/.local/lib/python3.6/site-packages/sqlalchemy/pool/base.py", line 495, in checkout
    rec = pool._do_get()
  File "/home/airflow/.local/lib/python3.6/site-packages/sqlalchemy/pool/impl.py", line 140, in _do_get
    self._dec_overflow()
  File "/home/airflow/.local/lib/python3.6/site-packages/sqlalchemy/util/langhelpers.py", line 70, in __exit__
    with_traceback=exc_tb,
  File "/home/airflow/.local/lib/python3.6/site-packages/sqlalchemy/util/compat.py", line 182, in raise_
    raise exception
  File "/home/airflow/.local/lib/python3.6/site-packages/sqlalchemy/pool/impl.py", line 137, in _do_get
    return self._create_connection()
  File "/home/airflow/.local/lib/python3.6/site-packages/sqlalchemy/pool/base.py", line 309, in _create_connection
    return _ConnectionRecord(self)
  File "/home/airflow/.local/lib/python3.6/site-packages/sqlalchemy/pool/base.py", line 440, in __init__
    self.__connect(first_connect_check=True)
  File "/home/airflow/.local/lib/python3.6/site-packages/sqlalchemy/pool/base.py", line 661, in __connect
    pool.logger.debug("Error on connect(): %s", e)
  File "/home/airflow/.local/lib/python3.6/site-packages/sqlalchemy/util/langhelpers.py", line 70, in __exit__
    with_traceback=exc_tb,
  File "/home/airflow/.local/lib/python3.6/site-packages/sqlalchemy/util/compat.py", line 182, in raise_
    raise exception
  File "/home/airflow/.local/lib/python3.6/site-packages/sqlalchemy/pool/base.py", line 656, in __connect
    connection = pool._invoke_creator(self)
  File "/home/airflow/.local/lib/python3.6/site-packages/sqlalchemy/engine/strategies.py", line 114, in connect
    return dialect.connect(*cargs, **cparams)
  File "/home/airflow/.local/lib/python3.6/site-packages/sqlalchemy/engine/default.py", line 508, in connect
    return self.dbapi.connect(*cargs, **cparams)
  File "/home/airflow/.local/lib/python3.6/site-packages/psycopg2/__init__.py", line 127, in connect
    conn = _connect(dsn, connection_factory=connection_factory, **kwasync)
sqlalchemy.exc.OperationalError: (psycopg2.OperationalError) could not connect to server: Connection refused
	Is the server running on host "db" (172.28.0.7) and accepting
	TCP/IP connections on port 5431?

(Background on this error at: http://sqlalche.me/e/13/e3q8)
[2023-03-10 21:52:23,132] {scheduler_job.py:641} WARNING - No viable dags retrieved from /opt/airflow/dags/spent_by_user.py
[2023-03-10 21:52:23,164] {scheduler_job.py:190} INFO - Processing /opt/airflow/dags/spent_by_user.py took 0.114 seconds
[2023-03-10 21:52:53,656] {scheduler_job.py:182} INFO - Started process (PID=347) to work on /opt/airflow/dags/spent_by_user.py
[2023-03-10 21:52:53,662] {scheduler_job.py:629} INFO - Processing file /opt/airflow/dags/spent_by_user.py for tasks to queue
[2023-03-10 21:52:53,666] {logging_mixin.py:104} INFO - [2023-03-10 21:52:53,665] {dagbag.py:448} INFO - Filling up the DagBag from /opt/airflow/dags/spent_by_user.py
[2023-03-10 21:52:53,733] {logging_mixin.py:104} INFO - [2023-03-10 21:52:53,708] {dagbag.py:305} ERROR - Failed to import: /opt/airflow/dags/spent_by_user.py
Traceback (most recent call last):
  File "/home/airflow/.local/lib/python3.6/site-packages/sqlalchemy/engine/base.py", line 2336, in _wrap_pool_connect
    return fn()
  File "/home/airflow/.local/lib/python3.6/site-packages/sqlalchemy/pool/base.py", line 364, in connect
    return _ConnectionFairy._checkout(self)
  File "/home/airflow/.local/lib/python3.6/site-packages/sqlalchemy/pool/base.py", line 778, in _checkout
    fairy = _ConnectionRecord.checkout(pool)
  File "/home/airflow/.local/lib/python3.6/site-packages/sqlalchemy/pool/base.py", line 495, in checkout
    rec = pool._do_get()
  File "/home/airflow/.local/lib/python3.6/site-packages/sqlalchemy/pool/impl.py", line 140, in _do_get
    self._dec_overflow()
  File "/home/airflow/.local/lib/python3.6/site-packages/sqlalchemy/util/langhelpers.py", line 70, in __exit__
    with_traceback=exc_tb,
  File "/home/airflow/.local/lib/python3.6/site-packages/sqlalchemy/util/compat.py", line 182, in raise_
    raise exception
  File "/home/airflow/.local/lib/python3.6/site-packages/sqlalchemy/pool/impl.py", line 137, in _do_get
    return self._create_connection()
  File "/home/airflow/.local/lib/python3.6/site-packages/sqlalchemy/pool/base.py", line 309, in _create_connection
    return _ConnectionRecord(self)
  File "/home/airflow/.local/lib/python3.6/site-packages/sqlalchemy/pool/base.py", line 440, in __init__
    self.__connect(first_connect_check=True)
  File "/home/airflow/.local/lib/python3.6/site-packages/sqlalchemy/pool/base.py", line 661, in __connect
    pool.logger.debug("Error on connect(): %s", e)
  File "/home/airflow/.local/lib/python3.6/site-packages/sqlalchemy/util/langhelpers.py", line 70, in __exit__
    with_traceback=exc_tb,
  File "/home/airflow/.local/lib/python3.6/site-packages/sqlalchemy/util/compat.py", line 182, in raise_
    raise exception
  File "/home/airflow/.local/lib/python3.6/site-packages/sqlalchemy/pool/base.py", line 656, in __connect
    connection = pool._invoke_creator(self)
  File "/home/airflow/.local/lib/python3.6/site-packages/sqlalchemy/engine/strategies.py", line 114, in connect
    return dialect.connect(*cargs, **cparams)
  File "/home/airflow/.local/lib/python3.6/site-packages/sqlalchemy/engine/default.py", line 508, in connect
    return self.dbapi.connect(*cargs, **cparams)
  File "/home/airflow/.local/lib/python3.6/site-packages/psycopg2/__init__.py", line 127, in connect
    conn = _connect(dsn, connection_factory=connection_factory, **kwasync)
psycopg2.OperationalError: could not connect to server: Connection refused
	Is the server running on host "db" (172.28.0.7) and accepting
	TCP/IP connections on port 5431?


The above exception was the direct cause of the following exception:

Traceback (most recent call last):
  File "/home/airflow/.local/lib/python3.6/site-packages/airflow/models/dagbag.py", line 302, in _load_modules_from_file
    loader.exec_module(new_module)
  File "<frozen importlib._bootstrap_external>", line 678, in exec_module
  File "<frozen importlib._bootstrap>", line 219, in _call_with_frames_removed
  File "/opt/airflow/dags/spent_by_user.py", line 20, in <module>
    Base.metadata.create_all(bind=engine, tables=[UserTotalSpent.__table__])
  File "/home/airflow/.local/lib/python3.6/site-packages/sqlalchemy/sql/schema.py", line 4664, in create_all
    ddl.SchemaGenerator, self, checkfirst=checkfirst, tables=tables
  File "/home/airflow/.local/lib/python3.6/site-packages/sqlalchemy/engine/base.py", line 2094, in _run_visitor
    with self._optional_conn_ctx_manager(connection) as conn:
  File "/usr/local/lib/python3.6/contextlib.py", line 81, in __enter__
    return next(self.gen)
  File "/home/airflow/.local/lib/python3.6/site-packages/sqlalchemy/engine/base.py", line 2086, in _optional_conn_ctx_manager
    with self._contextual_connect() as conn:
  File "/home/airflow/.local/lib/python3.6/site-packages/sqlalchemy/engine/base.py", line 2302, in _contextual_connect
    self._wrap_pool_connect(self.pool.connect, None),
  File "/home/airflow/.local/lib/python3.6/site-packages/sqlalchemy/engine/base.py", line 2340, in _wrap_pool_connect
    e, dialect, self
  File "/home/airflow/.local/lib/python3.6/site-packages/sqlalchemy/engine/base.py", line 1584, in _handle_dbapi_exception_noconnection
    sqlalchemy_exception, with_traceback=exc_info[2], from_=e
  File "/home/airflow/.local/lib/python3.6/site-packages/sqlalchemy/util/compat.py", line 182, in raise_
    raise exception
  File "/home/airflow/.local/lib/python3.6/site-packages/sqlalchemy/engine/base.py", line 2336, in _wrap_pool_connect
    return fn()
  File "/home/airflow/.local/lib/python3.6/site-packages/sqlalchemy/pool/base.py", line 364, in connect
    return _ConnectionFairy._checkout(self)
  File "/home/airflow/.local/lib/python3.6/site-packages/sqlalchemy/pool/base.py", line 778, in _checkout
    fairy = _ConnectionRecord.checkout(pool)
  File "/home/airflow/.local/lib/python3.6/site-packages/sqlalchemy/pool/base.py", line 495, in checkout
    rec = pool._do_get()
  File "/home/airflow/.local/lib/python3.6/site-packages/sqlalchemy/pool/impl.py", line 140, in _do_get
    self._dec_overflow()
  File "/home/airflow/.local/lib/python3.6/site-packages/sqlalchemy/util/langhelpers.py", line 70, in __exit__
    with_traceback=exc_tb,
  File "/home/airflow/.local/lib/python3.6/site-packages/sqlalchemy/util/compat.py", line 182, in raise_
    raise exception
  File "/home/airflow/.local/lib/python3.6/site-packages/sqlalchemy/pool/impl.py", line 137, in _do_get
    return self._create_connection()
  File "/home/airflow/.local/lib/python3.6/site-packages/sqlalchemy/pool/base.py", line 309, in _create_connection
    return _ConnectionRecord(self)
  File "/home/airflow/.local/lib/python3.6/site-packages/sqlalchemy/pool/base.py", line 440, in __init__
    self.__connect(first_connect_check=True)
  File "/home/airflow/.local/lib/python3.6/site-packages/sqlalchemy/pool/base.py", line 661, in __connect
    pool.logger.debug("Error on connect(): %s", e)
  File "/home/airflow/.local/lib/python3.6/site-packages/sqlalchemy/util/langhelpers.py", line 70, in __exit__
    with_traceback=exc_tb,
  File "/home/airflow/.local/lib/python3.6/site-packages/sqlalchemy/util/compat.py", line 182, in raise_
    raise exception
  File "/home/airflow/.local/lib/python3.6/site-packages/sqlalchemy/pool/base.py", line 656, in __connect
    connection = pool._invoke_creator(self)
  File "/home/airflow/.local/lib/python3.6/site-packages/sqlalchemy/engine/strategies.py", line 114, in connect
    return dialect.connect(*cargs, **cparams)
  File "/home/airflow/.local/lib/python3.6/site-packages/sqlalchemy/engine/default.py", line 508, in connect
    return self.dbapi.connect(*cargs, **cparams)
  File "/home/airflow/.local/lib/python3.6/site-packages/psycopg2/__init__.py", line 127, in connect
    conn = _connect(dsn, connection_factory=connection_factory, **kwasync)
sqlalchemy.exc.OperationalError: (psycopg2.OperationalError) could not connect to server: Connection refused
	Is the server running on host "db" (172.28.0.7) and accepting
	TCP/IP connections on port 5431?

(Background on this error at: http://sqlalche.me/e/13/e3q8)
[2023-03-10 21:52:53,740] {scheduler_job.py:641} WARNING - No viable dags retrieved from /opt/airflow/dags/spent_by_user.py
[2023-03-10 21:52:53,777] {scheduler_job.py:190} INFO - Processing /opt/airflow/dags/spent_by_user.py took 0.128 seconds
[2023-03-10 21:53:24,075] {scheduler_job.py:182} INFO - Started process (PID=401) to work on /opt/airflow/dags/spent_by_user.py
[2023-03-10 21:53:24,080] {scheduler_job.py:629} INFO - Processing file /opt/airflow/dags/spent_by_user.py for tasks to queue
[2023-03-10 21:53:24,083] {logging_mixin.py:104} INFO - [2023-03-10 21:53:24,083] {dagbag.py:448} INFO - Filling up the DagBag from /opt/airflow/dags/spent_by_user.py
[2023-03-10 21:53:24,146] {logging_mixin.py:104} INFO - [2023-03-10 21:53:24,126] {dagbag.py:305} ERROR - Failed to import: /opt/airflow/dags/spent_by_user.py
Traceback (most recent call last):
  File "/home/airflow/.local/lib/python3.6/site-packages/sqlalchemy/engine/base.py", line 2336, in _wrap_pool_connect
    return fn()
  File "/home/airflow/.local/lib/python3.6/site-packages/sqlalchemy/pool/base.py", line 364, in connect
    return _ConnectionFairy._checkout(self)
  File "/home/airflow/.local/lib/python3.6/site-packages/sqlalchemy/pool/base.py", line 778, in _checkout
    fairy = _ConnectionRecord.checkout(pool)
  File "/home/airflow/.local/lib/python3.6/site-packages/sqlalchemy/pool/base.py", line 495, in checkout
    rec = pool._do_get()
  File "/home/airflow/.local/lib/python3.6/site-packages/sqlalchemy/pool/impl.py", line 140, in _do_get
    self._dec_overflow()
  File "/home/airflow/.local/lib/python3.6/site-packages/sqlalchemy/util/langhelpers.py", line 70, in __exit__
    with_traceback=exc_tb,
  File "/home/airflow/.local/lib/python3.6/site-packages/sqlalchemy/util/compat.py", line 182, in raise_
    raise exception
  File "/home/airflow/.local/lib/python3.6/site-packages/sqlalchemy/pool/impl.py", line 137, in _do_get
    return self._create_connection()
  File "/home/airflow/.local/lib/python3.6/site-packages/sqlalchemy/pool/base.py", line 309, in _create_connection
    return _ConnectionRecord(self)
  File "/home/airflow/.local/lib/python3.6/site-packages/sqlalchemy/pool/base.py", line 440, in __init__
    self.__connect(first_connect_check=True)
  File "/home/airflow/.local/lib/python3.6/site-packages/sqlalchemy/pool/base.py", line 661, in __connect
    pool.logger.debug("Error on connect(): %s", e)
  File "/home/airflow/.local/lib/python3.6/site-packages/sqlalchemy/util/langhelpers.py", line 70, in __exit__
    with_traceback=exc_tb,
  File "/home/airflow/.local/lib/python3.6/site-packages/sqlalchemy/util/compat.py", line 182, in raise_
    raise exception
  File "/home/airflow/.local/lib/python3.6/site-packages/sqlalchemy/pool/base.py", line 656, in __connect
    connection = pool._invoke_creator(self)
  File "/home/airflow/.local/lib/python3.6/site-packages/sqlalchemy/engine/strategies.py", line 114, in connect
    return dialect.connect(*cargs, **cparams)
  File "/home/airflow/.local/lib/python3.6/site-packages/sqlalchemy/engine/default.py", line 508, in connect
    return self.dbapi.connect(*cargs, **cparams)
  File "/home/airflow/.local/lib/python3.6/site-packages/psycopg2/__init__.py", line 127, in connect
    conn = _connect(dsn, connection_factory=connection_factory, **kwasync)
psycopg2.OperationalError: could not connect to server: Connection refused
	Is the server running on host "db" (172.28.0.7) and accepting
	TCP/IP connections on port 5431?


The above exception was the direct cause of the following exception:

Traceback (most recent call last):
  File "/home/airflow/.local/lib/python3.6/site-packages/airflow/models/dagbag.py", line 302, in _load_modules_from_file
    loader.exec_module(new_module)
  File "<frozen importlib._bootstrap_external>", line 678, in exec_module
  File "<frozen importlib._bootstrap>", line 219, in _call_with_frames_removed
  File "/opt/airflow/dags/spent_by_user.py", line 20, in <module>
    Base.metadata.create_all(bind=engine, tables=[UserTotalSpent.__table__])
  File "/home/airflow/.local/lib/python3.6/site-packages/sqlalchemy/sql/schema.py", line 4664, in create_all
    ddl.SchemaGenerator, self, checkfirst=checkfirst, tables=tables
  File "/home/airflow/.local/lib/python3.6/site-packages/sqlalchemy/engine/base.py", line 2094, in _run_visitor
    with self._optional_conn_ctx_manager(connection) as conn:
  File "/usr/local/lib/python3.6/contextlib.py", line 81, in __enter__
    return next(self.gen)
  File "/home/airflow/.local/lib/python3.6/site-packages/sqlalchemy/engine/base.py", line 2086, in _optional_conn_ctx_manager
    with self._contextual_connect() as conn:
  File "/home/airflow/.local/lib/python3.6/site-packages/sqlalchemy/engine/base.py", line 2302, in _contextual_connect
    self._wrap_pool_connect(self.pool.connect, None),
  File "/home/airflow/.local/lib/python3.6/site-packages/sqlalchemy/engine/base.py", line 2340, in _wrap_pool_connect
    e, dialect, self
  File "/home/airflow/.local/lib/python3.6/site-packages/sqlalchemy/engine/base.py", line 1584, in _handle_dbapi_exception_noconnection
    sqlalchemy_exception, with_traceback=exc_info[2], from_=e
  File "/home/airflow/.local/lib/python3.6/site-packages/sqlalchemy/util/compat.py", line 182, in raise_
    raise exception
  File "/home/airflow/.local/lib/python3.6/site-packages/sqlalchemy/engine/base.py", line 2336, in _wrap_pool_connect
    return fn()
  File "/home/airflow/.local/lib/python3.6/site-packages/sqlalchemy/pool/base.py", line 364, in connect
    return _ConnectionFairy._checkout(self)
  File "/home/airflow/.local/lib/python3.6/site-packages/sqlalchemy/pool/base.py", line 778, in _checkout
    fairy = _ConnectionRecord.checkout(pool)
  File "/home/airflow/.local/lib/python3.6/site-packages/sqlalchemy/pool/base.py", line 495, in checkout
    rec = pool._do_get()
  File "/home/airflow/.local/lib/python3.6/site-packages/sqlalchemy/pool/impl.py", line 140, in _do_get
    self._dec_overflow()
  File "/home/airflow/.local/lib/python3.6/site-packages/sqlalchemy/util/langhelpers.py", line 70, in __exit__
    with_traceback=exc_tb,
  File "/home/airflow/.local/lib/python3.6/site-packages/sqlalchemy/util/compat.py", line 182, in raise_
    raise exception
  File "/home/airflow/.local/lib/python3.6/site-packages/sqlalchemy/pool/impl.py", line 137, in _do_get
    return self._create_connection()
  File "/home/airflow/.local/lib/python3.6/site-packages/sqlalchemy/pool/base.py", line 309, in _create_connection
    return _ConnectionRecord(self)
  File "/home/airflow/.local/lib/python3.6/site-packages/sqlalchemy/pool/base.py", line 440, in __init__
    self.__connect(first_connect_check=True)
  File "/home/airflow/.local/lib/python3.6/site-packages/sqlalchemy/pool/base.py", line 661, in __connect
    pool.logger.debug("Error on connect(): %s", e)
  File "/home/airflow/.local/lib/python3.6/site-packages/sqlalchemy/util/langhelpers.py", line 70, in __exit__
    with_traceback=exc_tb,
  File "/home/airflow/.local/lib/python3.6/site-packages/sqlalchemy/util/compat.py", line 182, in raise_
    raise exception
  File "/home/airflow/.local/lib/python3.6/site-packages/sqlalchemy/pool/base.py", line 656, in __connect
    connection = pool._invoke_creator(self)
  File "/home/airflow/.local/lib/python3.6/site-packages/sqlalchemy/engine/strategies.py", line 114, in connect
    return dialect.connect(*cargs, **cparams)
  File "/home/airflow/.local/lib/python3.6/site-packages/sqlalchemy/engine/default.py", line 508, in connect
    return self.dbapi.connect(*cargs, **cparams)
  File "/home/airflow/.local/lib/python3.6/site-packages/psycopg2/__init__.py", line 127, in connect
    conn = _connect(dsn, connection_factory=connection_factory, **kwasync)
sqlalchemy.exc.OperationalError: (psycopg2.OperationalError) could not connect to server: Connection refused
	Is the server running on host "db" (172.28.0.7) and accepting
	TCP/IP connections on port 5431?

(Background on this error at: http://sqlalche.me/e/13/e3q8)
[2023-03-10 21:53:24,154] {scheduler_job.py:641} WARNING - No viable dags retrieved from /opt/airflow/dags/spent_by_user.py
[2023-03-10 21:53:24,187] {scheduler_job.py:190} INFO - Processing /opt/airflow/dags/spent_by_user.py took 0.119 seconds
[2023-03-10 21:53:54,653] {scheduler_job.py:182} INFO - Started process (PID=455) to work on /opt/airflow/dags/spent_by_user.py
[2023-03-10 21:53:54,659] {scheduler_job.py:629} INFO - Processing file /opt/airflow/dags/spent_by_user.py for tasks to queue
[2023-03-10 21:53:54,664] {logging_mixin.py:104} INFO - [2023-03-10 21:53:54,663] {dagbag.py:448} INFO - Filling up the DagBag from /opt/airflow/dags/spent_by_user.py
[2023-03-10 21:53:54,750] {logging_mixin.py:104} INFO - [2023-03-10 21:53:54,725] {dagbag.py:305} ERROR - Failed to import: /opt/airflow/dags/spent_by_user.py
Traceback (most recent call last):
  File "/home/airflow/.local/lib/python3.6/site-packages/sqlalchemy/engine/base.py", line 2336, in _wrap_pool_connect
    return fn()
  File "/home/airflow/.local/lib/python3.6/site-packages/sqlalchemy/pool/base.py", line 364, in connect
    return _ConnectionFairy._checkout(self)
  File "/home/airflow/.local/lib/python3.6/site-packages/sqlalchemy/pool/base.py", line 778, in _checkout
    fairy = _ConnectionRecord.checkout(pool)
  File "/home/airflow/.local/lib/python3.6/site-packages/sqlalchemy/pool/base.py", line 495, in checkout
    rec = pool._do_get()
  File "/home/airflow/.local/lib/python3.6/site-packages/sqlalchemy/pool/impl.py", line 140, in _do_get
    self._dec_overflow()
  File "/home/airflow/.local/lib/python3.6/site-packages/sqlalchemy/util/langhelpers.py", line 70, in __exit__
    with_traceback=exc_tb,
  File "/home/airflow/.local/lib/python3.6/site-packages/sqlalchemy/util/compat.py", line 182, in raise_
    raise exception
  File "/home/airflow/.local/lib/python3.6/site-packages/sqlalchemy/pool/impl.py", line 137, in _do_get
    return self._create_connection()
  File "/home/airflow/.local/lib/python3.6/site-packages/sqlalchemy/pool/base.py", line 309, in _create_connection
    return _ConnectionRecord(self)
  File "/home/airflow/.local/lib/python3.6/site-packages/sqlalchemy/pool/base.py", line 440, in __init__
    self.__connect(first_connect_check=True)
  File "/home/airflow/.local/lib/python3.6/site-packages/sqlalchemy/pool/base.py", line 661, in __connect
    pool.logger.debug("Error on connect(): %s", e)
  File "/home/airflow/.local/lib/python3.6/site-packages/sqlalchemy/util/langhelpers.py", line 70, in __exit__
    with_traceback=exc_tb,
  File "/home/airflow/.local/lib/python3.6/site-packages/sqlalchemy/util/compat.py", line 182, in raise_
    raise exception
  File "/home/airflow/.local/lib/python3.6/site-packages/sqlalchemy/pool/base.py", line 656, in __connect
    connection = pool._invoke_creator(self)
  File "/home/airflow/.local/lib/python3.6/site-packages/sqlalchemy/engine/strategies.py", line 114, in connect
    return dialect.connect(*cargs, **cparams)
  File "/home/airflow/.local/lib/python3.6/site-packages/sqlalchemy/engine/default.py", line 508, in connect
    return self.dbapi.connect(*cargs, **cparams)
  File "/home/airflow/.local/lib/python3.6/site-packages/psycopg2/__init__.py", line 127, in connect
    conn = _connect(dsn, connection_factory=connection_factory, **kwasync)
psycopg2.OperationalError: could not connect to server: Connection refused
	Is the server running on host "db" (172.28.0.7) and accepting
	TCP/IP connections on port 5431?


The above exception was the direct cause of the following exception:

Traceback (most recent call last):
  File "/home/airflow/.local/lib/python3.6/site-packages/airflow/models/dagbag.py", line 302, in _load_modules_from_file
    loader.exec_module(new_module)
  File "<frozen importlib._bootstrap_external>", line 678, in exec_module
  File "<frozen importlib._bootstrap>", line 219, in _call_with_frames_removed
  File "/opt/airflow/dags/spent_by_user.py", line 20, in <module>
    Base.metadata.create_all(bind=engine, tables=[UserTotalSpent.__table__])
  File "/home/airflow/.local/lib/python3.6/site-packages/sqlalchemy/sql/schema.py", line 4664, in create_all
    ddl.SchemaGenerator, self, checkfirst=checkfirst, tables=tables
  File "/home/airflow/.local/lib/python3.6/site-packages/sqlalchemy/engine/base.py", line 2094, in _run_visitor
    with self._optional_conn_ctx_manager(connection) as conn:
  File "/usr/local/lib/python3.6/contextlib.py", line 81, in __enter__
    return next(self.gen)
  File "/home/airflow/.local/lib/python3.6/site-packages/sqlalchemy/engine/base.py", line 2086, in _optional_conn_ctx_manager
    with self._contextual_connect() as conn:
  File "/home/airflow/.local/lib/python3.6/site-packages/sqlalchemy/engine/base.py", line 2302, in _contextual_connect
    self._wrap_pool_connect(self.pool.connect, None),
  File "/home/airflow/.local/lib/python3.6/site-packages/sqlalchemy/engine/base.py", line 2340, in _wrap_pool_connect
    e, dialect, self
  File "/home/airflow/.local/lib/python3.6/site-packages/sqlalchemy/engine/base.py", line 1584, in _handle_dbapi_exception_noconnection
    sqlalchemy_exception, with_traceback=exc_info[2], from_=e
  File "/home/airflow/.local/lib/python3.6/site-packages/sqlalchemy/util/compat.py", line 182, in raise_
    raise exception
  File "/home/airflow/.local/lib/python3.6/site-packages/sqlalchemy/engine/base.py", line 2336, in _wrap_pool_connect
    return fn()
  File "/home/airflow/.local/lib/python3.6/site-packages/sqlalchemy/pool/base.py", line 364, in connect
    return _ConnectionFairy._checkout(self)
  File "/home/airflow/.local/lib/python3.6/site-packages/sqlalchemy/pool/base.py", line 778, in _checkout
    fairy = _ConnectionRecord.checkout(pool)
  File "/home/airflow/.local/lib/python3.6/site-packages/sqlalchemy/pool/base.py", line 495, in checkout
    rec = pool._do_get()
  File "/home/airflow/.local/lib/python3.6/site-packages/sqlalchemy/pool/impl.py", line 140, in _do_get
    self._dec_overflow()
  File "/home/airflow/.local/lib/python3.6/site-packages/sqlalchemy/util/langhelpers.py", line 70, in __exit__
    with_traceback=exc_tb,
  File "/home/airflow/.local/lib/python3.6/site-packages/sqlalchemy/util/compat.py", line 182, in raise_
    raise exception
  File "/home/airflow/.local/lib/python3.6/site-packages/sqlalchemy/pool/impl.py", line 137, in _do_get
    return self._create_connection()
  File "/home/airflow/.local/lib/python3.6/site-packages/sqlalchemy/pool/base.py", line 309, in _create_connection
    return _ConnectionRecord(self)
  File "/home/airflow/.local/lib/python3.6/site-packages/sqlalchemy/pool/base.py", line 440, in __init__
    self.__connect(first_connect_check=True)
  File "/home/airflow/.local/lib/python3.6/site-packages/sqlalchemy/pool/base.py", line 661, in __connect
    pool.logger.debug("Error on connect(): %s", e)
  File "/home/airflow/.local/lib/python3.6/site-packages/sqlalchemy/util/langhelpers.py", line 70, in __exit__
    with_traceback=exc_tb,
  File "/home/airflow/.local/lib/python3.6/site-packages/sqlalchemy/util/compat.py", line 182, in raise_
    raise exception
  File "/home/airflow/.local/lib/python3.6/site-packages/sqlalchemy/pool/base.py", line 656, in __connect
    connection = pool._invoke_creator(self)
  File "/home/airflow/.local/lib/python3.6/site-packages/sqlalchemy/engine/strategies.py", line 114, in connect
    return dialect.connect(*cargs, **cparams)
  File "/home/airflow/.local/lib/python3.6/site-packages/sqlalchemy/engine/default.py", line 508, in connect
    return self.dbapi.connect(*cargs, **cparams)
  File "/home/airflow/.local/lib/python3.6/site-packages/psycopg2/__init__.py", line 127, in connect
    conn = _connect(dsn, connection_factory=connection_factory, **kwasync)
sqlalchemy.exc.OperationalError: (psycopg2.OperationalError) could not connect to server: Connection refused
	Is the server running on host "db" (172.28.0.7) and accepting
	TCP/IP connections on port 5431?

(Background on this error at: http://sqlalche.me/e/13/e3q8)
[2023-03-10 21:53:54,759] {scheduler_job.py:641} WARNING - No viable dags retrieved from /opt/airflow/dags/spent_by_user.py
[2023-03-10 21:53:54,797] {scheduler_job.py:190} INFO - Processing /opt/airflow/dags/spent_by_user.py took 0.153 seconds
[2023-03-10 21:54:25,343] {scheduler_job.py:182} INFO - Started process (PID=511) to work on /opt/airflow/dags/spent_by_user.py
[2023-03-10 21:54:25,348] {scheduler_job.py:629} INFO - Processing file /opt/airflow/dags/spent_by_user.py for tasks to queue
[2023-03-10 21:54:25,352] {logging_mixin.py:104} INFO - [2023-03-10 21:54:25,351] {dagbag.py:448} INFO - Filling up the DagBag from /opt/airflow/dags/spent_by_user.py
[2023-03-10 21:54:25,419] {logging_mixin.py:104} INFO - [2023-03-10 21:54:25,394] {dagbag.py:305} ERROR - Failed to import: /opt/airflow/dags/spent_by_user.py
Traceback (most recent call last):
  File "/home/airflow/.local/lib/python3.6/site-packages/sqlalchemy/engine/base.py", line 2336, in _wrap_pool_connect
    return fn()
  File "/home/airflow/.local/lib/python3.6/site-packages/sqlalchemy/pool/base.py", line 364, in connect
    return _ConnectionFairy._checkout(self)
  File "/home/airflow/.local/lib/python3.6/site-packages/sqlalchemy/pool/base.py", line 778, in _checkout
    fairy = _ConnectionRecord.checkout(pool)
  File "/home/airflow/.local/lib/python3.6/site-packages/sqlalchemy/pool/base.py", line 495, in checkout
    rec = pool._do_get()
  File "/home/airflow/.local/lib/python3.6/site-packages/sqlalchemy/pool/impl.py", line 140, in _do_get
    self._dec_overflow()
  File "/home/airflow/.local/lib/python3.6/site-packages/sqlalchemy/util/langhelpers.py", line 70, in __exit__
    with_traceback=exc_tb,
  File "/home/airflow/.local/lib/python3.6/site-packages/sqlalchemy/util/compat.py", line 182, in raise_
    raise exception
  File "/home/airflow/.local/lib/python3.6/site-packages/sqlalchemy/pool/impl.py", line 137, in _do_get
    return self._create_connection()
  File "/home/airflow/.local/lib/python3.6/site-packages/sqlalchemy/pool/base.py", line 309, in _create_connection
    return _ConnectionRecord(self)
  File "/home/airflow/.local/lib/python3.6/site-packages/sqlalchemy/pool/base.py", line 440, in __init__
    self.__connect(first_connect_check=True)
  File "/home/airflow/.local/lib/python3.6/site-packages/sqlalchemy/pool/base.py", line 661, in __connect
    pool.logger.debug("Error on connect(): %s", e)
  File "/home/airflow/.local/lib/python3.6/site-packages/sqlalchemy/util/langhelpers.py", line 70, in __exit__
    with_traceback=exc_tb,
  File "/home/airflow/.local/lib/python3.6/site-packages/sqlalchemy/util/compat.py", line 182, in raise_
    raise exception
  File "/home/airflow/.local/lib/python3.6/site-packages/sqlalchemy/pool/base.py", line 656, in __connect
    connection = pool._invoke_creator(self)
  File "/home/airflow/.local/lib/python3.6/site-packages/sqlalchemy/engine/strategies.py", line 114, in connect
    return dialect.connect(*cargs, **cparams)
  File "/home/airflow/.local/lib/python3.6/site-packages/sqlalchemy/engine/default.py", line 508, in connect
    return self.dbapi.connect(*cargs, **cparams)
  File "/home/airflow/.local/lib/python3.6/site-packages/psycopg2/__init__.py", line 127, in connect
    conn = _connect(dsn, connection_factory=connection_factory, **kwasync)
psycopg2.OperationalError: could not connect to server: Connection refused
	Is the server running on host "db" (172.28.0.7) and accepting
	TCP/IP connections on port 5431?


The above exception was the direct cause of the following exception:

Traceback (most recent call last):
  File "/home/airflow/.local/lib/python3.6/site-packages/airflow/models/dagbag.py", line 302, in _load_modules_from_file
    loader.exec_module(new_module)
  File "<frozen importlib._bootstrap_external>", line 678, in exec_module
  File "<frozen importlib._bootstrap>", line 219, in _call_with_frames_removed
  File "/opt/airflow/dags/spent_by_user.py", line 20, in <module>
    Base.metadata.create_all(bind=engine, tables=[UserTotalSpent.__table__])
  File "/home/airflow/.local/lib/python3.6/site-packages/sqlalchemy/sql/schema.py", line 4664, in create_all
    ddl.SchemaGenerator, self, checkfirst=checkfirst, tables=tables
  File "/home/airflow/.local/lib/python3.6/site-packages/sqlalchemy/engine/base.py", line 2094, in _run_visitor
    with self._optional_conn_ctx_manager(connection) as conn:
  File "/usr/local/lib/python3.6/contextlib.py", line 81, in __enter__
    return next(self.gen)
  File "/home/airflow/.local/lib/python3.6/site-packages/sqlalchemy/engine/base.py", line 2086, in _optional_conn_ctx_manager
    with self._contextual_connect() as conn:
  File "/home/airflow/.local/lib/python3.6/site-packages/sqlalchemy/engine/base.py", line 2302, in _contextual_connect
    self._wrap_pool_connect(self.pool.connect, None),
  File "/home/airflow/.local/lib/python3.6/site-packages/sqlalchemy/engine/base.py", line 2340, in _wrap_pool_connect
    e, dialect, self
  File "/home/airflow/.local/lib/python3.6/site-packages/sqlalchemy/engine/base.py", line 1584, in _handle_dbapi_exception_noconnection
    sqlalchemy_exception, with_traceback=exc_info[2], from_=e
  File "/home/airflow/.local/lib/python3.6/site-packages/sqlalchemy/util/compat.py", line 182, in raise_
    raise exception
  File "/home/airflow/.local/lib/python3.6/site-packages/sqlalchemy/engine/base.py", line 2336, in _wrap_pool_connect
    return fn()
  File "/home/airflow/.local/lib/python3.6/site-packages/sqlalchemy/pool/base.py", line 364, in connect
    return _ConnectionFairy._checkout(self)
  File "/home/airflow/.local/lib/python3.6/site-packages/sqlalchemy/pool/base.py", line 778, in _checkout
    fairy = _ConnectionRecord.checkout(pool)
  File "/home/airflow/.local/lib/python3.6/site-packages/sqlalchemy/pool/base.py", line 495, in checkout
    rec = pool._do_get()
  File "/home/airflow/.local/lib/python3.6/site-packages/sqlalchemy/pool/impl.py", line 140, in _do_get
    self._dec_overflow()
  File "/home/airflow/.local/lib/python3.6/site-packages/sqlalchemy/util/langhelpers.py", line 70, in __exit__
    with_traceback=exc_tb,
  File "/home/airflow/.local/lib/python3.6/site-packages/sqlalchemy/util/compat.py", line 182, in raise_
    raise exception
  File "/home/airflow/.local/lib/python3.6/site-packages/sqlalchemy/pool/impl.py", line 137, in _do_get
    return self._create_connection()
  File "/home/airflow/.local/lib/python3.6/site-packages/sqlalchemy/pool/base.py", line 309, in _create_connection
    return _ConnectionRecord(self)
  File "/home/airflow/.local/lib/python3.6/site-packages/sqlalchemy/pool/base.py", line 440, in __init__
    self.__connect(first_connect_check=True)
  File "/home/airflow/.local/lib/python3.6/site-packages/sqlalchemy/pool/base.py", line 661, in __connect
    pool.logger.debug("Error on connect(): %s", e)
  File "/home/airflow/.local/lib/python3.6/site-packages/sqlalchemy/util/langhelpers.py", line 70, in __exit__
    with_traceback=exc_tb,
  File "/home/airflow/.local/lib/python3.6/site-packages/sqlalchemy/util/compat.py", line 182, in raise_
    raise exception
  File "/home/airflow/.local/lib/python3.6/site-packages/sqlalchemy/pool/base.py", line 656, in __connect
    connection = pool._invoke_creator(self)
  File "/home/airflow/.local/lib/python3.6/site-packages/sqlalchemy/engine/strategies.py", line 114, in connect
    return dialect.connect(*cargs, **cparams)
  File "/home/airflow/.local/lib/python3.6/site-packages/sqlalchemy/engine/default.py", line 508, in connect
    return self.dbapi.connect(*cargs, **cparams)
  File "/home/airflow/.local/lib/python3.6/site-packages/psycopg2/__init__.py", line 127, in connect
    conn = _connect(dsn, connection_factory=connection_factory, **kwasync)
sqlalchemy.exc.OperationalError: (psycopg2.OperationalError) could not connect to server: Connection refused
	Is the server running on host "db" (172.28.0.7) and accepting
	TCP/IP connections on port 5431?

(Background on this error at: http://sqlalche.me/e/13/e3q8)
[2023-03-10 21:54:25,427] {scheduler_job.py:641} WARNING - No viable dags retrieved from /opt/airflow/dags/spent_by_user.py
[2023-03-10 21:54:25,475] {scheduler_job.py:190} INFO - Processing /opt/airflow/dags/spent_by_user.py took 0.141 seconds
[2023-03-10 21:56:26,700] {scheduler_job.py:182} INFO - Started process (PID=61) to work on /opt/airflow/dags/spent_by_user.py
[2023-03-10 21:56:26,705] {scheduler_job.py:629} INFO - Processing file /opt/airflow/dags/spent_by_user.py for tasks to queue
[2023-03-10 21:56:26,715] {logging_mixin.py:104} INFO - [2023-03-10 21:56:26,708] {dagbag.py:448} INFO - Filling up the DagBag from /opt/airflow/dags/spent_by_user.py
[2023-03-10 21:56:26,947] {logging_mixin.py:104} INFO - [2023-03-10 21:56:26,933] {dagbag.py:305} ERROR - Failed to import: /opt/airflow/dags/spent_by_user.py
Traceback (most recent call last):
  File "/home/airflow/.local/lib/python3.6/site-packages/airflow/models/dagbag.py", line 302, in _load_modules_from_file
    loader.exec_module(new_module)
  File "<frozen importlib._bootstrap_external>", line 678, in exec_module
  File "<frozen importlib._bootstrap>", line 219, in _call_with_frames_removed
  File "/opt/airflow/dags/spent_by_user.py", line 50, in <module>
    dag=dag,
  File "/home/airflow/.local/lib/python3.6/site-packages/airflow/models/baseoperator.py", line 89, in __call__
    obj: BaseOperator = type.__call__(cls, *args, **kwargs)
  File "/home/airflow/.local/lib/python3.6/site-packages/airflow/utils/decorators.py", line 94, in wrapper
    result = func(*args, **kwargs)
  File "/home/airflow/.local/lib/python3.6/site-packages/airflow/operators/python.py", line 101, in __init__
    super().__init__(**kwargs)
  File "/home/airflow/.local/lib/python3.6/site-packages/airflow/utils/decorators.py", line 94, in wrapper
    result = func(*args, **kwargs)
  File "/home/airflow/.local/lib/python3.6/site-packages/airflow/models/baseoperator.py", line 487, in __init__
    self.dag = dag or DagContext.get_current_dag()
  File "/home/airflow/.local/lib/python3.6/site-packages/airflow/models/baseoperator.py", line 593, in __setattr__
    super().__setattr__(key, value)
  File "/home/airflow/.local/lib/python3.6/site-packages/airflow/models/baseoperator.py", line 644, in dag
    dag.add_task(self)
  File "/home/airflow/.local/lib/python3.6/site-packages/airflow/models/dag.py", line 1589, in add_task
    raise AirflowException("Task is missing the start_date parameter")
airflow.exceptions.AirflowException: Task is missing the start_date parameter
[2023-03-10 21:56:26,953] {scheduler_job.py:641} WARNING - No viable dags retrieved from /opt/airflow/dags/spent_by_user.py
[2023-03-10 21:56:27,010] {scheduler_job.py:190} INFO - Processing /opt/airflow/dags/spent_by_user.py took 0.320 seconds
[2023-03-10 21:56:57,118] {scheduler_job.py:182} INFO - Started process (PID=115) to work on /opt/airflow/dags/spent_by_user.py
[2023-03-10 21:56:57,123] {scheduler_job.py:629} INFO - Processing file /opt/airflow/dags/spent_by_user.py for tasks to queue
[2023-03-10 21:56:57,126] {logging_mixin.py:104} INFO - [2023-03-10 21:56:57,126] {dagbag.py:448} INFO - Filling up the DagBag from /opt/airflow/dags/spent_by_user.py
[2023-03-10 21:56:57,273] {logging_mixin.py:104} INFO - [2023-03-10 21:56:57,261] {dagbag.py:305} ERROR - Failed to import: /opt/airflow/dags/spent_by_user.py
Traceback (most recent call last):
  File "/home/airflow/.local/lib/python3.6/site-packages/airflow/models/dagbag.py", line 302, in _load_modules_from_file
    loader.exec_module(new_module)
  File "<frozen importlib._bootstrap_external>", line 678, in exec_module
  File "<frozen importlib._bootstrap>", line 219, in _call_with_frames_removed
  File "/opt/airflow/dags/spent_by_user.py", line 50, in <module>
    dag=dag,
  File "/home/airflow/.local/lib/python3.6/site-packages/airflow/models/baseoperator.py", line 89, in __call__
    obj: BaseOperator = type.__call__(cls, *args, **kwargs)
  File "/home/airflow/.local/lib/python3.6/site-packages/airflow/utils/decorators.py", line 94, in wrapper
    result = func(*args, **kwargs)
  File "/home/airflow/.local/lib/python3.6/site-packages/airflow/operators/python.py", line 101, in __init__
    super().__init__(**kwargs)
  File "/home/airflow/.local/lib/python3.6/site-packages/airflow/utils/decorators.py", line 94, in wrapper
    result = func(*args, **kwargs)
  File "/home/airflow/.local/lib/python3.6/site-packages/airflow/models/baseoperator.py", line 487, in __init__
    self.dag = dag or DagContext.get_current_dag()
  File "/home/airflow/.local/lib/python3.6/site-packages/airflow/models/baseoperator.py", line 593, in __setattr__
    super().__setattr__(key, value)
  File "/home/airflow/.local/lib/python3.6/site-packages/airflow/models/baseoperator.py", line 644, in dag
    dag.add_task(self)
  File "/home/airflow/.local/lib/python3.6/site-packages/airflow/models/dag.py", line 1589, in add_task
    raise AirflowException("Task is missing the start_date parameter")
airflow.exceptions.AirflowException: Task is missing the start_date parameter
[2023-03-10 21:56:57,278] {scheduler_job.py:641} WARNING - No viable dags retrieved from /opt/airflow/dags/spent_by_user.py
[2023-03-10 21:56:57,315] {scheduler_job.py:190} INFO - Processing /opt/airflow/dags/spent_by_user.py took 0.205 seconds
[2023-03-10 21:57:28,137] {scheduler_job.py:182} INFO - Started process (PID=169) to work on /opt/airflow/dags/spent_by_user.py
[2023-03-10 21:57:28,142] {scheduler_job.py:629} INFO - Processing file /opt/airflow/dags/spent_by_user.py for tasks to queue
[2023-03-10 21:57:28,155] {logging_mixin.py:104} INFO - [2023-03-10 21:57:28,155] {dagbag.py:448} INFO - Filling up the DagBag from /opt/airflow/dags/spent_by_user.py
[2023-03-10 21:57:28,427] {logging_mixin.py:104} INFO - [2023-03-10 21:57:28,408] {dagbag.py:305} ERROR - Failed to import: /opt/airflow/dags/spent_by_user.py
Traceback (most recent call last):
  File "/home/airflow/.local/lib/python3.6/site-packages/airflow/models/dagbag.py", line 302, in _load_modules_from_file
    loader.exec_module(new_module)
  File "<frozen importlib._bootstrap_external>", line 678, in exec_module
  File "<frozen importlib._bootstrap>", line 219, in _call_with_frames_removed
  File "/opt/airflow/dags/spent_by_user.py", line 50, in <module>
    dag=dag,
  File "/home/airflow/.local/lib/python3.6/site-packages/airflow/models/baseoperator.py", line 89, in __call__
    obj: BaseOperator = type.__call__(cls, *args, **kwargs)
  File "/home/airflow/.local/lib/python3.6/site-packages/airflow/utils/decorators.py", line 94, in wrapper
    result = func(*args, **kwargs)
  File "/home/airflow/.local/lib/python3.6/site-packages/airflow/operators/python.py", line 101, in __init__
    super().__init__(**kwargs)
  File "/home/airflow/.local/lib/python3.6/site-packages/airflow/utils/decorators.py", line 94, in wrapper
    result = func(*args, **kwargs)
  File "/home/airflow/.local/lib/python3.6/site-packages/airflow/models/baseoperator.py", line 487, in __init__
    self.dag = dag or DagContext.get_current_dag()
  File "/home/airflow/.local/lib/python3.6/site-packages/airflow/models/baseoperator.py", line 593, in __setattr__
    super().__setattr__(key, value)
  File "/home/airflow/.local/lib/python3.6/site-packages/airflow/models/baseoperator.py", line 644, in dag
    dag.add_task(self)
  File "/home/airflow/.local/lib/python3.6/site-packages/airflow/models/dag.py", line 1589, in add_task
    raise AirflowException("Task is missing the start_date parameter")
airflow.exceptions.AirflowException: Task is missing the start_date parameter
[2023-03-10 21:57:28,436] {scheduler_job.py:641} WARNING - No viable dags retrieved from /opt/airflow/dags/spent_by_user.py
[2023-03-10 21:57:28,496] {scheduler_job.py:190} INFO - Processing /opt/airflow/dags/spent_by_user.py took 0.369 seconds
[2023-03-10 21:57:58,976] {scheduler_job.py:182} INFO - Started process (PID=223) to work on /opt/airflow/dags/spent_by_user.py
[2023-03-10 21:57:58,980] {scheduler_job.py:629} INFO - Processing file /opt/airflow/dags/spent_by_user.py for tasks to queue
[2023-03-10 21:57:58,983] {logging_mixin.py:104} INFO - [2023-03-10 21:57:58,982] {dagbag.py:448} INFO - Filling up the DagBag from /opt/airflow/dags/spent_by_user.py
[2023-03-10 21:57:59,128] {logging_mixin.py:104} INFO - [2023-03-10 21:57:59,115] {dagbag.py:305} ERROR - Failed to import: /opt/airflow/dags/spent_by_user.py
Traceback (most recent call last):
  File "/home/airflow/.local/lib/python3.6/site-packages/airflow/models/dagbag.py", line 302, in _load_modules_from_file
    loader.exec_module(new_module)
  File "<frozen importlib._bootstrap_external>", line 678, in exec_module
  File "<frozen importlib._bootstrap>", line 219, in _call_with_frames_removed
  File "/opt/airflow/dags/spent_by_user.py", line 50, in <module>
    dag=dag,
  File "/home/airflow/.local/lib/python3.6/site-packages/airflow/models/baseoperator.py", line 89, in __call__
    obj: BaseOperator = type.__call__(cls, *args, **kwargs)
  File "/home/airflow/.local/lib/python3.6/site-packages/airflow/utils/decorators.py", line 94, in wrapper
    result = func(*args, **kwargs)
  File "/home/airflow/.local/lib/python3.6/site-packages/airflow/operators/python.py", line 101, in __init__
    super().__init__(**kwargs)
  File "/home/airflow/.local/lib/python3.6/site-packages/airflow/utils/decorators.py", line 94, in wrapper
    result = func(*args, **kwargs)
  File "/home/airflow/.local/lib/python3.6/site-packages/airflow/models/baseoperator.py", line 487, in __init__
    self.dag = dag or DagContext.get_current_dag()
  File "/home/airflow/.local/lib/python3.6/site-packages/airflow/models/baseoperator.py", line 593, in __setattr__
    super().__setattr__(key, value)
  File "/home/airflow/.local/lib/python3.6/site-packages/airflow/models/baseoperator.py", line 644, in dag
    dag.add_task(self)
  File "/home/airflow/.local/lib/python3.6/site-packages/airflow/models/dag.py", line 1589, in add_task
    raise AirflowException("Task is missing the start_date parameter")
airflow.exceptions.AirflowException: Task is missing the start_date parameter
[2023-03-10 21:57:59,135] {scheduler_job.py:641} WARNING - No viable dags retrieved from /opt/airflow/dags/spent_by_user.py
[2023-03-10 21:57:59,170] {scheduler_job.py:190} INFO - Processing /opt/airflow/dags/spent_by_user.py took 0.203 seconds
[2023-03-10 21:58:29,289] {scheduler_job.py:182} INFO - Started process (PID=277) to work on /opt/airflow/dags/spent_by_user.py
[2023-03-10 21:58:29,294] {scheduler_job.py:629} INFO - Processing file /opt/airflow/dags/spent_by_user.py for tasks to queue
[2023-03-10 21:58:29,296] {logging_mixin.py:104} INFO - [2023-03-10 21:58:29,296] {dagbag.py:448} INFO - Filling up the DagBag from /opt/airflow/dags/spent_by_user.py
[2023-03-10 21:58:29,434] {logging_mixin.py:104} INFO - [2023-03-10 21:58:29,422] {dagbag.py:305} ERROR - Failed to import: /opt/airflow/dags/spent_by_user.py
Traceback (most recent call last):
  File "/home/airflow/.local/lib/python3.6/site-packages/airflow/models/dagbag.py", line 302, in _load_modules_from_file
    loader.exec_module(new_module)
  File "<frozen importlib._bootstrap_external>", line 678, in exec_module
  File "<frozen importlib._bootstrap>", line 219, in _call_with_frames_removed
  File "/opt/airflow/dags/spent_by_user.py", line 50, in <module>
    dag=dag,
  File "/home/airflow/.local/lib/python3.6/site-packages/airflow/models/baseoperator.py", line 89, in __call__
    obj: BaseOperator = type.__call__(cls, *args, **kwargs)
  File "/home/airflow/.local/lib/python3.6/site-packages/airflow/utils/decorators.py", line 94, in wrapper
    result = func(*args, **kwargs)
  File "/home/airflow/.local/lib/python3.6/site-packages/airflow/operators/python.py", line 101, in __init__
    super().__init__(**kwargs)
  File "/home/airflow/.local/lib/python3.6/site-packages/airflow/utils/decorators.py", line 94, in wrapper
    result = func(*args, **kwargs)
  File "/home/airflow/.local/lib/python3.6/site-packages/airflow/models/baseoperator.py", line 487, in __init__
    self.dag = dag or DagContext.get_current_dag()
  File "/home/airflow/.local/lib/python3.6/site-packages/airflow/models/baseoperator.py", line 593, in __setattr__
    super().__setattr__(key, value)
  File "/home/airflow/.local/lib/python3.6/site-packages/airflow/models/baseoperator.py", line 644, in dag
    dag.add_task(self)
  File "/home/airflow/.local/lib/python3.6/site-packages/airflow/models/dag.py", line 1589, in add_task
    raise AirflowException("Task is missing the start_date parameter")
airflow.exceptions.AirflowException: Task is missing the start_date parameter
[2023-03-10 21:58:29,440] {scheduler_job.py:641} WARNING - No viable dags retrieved from /opt/airflow/dags/spent_by_user.py
[2023-03-10 21:58:29,470] {scheduler_job.py:190} INFO - Processing /opt/airflow/dags/spent_by_user.py took 0.189 seconds
[2023-03-10 21:58:59,836] {scheduler_job.py:182} INFO - Started process (PID=329) to work on /opt/airflow/dags/spent_by_user.py
[2023-03-10 21:58:59,842] {scheduler_job.py:629} INFO - Processing file /opt/airflow/dags/spent_by_user.py for tasks to queue
[2023-03-10 21:58:59,845] {logging_mixin.py:104} INFO - [2023-03-10 21:58:59,845] {dagbag.py:448} INFO - Filling up the DagBag from /opt/airflow/dags/spent_by_user.py
[2023-03-10 21:58:59,866] {logging_mixin.py:104} INFO - [2023-03-10 21:58:59,862] {dagbag.py:305} ERROR - Failed to import: /opt/airflow/dags/spent_by_user.py
Traceback (most recent call last):
  File "/home/airflow/.local/lib/python3.6/site-packages/airflow/models/dagbag.py", line 302, in _load_modules_from_file
    loader.exec_module(new_module)
  File "<frozen importlib._bootstrap_external>", line 674, in exec_module
  File "<frozen importlib._bootstrap_external>", line 781, in get_code
  File "<frozen importlib._bootstrap_external>", line 741, in source_to_code
  File "<frozen importlib._bootstrap>", line 219, in _call_with_frames_removed
  File "/opt/airflow/dags/spent_by_user.py", line 25
    'start_date': dt.datetime(2023, 01, 01),
                                     ^
SyntaxError: invalid token
[2023-03-10 21:58:59,870] {scheduler_job.py:641} WARNING - No viable dags retrieved from /opt/airflow/dags/spent_by_user.py
[2023-03-10 21:58:59,904] {scheduler_job.py:190} INFO - Processing /opt/airflow/dags/spent_by_user.py took 0.074 seconds
[2023-03-10 22:00:18,172] {scheduler_job.py:182} INFO - Started process (PID=81) to work on /opt/airflow/dags/spent_by_user.py
[2023-03-10 22:00:18,177] {scheduler_job.py:629} INFO - Processing file /opt/airflow/dags/spent_by_user.py for tasks to queue
[2023-03-10 22:00:18,180] {logging_mixin.py:104} INFO - [2023-03-10 22:00:18,180] {dagbag.py:448} INFO - Filling up the DagBag from /opt/airflow/dags/spent_by_user.py
[2023-03-10 22:00:18,379] {scheduler_job.py:639} INFO - DAG(s) dict_keys(['user_total_spent']) retrieved from /opt/airflow/dags/spent_by_user.py
[2023-03-10 22:00:18,517] {logging_mixin.py:104} INFO - [2023-03-10 22:00:18,516] {dag.py:1818} INFO - Sync 1 DAGs
[2023-03-10 22:00:18,565] {logging_mixin.py:104} INFO - [2023-03-10 22:00:18,565] {dag.py:1837} INFO - Creating ORM DAG for user_total_spent
[2023-03-10 22:00:18,596] {logging_mixin.py:104} INFO - [2023-03-10 22:00:18,595] {dag.py:2273} INFO - Setting next_dagrun for user_total_spent to 2023-01-01T00:00:00+00:00
[2023-03-10 22:00:18,650] {scheduler_job.py:190} INFO - Processing /opt/airflow/dags/spent_by_user.py took 0.487 seconds
[2023-03-10 22:00:48,718] {scheduler_job.py:182} INFO - Started process (PID=135) to work on /opt/airflow/dags/spent_by_user.py
[2023-03-10 22:00:48,723] {scheduler_job.py:629} INFO - Processing file /opt/airflow/dags/spent_by_user.py for tasks to queue
[2023-03-10 22:00:48,726] {logging_mixin.py:104} INFO - [2023-03-10 22:00:48,726] {dagbag.py:448} INFO - Filling up the DagBag from /opt/airflow/dags/spent_by_user.py
[2023-03-10 22:00:48,888] {scheduler_job.py:639} INFO - DAG(s) dict_keys(['user_total_spent']) retrieved from /opt/airflow/dags/spent_by_user.py
[2023-03-10 22:00:48,952] {logging_mixin.py:104} INFO - [2023-03-10 22:00:48,951] {dag.py:1818} INFO - Sync 1 DAGs
[2023-03-10 22:00:49,011] {logging_mixin.py:104} INFO - [2023-03-10 22:00:49,010] {dag.py:2273} INFO - Setting next_dagrun for user_total_spent to 2023-01-01T00:00:00+00:00
[2023-03-10 22:00:49,036] {scheduler_job.py:190} INFO - Processing /opt/airflow/dags/spent_by_user.py took 0.324 seconds
[2023-03-10 22:01:19,443] {scheduler_job.py:182} INFO - Started process (PID=181) to work on /opt/airflow/dags/spent_by_user.py
[2023-03-10 22:01:19,451] {scheduler_job.py:629} INFO - Processing file /opt/airflow/dags/spent_by_user.py for tasks to queue
[2023-03-10 22:01:19,458] {logging_mixin.py:104} INFO - [2023-03-10 22:01:19,458] {dagbag.py:448} INFO - Filling up the DagBag from /opt/airflow/dags/spent_by_user.py
[2023-03-10 22:01:19,631] {scheduler_job.py:639} INFO - DAG(s) dict_keys(['user_total_spent']) retrieved from /opt/airflow/dags/spent_by_user.py
[2023-03-10 22:01:19,716] {logging_mixin.py:104} INFO - [2023-03-10 22:01:19,716] {dag.py:1818} INFO - Sync 1 DAGs
[2023-03-10 22:01:19,783] {logging_mixin.py:104} INFO - [2023-03-10 22:01:19,782] {dag.py:2273} INFO - Setting next_dagrun for user_total_spent to 2023-01-01T00:00:00+00:00
[2023-03-10 22:01:19,821] {scheduler_job.py:190} INFO - Processing /opt/airflow/dags/spent_by_user.py took 0.390 seconds
[2023-03-10 22:01:50,174] {scheduler_job.py:182} INFO - Started process (PID=235) to work on /opt/airflow/dags/spent_by_user.py
[2023-03-10 22:01:50,178] {scheduler_job.py:629} INFO - Processing file /opt/airflow/dags/spent_by_user.py for tasks to queue
[2023-03-10 22:01:50,182] {logging_mixin.py:104} INFO - [2023-03-10 22:01:50,181] {dagbag.py:448} INFO - Filling up the DagBag from /opt/airflow/dags/spent_by_user.py
[2023-03-10 22:01:50,332] {scheduler_job.py:639} INFO - DAG(s) dict_keys(['user_total_spent']) retrieved from /opt/airflow/dags/spent_by_user.py
[2023-03-10 22:01:50,390] {logging_mixin.py:104} INFO - [2023-03-10 22:01:50,390] {dag.py:1818} INFO - Sync 1 DAGs
[2023-03-10 22:01:50,448] {logging_mixin.py:104} INFO - [2023-03-10 22:01:50,446] {dag.py:2273} INFO - Setting next_dagrun for user_total_spent to 2023-01-01T00:00:00+00:00
[2023-03-10 22:01:50,472] {scheduler_job.py:190} INFO - Processing /opt/airflow/dags/spent_by_user.py took 0.305 seconds
[2023-03-10 22:02:20,584] {scheduler_job.py:182} INFO - Started process (PID=289) to work on /opt/airflow/dags/spent_by_user.py
[2023-03-10 22:02:20,589] {scheduler_job.py:629} INFO - Processing file /opt/airflow/dags/spent_by_user.py for tasks to queue
[2023-03-10 22:02:20,594] {logging_mixin.py:104} INFO - [2023-03-10 22:02:20,594] {dagbag.py:448} INFO - Filling up the DagBag from /opt/airflow/dags/spent_by_user.py
[2023-03-10 22:02:20,752] {scheduler_job.py:639} INFO - DAG(s) dict_keys(['user_total_spent']) retrieved from /opt/airflow/dags/spent_by_user.py
[2023-03-10 22:02:20,808] {logging_mixin.py:104} INFO - [2023-03-10 22:02:20,808] {dag.py:1818} INFO - Sync 1 DAGs
[2023-03-10 22:02:20,861] {logging_mixin.py:104} INFO - [2023-03-10 22:02:20,861] {dag.py:2273} INFO - Setting next_dagrun for user_total_spent to 2023-01-01T00:00:00+00:00
[2023-03-10 22:02:20,879] {scheduler_job.py:190} INFO - Processing /opt/airflow/dags/spent_by_user.py took 0.302 seconds
[2023-03-10 22:02:51,305] {scheduler_job.py:182} INFO - Started process (PID=341) to work on /opt/airflow/dags/spent_by_user.py
[2023-03-10 22:02:51,311] {scheduler_job.py:629} INFO - Processing file /opt/airflow/dags/spent_by_user.py for tasks to queue
[2023-03-10 22:02:51,314] {logging_mixin.py:104} INFO - [2023-03-10 22:02:51,313] {dagbag.py:448} INFO - Filling up the DagBag from /opt/airflow/dags/spent_by_user.py
[2023-03-10 22:02:51,465] {scheduler_job.py:639} INFO - DAG(s) dict_keys(['user_total_spent']) retrieved from /opt/airflow/dags/spent_by_user.py
[2023-03-10 22:02:51,520] {logging_mixin.py:104} INFO - [2023-03-10 22:02:51,519] {dag.py:1818} INFO - Sync 1 DAGs
[2023-03-10 22:02:51,572] {logging_mixin.py:104} INFO - [2023-03-10 22:02:51,572] {dag.py:2273} INFO - Setting next_dagrun for user_total_spent to 2023-01-01T00:00:00+00:00
[2023-03-10 22:02:51,602] {scheduler_job.py:190} INFO - Processing /opt/airflow/dags/spent_by_user.py took 0.304 seconds
[2023-03-10 22:03:22,253] {scheduler_job.py:182} INFO - Started process (PID=397) to work on /opt/airflow/dags/spent_by_user.py
[2023-03-10 22:03:22,258] {scheduler_job.py:629} INFO - Processing file /opt/airflow/dags/spent_by_user.py for tasks to queue
[2023-03-10 22:03:22,262] {logging_mixin.py:104} INFO - [2023-03-10 22:03:22,261] {dagbag.py:448} INFO - Filling up the DagBag from /opt/airflow/dags/spent_by_user.py
[2023-03-10 22:03:22,418] {scheduler_job.py:639} INFO - DAG(s) dict_keys(['user_total_spent']) retrieved from /opt/airflow/dags/spent_by_user.py
[2023-03-10 22:03:22,476] {logging_mixin.py:104} INFO - [2023-03-10 22:03:22,476] {dag.py:1818} INFO - Sync 1 DAGs
[2023-03-10 22:03:22,533] {logging_mixin.py:104} INFO - [2023-03-10 22:03:22,533] {dag.py:2273} INFO - Setting next_dagrun for user_total_spent to 2023-01-01T00:00:00+00:00
[2023-03-10 22:03:22,553] {scheduler_job.py:190} INFO - Processing /opt/airflow/dags/spent_by_user.py took 0.307 seconds
[2023-03-10 22:03:53,293] {scheduler_job.py:182} INFO - Started process (PID=453) to work on /opt/airflow/dags/spent_by_user.py
[2023-03-10 22:03:53,299] {scheduler_job.py:629} INFO - Processing file /opt/airflow/dags/spent_by_user.py for tasks to queue
[2023-03-10 22:03:53,303] {logging_mixin.py:104} INFO - [2023-03-10 22:03:53,303] {dagbag.py:448} INFO - Filling up the DagBag from /opt/airflow/dags/spent_by_user.py
[2023-03-10 22:03:53,471] {scheduler_job.py:639} INFO - DAG(s) dict_keys(['user_total_spent']) retrieved from /opt/airflow/dags/spent_by_user.py
[2023-03-10 22:03:53,538] {logging_mixin.py:104} INFO - [2023-03-10 22:03:53,537] {dag.py:1818} INFO - Sync 1 DAGs
[2023-03-10 22:03:53,596] {logging_mixin.py:104} INFO - [2023-03-10 22:03:53,595] {dag.py:2273} INFO - Setting next_dagrun for user_total_spent to 2023-01-01T00:00:00+00:00
[2023-03-10 22:03:53,624] {scheduler_job.py:190} INFO - Processing /opt/airflow/dags/spent_by_user.py took 0.338 seconds
[2023-03-10 22:04:23,932] {scheduler_job.py:182} INFO - Started process (PID=505) to work on /opt/airflow/dags/spent_by_user.py
[2023-03-10 22:04:23,937] {scheduler_job.py:629} INFO - Processing file /opt/airflow/dags/spent_by_user.py for tasks to queue
[2023-03-10 22:04:23,940] {logging_mixin.py:104} INFO - [2023-03-10 22:04:23,939] {dagbag.py:448} INFO - Filling up the DagBag from /opt/airflow/dags/spent_by_user.py
[2023-03-10 22:04:24,100] {scheduler_job.py:639} INFO - DAG(s) dict_keys(['user_total_spent']) retrieved from /opt/airflow/dags/spent_by_user.py
[2023-03-10 22:04:24,158] {logging_mixin.py:104} INFO - [2023-03-10 22:04:24,157] {dag.py:1818} INFO - Sync 1 DAGs
[2023-03-10 22:04:24,210] {logging_mixin.py:104} INFO - [2023-03-10 22:04:24,210] {dag.py:2273} INFO - Setting next_dagrun for user_total_spent to 2023-01-01T00:00:00+00:00
[2023-03-10 22:04:24,232] {scheduler_job.py:190} INFO - Processing /opt/airflow/dags/spent_by_user.py took 0.307 seconds
[2023-03-10 22:04:54,278] {scheduler_job.py:182} INFO - Started process (PID=559) to work on /opt/airflow/dags/spent_by_user.py
[2023-03-10 22:04:54,283] {scheduler_job.py:629} INFO - Processing file /opt/airflow/dags/spent_by_user.py for tasks to queue
[2023-03-10 22:04:54,286] {logging_mixin.py:104} INFO - [2023-03-10 22:04:54,286] {dagbag.py:448} INFO - Filling up the DagBag from /opt/airflow/dags/spent_by_user.py
[2023-03-10 22:04:54,454] {scheduler_job.py:639} INFO - DAG(s) dict_keys(['user_total_spent']) retrieved from /opt/airflow/dags/spent_by_user.py
[2023-03-10 22:04:54,507] {logging_mixin.py:104} INFO - [2023-03-10 22:04:54,507] {dag.py:1818} INFO - Sync 1 DAGs
[2023-03-10 22:04:54,559] {logging_mixin.py:104} INFO - [2023-03-10 22:04:54,559] {dag.py:2273} INFO - Setting next_dagrun for user_total_spent to 2023-01-01T00:00:00+00:00
[2023-03-10 22:04:54,582] {scheduler_job.py:190} INFO - Processing /opt/airflow/dags/spent_by_user.py took 0.311 seconds
[2023-03-10 22:05:25,092] {scheduler_job.py:182} INFO - Started process (PID=609) to work on /opt/airflow/dags/spent_by_user.py
[2023-03-10 22:05:25,096] {scheduler_job.py:629} INFO - Processing file /opt/airflow/dags/spent_by_user.py for tasks to queue
[2023-03-10 22:05:25,100] {logging_mixin.py:104} INFO - [2023-03-10 22:05:25,099] {dagbag.py:448} INFO - Filling up the DagBag from /opt/airflow/dags/spent_by_user.py
[2023-03-10 22:05:25,258] {scheduler_job.py:639} INFO - DAG(s) dict_keys(['user_total_spent']) retrieved from /opt/airflow/dags/spent_by_user.py
[2023-03-10 22:05:25,319] {logging_mixin.py:104} INFO - [2023-03-10 22:05:25,319] {dag.py:1818} INFO - Sync 1 DAGs
[2023-03-10 22:05:25,383] {logging_mixin.py:104} INFO - [2023-03-10 22:05:25,382] {dag.py:2273} INFO - Setting next_dagrun for user_total_spent to 2023-01-01T00:00:00+00:00
[2023-03-10 22:05:25,410] {scheduler_job.py:190} INFO - Processing /opt/airflow/dags/spent_by_user.py took 0.325 seconds
[2023-03-10 22:05:56,209] {scheduler_job.py:182} INFO - Started process (PID=663) to work on /opt/airflow/dags/spent_by_user.py
[2023-03-10 22:05:56,213] {scheduler_job.py:629} INFO - Processing file /opt/airflow/dags/spent_by_user.py for tasks to queue
[2023-03-10 22:05:56,216] {logging_mixin.py:104} INFO - [2023-03-10 22:05:56,216] {dagbag.py:448} INFO - Filling up the DagBag from /opt/airflow/dags/spent_by_user.py
[2023-03-10 22:05:56,369] {scheduler_job.py:639} INFO - DAG(s) dict_keys(['user_total_spent']) retrieved from /opt/airflow/dags/spent_by_user.py
[2023-03-10 22:05:56,421] {logging_mixin.py:104} INFO - [2023-03-10 22:05:56,420] {dag.py:1818} INFO - Sync 1 DAGs
[2023-03-10 22:05:56,471] {logging_mixin.py:104} INFO - [2023-03-10 22:05:56,470] {dag.py:2273} INFO - Setting next_dagrun for user_total_spent to 2023-01-01T00:00:00+00:00
[2023-03-10 22:05:56,491] {scheduler_job.py:190} INFO - Processing /opt/airflow/dags/spent_by_user.py took 0.290 seconds
[2023-03-10 22:06:26,906] {scheduler_job.py:182} INFO - Started process (PID=715) to work on /opt/airflow/dags/spent_by_user.py
[2023-03-10 22:06:26,911] {scheduler_job.py:629} INFO - Processing file /opt/airflow/dags/spent_by_user.py for tasks to queue
[2023-03-10 22:06:26,914] {logging_mixin.py:104} INFO - [2023-03-10 22:06:26,914] {dagbag.py:448} INFO - Filling up the DagBag from /opt/airflow/dags/spent_by_user.py
[2023-03-10 22:06:27,066] {scheduler_job.py:639} INFO - DAG(s) dict_keys(['user_total_spent']) retrieved from /opt/airflow/dags/spent_by_user.py
[2023-03-10 22:06:27,122] {logging_mixin.py:104} INFO - [2023-03-10 22:06:27,122] {dag.py:1818} INFO - Sync 1 DAGs
[2023-03-10 22:06:27,180] {logging_mixin.py:104} INFO - [2023-03-10 22:06:27,179] {dag.py:2273} INFO - Setting next_dagrun for user_total_spent to 2023-01-01T00:00:00+00:00
[2023-03-10 22:06:27,201] {scheduler_job.py:190} INFO - Processing /opt/airflow/dags/spent_by_user.py took 0.302 seconds
[2023-03-10 22:06:57,837] {scheduler_job.py:182} INFO - Started process (PID=773) to work on /opt/airflow/dags/spent_by_user.py
[2023-03-10 22:06:57,843] {scheduler_job.py:629} INFO - Processing file /opt/airflow/dags/spent_by_user.py for tasks to queue
[2023-03-10 22:06:57,846] {logging_mixin.py:104} INFO - [2023-03-10 22:06:57,846] {dagbag.py:448} INFO - Filling up the DagBag from /opt/airflow/dags/spent_by_user.py
[2023-03-10 22:06:57,996] {scheduler_job.py:639} INFO - DAG(s) dict_keys(['user_total_spent']) retrieved from /opt/airflow/dags/spent_by_user.py
[2023-03-10 22:06:58,061] {logging_mixin.py:104} INFO - [2023-03-10 22:06:58,060] {dag.py:1818} INFO - Sync 1 DAGs
[2023-03-10 22:06:58,116] {logging_mixin.py:104} INFO - [2023-03-10 22:06:58,115] {dag.py:2273} INFO - Setting next_dagrun for user_total_spent to 2023-01-01T00:00:00+00:00
[2023-03-10 22:06:58,136] {scheduler_job.py:190} INFO - Processing /opt/airflow/dags/spent_by_user.py took 0.305 seconds
[2023-03-10 22:07:28,490] {scheduler_job.py:182} INFO - Started process (PID=827) to work on /opt/airflow/dags/spent_by_user.py
[2023-03-10 22:07:28,496] {scheduler_job.py:629} INFO - Processing file /opt/airflow/dags/spent_by_user.py for tasks to queue
[2023-03-10 22:07:28,499] {logging_mixin.py:104} INFO - [2023-03-10 22:07:28,499] {dagbag.py:448} INFO - Filling up the DagBag from /opt/airflow/dags/spent_by_user.py
[2023-03-10 22:07:28,650] {scheduler_job.py:639} INFO - DAG(s) dict_keys(['user_total_spent']) retrieved from /opt/airflow/dags/spent_by_user.py
[2023-03-10 22:07:28,705] {logging_mixin.py:104} INFO - [2023-03-10 22:07:28,704] {dag.py:1818} INFO - Sync 1 DAGs
[2023-03-10 22:07:28,762] {logging_mixin.py:104} INFO - [2023-03-10 22:07:28,762] {dag.py:2273} INFO - Setting next_dagrun for user_total_spent to 2023-01-01T00:00:00+00:00
[2023-03-10 22:07:28,785] {scheduler_job.py:190} INFO - Processing /opt/airflow/dags/spent_by_user.py took 0.302 seconds
[2023-03-10 22:07:59,122] {scheduler_job.py:182} INFO - Started process (PID=881) to work on /opt/airflow/dags/spent_by_user.py
[2023-03-10 22:07:59,126] {scheduler_job.py:629} INFO - Processing file /opt/airflow/dags/spent_by_user.py for tasks to queue
[2023-03-10 22:07:59,130] {logging_mixin.py:104} INFO - [2023-03-10 22:07:59,129] {dagbag.py:448} INFO - Filling up the DagBag from /opt/airflow/dags/spent_by_user.py
[2023-03-10 22:07:59,278] {scheduler_job.py:639} INFO - DAG(s) dict_keys(['user_total_spent']) retrieved from /opt/airflow/dags/spent_by_user.py
[2023-03-10 22:07:59,336] {logging_mixin.py:104} INFO - [2023-03-10 22:07:59,335] {dag.py:1818} INFO - Sync 1 DAGs
[2023-03-10 22:07:59,388] {logging_mixin.py:104} INFO - [2023-03-10 22:07:59,387] {dag.py:2273} INFO - Setting next_dagrun for user_total_spent to 2023-01-01T00:00:00+00:00
[2023-03-10 22:07:59,409] {scheduler_job.py:190} INFO - Processing /opt/airflow/dags/spent_by_user.py took 0.294 seconds
[2023-03-10 22:08:30,243] {scheduler_job.py:182} INFO - Started process (PID=933) to work on /opt/airflow/dags/spent_by_user.py
[2023-03-10 22:08:30,248] {scheduler_job.py:629} INFO - Processing file /opt/airflow/dags/spent_by_user.py for tasks to queue
[2023-03-10 22:08:30,253] {logging_mixin.py:104} INFO - [2023-03-10 22:08:30,252] {dagbag.py:448} INFO - Filling up the DagBag from /opt/airflow/dags/spent_by_user.py
[2023-03-10 22:08:30,401] {scheduler_job.py:639} INFO - DAG(s) dict_keys(['user_total_spent']) retrieved from /opt/airflow/dags/spent_by_user.py
[2023-03-10 22:08:30,465] {logging_mixin.py:104} INFO - [2023-03-10 22:08:30,465] {dag.py:1818} INFO - Sync 1 DAGs
[2023-03-10 22:08:30,518] {logging_mixin.py:104} INFO - [2023-03-10 22:08:30,518] {dag.py:2273} INFO - Setting next_dagrun for user_total_spent to 2023-01-01T00:00:00+00:00
[2023-03-10 22:08:30,539] {scheduler_job.py:190} INFO - Processing /opt/airflow/dags/spent_by_user.py took 0.302 seconds
[2023-03-10 22:09:00,713] {scheduler_job.py:182} INFO - Started process (PID=989) to work on /opt/airflow/dags/spent_by_user.py
[2023-03-10 22:09:00,717] {scheduler_job.py:629} INFO - Processing file /opt/airflow/dags/spent_by_user.py for tasks to queue
[2023-03-10 22:09:00,720] {logging_mixin.py:104} INFO - [2023-03-10 22:09:00,720] {dagbag.py:448} INFO - Filling up the DagBag from /opt/airflow/dags/spent_by_user.py
[2023-03-10 22:09:00,873] {scheduler_job.py:639} INFO - DAG(s) dict_keys(['user_total_spent']) retrieved from /opt/airflow/dags/spent_by_user.py
[2023-03-10 22:09:00,934] {logging_mixin.py:104} INFO - [2023-03-10 22:09:00,933] {dag.py:1818} INFO - Sync 1 DAGs
[2023-03-10 22:09:00,984] {logging_mixin.py:104} INFO - [2023-03-10 22:09:00,984] {dag.py:2273} INFO - Setting next_dagrun for user_total_spent to 2023-01-01T00:00:00+00:00
[2023-03-10 22:09:01,004] {scheduler_job.py:190} INFO - Processing /opt/airflow/dags/spent_by_user.py took 0.298 seconds
[2023-03-10 22:09:31,160] {scheduler_job.py:182} INFO - Started process (PID=1043) to work on /opt/airflow/dags/spent_by_user.py
[2023-03-10 22:09:31,164] {scheduler_job.py:629} INFO - Processing file /opt/airflow/dags/spent_by_user.py for tasks to queue
[2023-03-10 22:09:31,167] {logging_mixin.py:104} INFO - [2023-03-10 22:09:31,167] {dagbag.py:448} INFO - Filling up the DagBag from /opt/airflow/dags/spent_by_user.py
[2023-03-10 22:09:31,314] {scheduler_job.py:639} INFO - DAG(s) dict_keys(['user_total_spent']) retrieved from /opt/airflow/dags/spent_by_user.py
[2023-03-10 22:09:31,372] {logging_mixin.py:104} INFO - [2023-03-10 22:09:31,371] {dag.py:1818} INFO - Sync 1 DAGs
[2023-03-10 22:09:31,422] {logging_mixin.py:104} INFO - [2023-03-10 22:09:31,422] {dag.py:2273} INFO - Setting next_dagrun for user_total_spent to 2023-01-01T00:00:00+00:00
[2023-03-10 22:09:31,447] {scheduler_job.py:190} INFO - Processing /opt/airflow/dags/spent_by_user.py took 0.294 seconds
[2023-03-10 22:10:01,574] {scheduler_job.py:182} INFO - Started process (PID=1097) to work on /opt/airflow/dags/spent_by_user.py
[2023-03-10 22:10:01,579] {scheduler_job.py:629} INFO - Processing file /opt/airflow/dags/spent_by_user.py for tasks to queue
[2023-03-10 22:10:01,582] {logging_mixin.py:104} INFO - [2023-03-10 22:10:01,581] {dagbag.py:448} INFO - Filling up the DagBag from /opt/airflow/dags/spent_by_user.py
[2023-03-10 22:10:01,749] {scheduler_job.py:639} INFO - DAG(s) dict_keys(['user_total_spent']) retrieved from /opt/airflow/dags/spent_by_user.py
[2023-03-10 22:10:01,810] {logging_mixin.py:104} INFO - [2023-03-10 22:10:01,809] {dag.py:1818} INFO - Sync 1 DAGs
[2023-03-10 22:10:01,863] {logging_mixin.py:104} INFO - [2023-03-10 22:10:01,863] {dag.py:2273} INFO - Setting next_dagrun for user_total_spent to 2023-01-01T00:00:00+00:00
[2023-03-10 22:10:01,884] {scheduler_job.py:190} INFO - Processing /opt/airflow/dags/spent_by_user.py took 0.318 seconds
[2023-03-10 22:10:32,815] {scheduler_job.py:182} INFO - Started process (PID=1153) to work on /opt/airflow/dags/spent_by_user.py
[2023-03-10 22:10:32,822] {scheduler_job.py:629} INFO - Processing file /opt/airflow/dags/spent_by_user.py for tasks to queue
[2023-03-10 22:10:32,825] {logging_mixin.py:104} INFO - [2023-03-10 22:10:32,825] {dagbag.py:448} INFO - Filling up the DagBag from /opt/airflow/dags/spent_by_user.py
[2023-03-10 22:10:33,009] {scheduler_job.py:639} INFO - DAG(s) dict_keys(['user_total_spent']) retrieved from /opt/airflow/dags/spent_by_user.py
[2023-03-10 22:10:33,072] {logging_mixin.py:104} INFO - [2023-03-10 22:10:33,072] {dag.py:1818} INFO - Sync 1 DAGs
[2023-03-10 22:10:33,139] {logging_mixin.py:104} INFO - [2023-03-10 22:10:33,138] {dag.py:2273} INFO - Setting next_dagrun for user_total_spent to 2023-01-01T00:00:00+00:00
[2023-03-10 22:10:33,179] {scheduler_job.py:190} INFO - Processing /opt/airflow/dags/spent_by_user.py took 0.376 seconds
[2023-03-10 22:11:03,351] {scheduler_job.py:182} INFO - Started process (PID=1209) to work on /opt/airflow/dags/spent_by_user.py
[2023-03-10 22:11:03,355] {scheduler_job.py:629} INFO - Processing file /opt/airflow/dags/spent_by_user.py for tasks to queue
[2023-03-10 22:11:03,358] {logging_mixin.py:104} INFO - [2023-03-10 22:11:03,358] {dagbag.py:448} INFO - Filling up the DagBag from /opt/airflow/dags/spent_by_user.py
[2023-03-10 22:11:03,519] {scheduler_job.py:639} INFO - DAG(s) dict_keys(['user_total_spent']) retrieved from /opt/airflow/dags/spent_by_user.py
[2023-03-10 22:11:03,584] {logging_mixin.py:104} INFO - [2023-03-10 22:11:03,584] {dag.py:1818} INFO - Sync 1 DAGs
[2023-03-10 22:11:03,639] {logging_mixin.py:104} INFO - [2023-03-10 22:11:03,638] {dag.py:2273} INFO - Setting next_dagrun for user_total_spent to 2023-01-01T00:00:00+00:00
[2023-03-10 22:11:03,659] {scheduler_job.py:190} INFO - Processing /opt/airflow/dags/spent_by_user.py took 0.316 seconds
[2023-03-10 22:11:34,000] {scheduler_job.py:182} INFO - Started process (PID=1255) to work on /opt/airflow/dags/spent_by_user.py
[2023-03-10 22:11:34,007] {scheduler_job.py:629} INFO - Processing file /opt/airflow/dags/spent_by_user.py for tasks to queue
[2023-03-10 22:11:34,012] {logging_mixin.py:104} INFO - [2023-03-10 22:11:34,011] {dagbag.py:448} INFO - Filling up the DagBag from /opt/airflow/dags/spent_by_user.py
[2023-03-10 22:11:34,200] {scheduler_job.py:639} INFO - DAG(s) dict_keys(['user_total_spent']) retrieved from /opt/airflow/dags/spent_by_user.py
[2023-03-10 22:11:34,264] {logging_mixin.py:104} INFO - [2023-03-10 22:11:34,264] {dag.py:1818} INFO - Sync 1 DAGs
[2023-03-10 22:11:34,319] {logging_mixin.py:104} INFO - [2023-03-10 22:11:34,318] {dag.py:2273} INFO - Setting next_dagrun for user_total_spent to 2023-01-01T00:00:00+00:00
[2023-03-10 22:11:34,352] {scheduler_job.py:190} INFO - Processing /opt/airflow/dags/spent_by_user.py took 0.361 seconds
[2023-03-10 22:12:53,621] {scheduler_job.py:182} INFO - Started process (PID=93) to work on /opt/airflow/dags/spent_by_user.py
[2023-03-10 22:12:53,628] {scheduler_job.py:629} INFO - Processing file /opt/airflow/dags/spent_by_user.py for tasks to queue
[2023-03-10 22:12:53,634] {logging_mixin.py:104} INFO - [2023-03-10 22:12:53,634] {dagbag.py:448} INFO - Filling up the DagBag from /opt/airflow/dags/spent_by_user.py
[2023-03-10 22:12:53,867] {scheduler_job.py:639} INFO - DAG(s) dict_keys(['user_total_spent']) retrieved from /opt/airflow/dags/spent_by_user.py
[2023-03-10 22:12:53,947] {logging_mixin.py:104} INFO - [2023-03-10 22:12:53,947] {dag.py:1818} INFO - Sync 1 DAGs
[2023-03-10 22:12:54,020] {logging_mixin.py:104} INFO - [2023-03-10 22:12:54,019] {dag.py:2273} INFO - Setting next_dagrun for user_total_spent to 2023-01-01T00:00:00+00:00
[2023-03-10 22:12:54,058] {scheduler_job.py:190} INFO - Processing /opt/airflow/dags/spent_by_user.py took 0.455 seconds
[2023-03-10 22:13:24,694] {scheduler_job.py:182} INFO - Started process (PID=147) to work on /opt/airflow/dags/spent_by_user.py
[2023-03-10 22:13:24,703] {scheduler_job.py:629} INFO - Processing file /opt/airflow/dags/spent_by_user.py for tasks to queue
[2023-03-10 22:13:24,709] {logging_mixin.py:104} INFO - [2023-03-10 22:13:24,708] {dagbag.py:448} INFO - Filling up the DagBag from /opt/airflow/dags/spent_by_user.py
[2023-03-10 22:13:24,932] {scheduler_job.py:639} INFO - DAG(s) dict_keys(['user_total_spent']) retrieved from /opt/airflow/dags/spent_by_user.py
[2023-03-10 22:13:25,009] {logging_mixin.py:104} INFO - [2023-03-10 22:13:25,008] {dag.py:1818} INFO - Sync 1 DAGs
[2023-03-10 22:13:25,096] {logging_mixin.py:104} INFO - [2023-03-10 22:13:25,095] {dag.py:2273} INFO - Setting next_dagrun for user_total_spent to 2023-01-01T00:00:00+00:00
[2023-03-10 22:13:25,126] {scheduler_job.py:190} INFO - Processing /opt/airflow/dags/spent_by_user.py took 0.442 seconds
[2023-03-10 22:13:56,878] {scheduler_job.py:182} INFO - Started process (PID=201) to work on /opt/airflow/dags/spent_by_user.py
[2023-03-10 22:13:56,889] {scheduler_job.py:629} INFO - Processing file /opt/airflow/dags/spent_by_user.py for tasks to queue
[2023-03-10 22:13:56,894] {logging_mixin.py:104} INFO - [2023-03-10 22:13:56,893] {dagbag.py:448} INFO - Filling up the DagBag from /opt/airflow/dags/spent_by_user.py
[2023-03-10 22:13:57,115] {scheduler_job.py:639} INFO - DAG(s) dict_keys(['user_total_spent']) retrieved from /opt/airflow/dags/spent_by_user.py
[2023-03-10 22:13:57,178] {logging_mixin.py:104} INFO - [2023-03-10 22:13:57,178] {dag.py:1818} INFO - Sync 1 DAGs
[2023-03-10 22:13:57,244] {logging_mixin.py:104} INFO - [2023-03-10 22:13:57,243] {dag.py:2273} INFO - Setting next_dagrun for user_total_spent to 2023-01-01T00:00:00+00:00
[2023-03-10 22:13:57,278] {scheduler_job.py:190} INFO - Processing /opt/airflow/dags/spent_by_user.py took 0.408 seconds
[2023-03-10 22:14:27,379] {scheduler_job.py:182} INFO - Started process (PID=255) to work on /opt/airflow/dags/spent_by_user.py
[2023-03-10 22:14:27,386] {scheduler_job.py:629} INFO - Processing file /opt/airflow/dags/spent_by_user.py for tasks to queue
[2023-03-10 22:14:27,391] {logging_mixin.py:104} INFO - [2023-03-10 22:14:27,390] {dagbag.py:448} INFO - Filling up the DagBag from /opt/airflow/dags/spent_by_user.py
[2023-03-10 22:14:27,566] {scheduler_job.py:639} INFO - DAG(s) dict_keys(['user_total_spent']) retrieved from /opt/airflow/dags/spent_by_user.py
[2023-03-10 22:14:27,627] {logging_mixin.py:104} INFO - [2023-03-10 22:14:27,626] {dag.py:1818} INFO - Sync 1 DAGs
[2023-03-10 22:14:27,686] {logging_mixin.py:104} INFO - [2023-03-10 22:14:27,685] {dag.py:2273} INFO - Setting next_dagrun for user_total_spent to 2023-01-01T00:00:00+00:00
[2023-03-10 22:14:27,710] {scheduler_job.py:190} INFO - Processing /opt/airflow/dags/spent_by_user.py took 0.340 seconds
[2023-03-10 22:14:58,197] {scheduler_job.py:182} INFO - Started process (PID=309) to work on /opt/airflow/dags/spent_by_user.py
[2023-03-10 22:14:58,201] {scheduler_job.py:629} INFO - Processing file /opt/airflow/dags/spent_by_user.py for tasks to queue
[2023-03-10 22:14:58,207] {logging_mixin.py:104} INFO - [2023-03-10 22:14:58,206] {dagbag.py:448} INFO - Filling up the DagBag from /opt/airflow/dags/spent_by_user.py
[2023-03-10 22:14:58,397] {scheduler_job.py:639} INFO - DAG(s) dict_keys(['user_total_spent']) retrieved from /opt/airflow/dags/spent_by_user.py
[2023-03-10 22:14:58,456] {logging_mixin.py:104} INFO - [2023-03-10 22:14:58,455] {dag.py:1818} INFO - Sync 1 DAGs
[2023-03-10 22:14:58,508] {logging_mixin.py:104} INFO - [2023-03-10 22:14:58,507] {dag.py:2273} INFO - Setting next_dagrun for user_total_spent to 2023-01-01T00:00:00+00:00
[2023-03-10 22:14:58,544] {scheduler_job.py:190} INFO - Processing /opt/airflow/dags/spent_by_user.py took 0.356 seconds
